Workbook

Sheet Sheet1

Sheet 야채 계산기
B1: 야채류 중량 산출 | F1: =F3*1.03 -> 3244.5 | G1: =G3*1.03 -> 6210.9 | H1: =H3*1.03 -> 2152.7 | I1: =I3*1.03 -> 1133 | J1: =J3*1.03 -> 453.2 | K1: =K3*1.03 -> 4552.6 | L1: =L3*1.03 -> 5047 | M1: =M3*1.03 -> 1895.2 | ... AS1: =AS3*1.03 -> 107.12
B2: 하루 물량 입력하면 <야채계산기, 마요네즈,참치계산기, 단무지계산기>시트에 야채, (정량 반영) 마요네즈, 단무지, 참깨, 참기름 (정량) , 참치 (일별 10% 여유반영) 필요량 자동 산출됨 | E2: 7/20기준 | F2: 삼각)전주비빔 | G2: 더큰)스팸김치볶음밥 | H2: NEW스팸무스비 | I2: 무스비)햄&참치김치볶음밥 | J2: 무스비)햄&청양불고기 | K2: 종가)들기름묵은지참치 | L2: 더큰)스팸계란볶음밥 | M2: 더큰)오징어&제육깻잎쌈밥 | N2: 더큰)리챔참치마요 | O2: 더큰)추석맥적구이한상 | P2: 커플)곱창김참치마요&전주비빔 | Q2: 더블치즈소시지김밥 | R2: 슈퍼)착한참치마요김밥 | S2: 왕돈까스김밥 | T2: 슈퍼)착한김치김밥 | U2: 참치김치볶음김밥 | V2: 직화)한돈제육쌈김밥 | W2: 스팸계란치즈김밥 | X2: 불고기치즈김밥 | Y2: THE근본김밥 | Z2: 필름)진미채치즈김밥 | AA2: 넷플)K스타일떡갈비김밥 | AB2: 용기)광장시장꼬마김밥 | AC2: 용기)에그햄꼬마김밥 | AD2: 혜자)돌아온명불허전 | AE2: 슈퍼)착한제육비빔밥 | AF2: 착한마파두부덮밥 | AG2: NEW혜자)백설갈비양념제육 | AH2: 착한제육덮밥 | AI2: 혜자)통등심돈까스&치킨까스도시락 | AJ2: 혜자)두툼돈까스&순창제육도시락 | AK2: 혜자)돌아온등심돈까스 | AL2: N혜자)불고기오징어제육 | AM2: 뭘좋아할지몰라다넣어봤어 | AN2: 두부김치제육 | AO2: 혜자)반반제육 | AP2: 이달의도시락10월 | AQ2: 쯔양)매콤흑당치킨&골뱅이 | AR2: 슈퍼)착한핫도그(오리지널) | AS2: 슈퍼)착한핫도그(사라다)
D3: 금일 | E3: =SUM(F3:AS3) -> 36438 | F3: 3824 | G3: 5117 | H3: 1403 | I3: 0 | J3: 0 | K3: 1840 | L3: 3188 | M3: 0 | N3: 2917 | O3: 0 | P3: 0 | Q3: 1288 | R3: 0 | S3: 1582 | T3: 0 | U3: 0 | V3: 2504 | W3: 3188 | X3: 1192 | Y3: 2598 | Z3: 0 | AA3: 0 | AB3: 0 | AC3: 0 | AD3: 778 | AE3: 0 | AF3: 0 | AG3: 1046 | AH3: 0 | AI3: 0 | AJ3: 0 | AK3: 851 | AL3: 1889 | AM3: 1233 | AN3: 0 | AO3: 0 | AP3: 0 | AQ3: 0 | AR3: 0 | AS3: 0
B4: 품목 | C4: 세팅값 | D4: 산출 | E4: 합계 (KG) | F4: 원물중량(g) | G4: 원물중량(g) | H4: 원물중량(g) | I4: 원물중량(g) | J4: 원물중량(g) | K4: 원물중량(g) | L4: 원물중량(g) | M4: 원물중량(g) | N4: 원물중량(g) | O4: 원물중량(g) | P4: 원물중량(g) | Q4: 원물중량(g) | R4: 원물중량(g) | S4: 원물중량(g) | T4: 원물중량(g) | U4: 원물중량(g) | V4: 원물중량(g) | W4: 원물중량(g) | X4: 원물중량(g) | Y4: 원물중량(g) | Z4: 원물중량(g) | AA4: 원물중량(g) | AB4: 원물중량(g) | AC4: 원물중량(g) | AD4: 원물중량(g) | AE4: 원물중량(g) | AF4: 원물중량(g) | AG4: 원물중량(g) | AH4: 원물중량(g) | AI4: 원물중량(g) | AJ4: 원물중량(g) | AK4: 원물중량(g) | AL4: 원물중량(g) | AM4: 원물중량(g) | AN4: 원물중량(g) | AO4: 원물중량(g) | AP4: 원물중량(g) | AQ4: 원물중량(g) | AR4: 원물중량(g) | AS4: 원물중량(g)
A5: 김밥류 | B5: [냉장] 우엉채(3kg*3봉 - 9kg * 1box) | C5: =D5*1 -> 0 | D5: =E5/3 -> 0 | E5: =SUMPRODUCT(F$3:AS$3,F5:AS5)/1000 -> 0 | AT5: =COUNTA(F5:AS5) -> 0
A6: 김밥류 | B6: [냉장] 당근채(4kg*3봉 - 1박스) | C6: =D6*1 -> 60.689769 | D6: =E6/4 -> 60.689769 | E6: =SUMPRODUCT(F$3:AS$3,F6:AS6)/1000*0.92 -> 242.75908 | R6: 23.63 | T6: ='[1]착한김치김밥(250612)슈퍼'!$B$8 -> 15.074 | U6: 12.13 | V6: 20.17 | W6: 22.22 | X6: 0 | Y6: 32.19 | Z6: 25.38 | AA6: 30.18 | AB6: 15.27 | AE6: ='[1]착한비빔밥(25.10.23)'!$B$7 -> 17.36 | AT6: =COUNTA(F6:AS6) -> 11
B7: [냉장] 양배추(10kg*box) | C7: =D7*1 -> 26.78116 | D7: =E7/10 -> 26.78116 | E7: =SUMPRODUCT(F$3:AS$3,F7:AS7)/1000 -> 267.8116 | Q7: 42.86 | S7: 67.4 | U7: 19.04 | W7: 30.54 | AA7: 32.87 | AL7: ='[1]혜자)직화불고기&오징어제육(25.9.16)'!$B$27 -> 3.56 | AQ7: 31.9 | AS7: ='[1]슈퍼)착한1900핫도그-사라다(25.09.02)'!$B$4 -> 36 | AT7: =COUNTA(F7:AS7) -> 8
B8: [냉장] 깐양파(10kg*1box) | C8: =D8*1 -> 9.4675779 | D8: =E8/10 -> 9.4675779 | E8: =SUMPRODUCT(F$3:AS$3,F8:AS8)/1000*1.1 -> 94.675779 | AD8: ='[1]혜자)돌아온 명불허전(25.9.18)리뉴얼'!$B$14 -> 28.45 | AF8: 17.55 | AH8: 38.43 | AI8: 5.28 | AJ8: ='[1]혜자)돈까스&고추장제육(25.11.13)'!$B$13 -> 1.68 | AL8: ='[1]혜자)직화불고기&오징어제육(25.9.16)'!$B$18 -> 5.07 | AM8: 2.04 | AP8: 6.08 | AR8: ='[1]슈퍼)착한1900핫도그-오리지널(25.09.02)'!$B$5 -> 25.51 | AT8: =COUNTA(F8:AS8) -> 9
A9: 삼각전주 | B9: [냉장] 깐도라지채(2kg*1봉 - 10kg*1box) | C9: =D9*1 -> 6.3367 | D9: =E9/2 -> 6.3367 | E9: =SUMPRODUCT(F$3:AS$3,F9:AS9)/1000 -> 12.6734 | F9: 3.76 | AE9: ='[1]착한비빔밥(25.10.23)'!$B$8 -> 15.08 | AT9: =COUNTA(F9:AS9) -> 2
B10: [냉장] 당근(10kg*1box) | C10: =D10*1 -> 0.3717 | D10: =E10/10 -> 0.3717 | E10: =SUMPRODUCT(F$3:AS$3,F10:AS10)/1000 -> 3.717 | F10: 1.18 | AT10: =COUNTA(F10:AS10) -> 1
B11: [냉장] 오이 10kg*1box | C11: =D11*1 -> 0 | D11: =E11/10 -> 0 | E11: =SUMPRODUCT(F$3:AS$3,F11:AS11)/1000 -> 0 | AT11: =COUNTA(F11:AS11) -> 0
A12: 삼각2종 | B12: [냉장] 온천콩나물(4kg*1box) | C12: =D12*1 -> 12.509398 | D12: =E12/4 -> 12.509398 | E12: =SUMPRODUCT(F$3:AS$3,F12:AS12)/1000*0.95 -> 50.037592 | F12: 5.13 | AE12: ='[1]착한비빔밥(25.10.23)'!$B$9 -> 24.39 | AO12: 30.06 | AT12: =COUNTA(F12:AS12) -> 3
A13: 김밥삼각 | B13: [냉장] 깻잎(2kg*1box) | C13: =D13*1 -> 9.2771 | D13: =E13/2 -> 9.2771 | E13: =SUMPRODUCT(F$3:AS$3,F13:AS13)/1000 -> 18.5542 | M13: 2.13 | R13: 3.02 | T13: ='[1]착한김치김밥(250612)슈퍼'!$B$20 -> 3.12 | U13: 4.16 | V13: 2.78 | AO13: 2.54 | AT13: =COUNTA(F13:AS13) -> 6
A14: 버거샌드 | B14: [냉장] 청상추(2kg*1box) | C14: =D14*1 -> 0.24695 | D14: =E14/2 -> 0.24695 | E14: =SUMPRODUCT(F$3:AS$3,F14:AS14)/1000 -> 0.4939 | AE14: ='[1]착한비빔밥(25.10.23)'!$B$10 -> 8.98 | AT14: =COUNTA(F14:AS14) -> 1
B15: [냉장] 깐쪽파 (1kg*2ea) | C15: =D15*1 -> 7.87189 | D15: =E15/1 -> 7.87189 | E15: =SUMPRODUCT(F$3:AS$3,F15:AS15)/1000*0.95 -> 7.87189 | AD15: ='[1]혜자)돌아온 명불허전(25.8.12)'!$B$26 -> 1.26 | AG15: ='[1]혜자)갈비양념제육도시락(25.9.30)'!$B$15 -> 0.56 | AI15: 0.11 | AJ15: 1.12 | AL15: ='[1]혜자)직화불고기&오징어제육(25.9.16)'!$B$20 -> 1.12 | AN15: 1.12 | AO15: 1.12 | AT15: =COUNTA(F15:AS15) -> 7
B16: [냉장] 깐대파(2kg/box) | C16: =D16*1 -> 1.5756 | D16: =E16/2 -> 1.5756 | E16: =SUMPRODUCT(F$3:AS$3,F16:AS16)/1000 -> 3.1512 | AI16: 1.56 | AT16: =COUNTA(F16:AS16) -> 1
B17: [냉장] 부추 (4kg*1box) | C17: =D17*1 -> 0.7535 | D17: =E17/4 -> 0.7535 | E17: =SUMPRODUCT(F$3:AS$3,F17:AS17)/1000 -> 3.014 | N17: 0 | AD17: ='[1]혜자)돌아온 명불허전(25.8.12)'!$B$20 -> 0.94 | AL17: ='[1]혜자)직화불고기&오징어제육(25.9.16)'!$B$19 -> 1.8 | AP17: 1.72 | AT17: =COUNTA(F17:AS17) -> 4
B18: [냉장] 프릴아이스 | C18: =D18*1 -> 0 | D18: =E18/1 -> 0 | E18: =SUMPRODUCT(F$3:AS$3,F18:AS18)/1000 -> 0 | AQ18: 12.43 | AT18: =COUNTA(F18:AS18) -> 1
B19: [냉장] 풋고추(1kg*5봉) | C19: =D19*1 -> 0 | D19: =E19/1 -> 0 | E19: =SUMPRODUCT(F$3:AS$3,F19:AS19)/1000 -> 0 | AT19: =COUNTA(F19:AS19) -> 0
B20: [냉장] 팽이버섯 150g*34ea | C20: =D20*1 -> 0 | D20: =E20/0.15 -> 0 | E20: =SUMPRODUCT(F$3:AS$3,F20:AS20)/1000 -> 0 | AT20: =COUNTA(F20:AS20) -> 0
B21: [냉장] 청양고추(1kg*5ea) | C21: =D21*1 -> 1.7501 | D21: =E21/1 -> 1.7501 | E21: =SUMPRODUCT(F$3:AS$3,F21:AS21)/1000 -> 1.7501 | J21: 3.74 | AP21: 0.19 | AT21: =COUNTA(F21:AS21) -> 2
B22: [냉장] 마늘쫑(7kg*1box) | C22: =D22*1 -> 0 | D22: =E22/7 -> 0 | E22: =SUMPRODUCT(F$3:AS$3,F22:AS22)/1000 -> 0 | AT22: =COUNTA(F22:AS22) -> 0
B23: [냉장] 애호박(6kg*1box) | C23: =D23*1 -> 0 | D23: =E23/6 -> 0 | E23: =SUMPRODUCT(F$3:AS$3,F23:AS23)/1000 -> 0 | AT23: =COUNTA(F23:AS23) -> 0
B24: [냉장] 청피망(10kg*1box) | C24: =D24*1 -> 0 | D24: =E24/2 -> 0 | E24: =SUMPRODUCT(F$3:AS$3,F24:AS24)/1000 -> 0 | AT24: =COUNTA(F24:AS24) -> 0
B25: [냉장] 홍피망(10kg*1box) | C25: =D25*1 -> 0 | D25: =E25/2 -> 0 | E25: =SUMPRODUCT(F$3:AS$3,F25:AS25)/1000 -> 0 | AT25: =COUNTA(F25:AS25) -> 0
B26: [냉장] 백오이(다다기오이) (10kg/box) | C26: =D26*1 -> 0 | D26: =E26/10 -> 0 | E26: =SUMPRODUCT(F$3:AS$3,F26:AS26)/1000 -> 0 | AT26: =COUNTA(F26:AS26) -> 0
B27: [냉장] 느타리버섯 2kg*1box | C27: =D27*1 -> 0 | D27: =E27/2 -> 0 | E27: =SUMPRODUCT(F$3:AS$3,F27:AS27)/1000 -> 0 | AT27: =COUNTA(F27:AS27) -> 0
F30: 3438 | G30: 5698 | H30: 1540 | I30: 647 | J30: 647 | K30: 2146 | L30: 3656 | M30: 1899 | N30: 3308 | O30: 3308 | P30: 3308 | Q30: 1228 | R30: 247 | S30: 1843 | T30: 198 | U30: 6200 | V30: 2102 | W30: 2603 | X30: 1223 | Y30: 2838 | Z30: 2838 | AA30: 2838 | AB30: 752 | AC30: 752 | AD30: 752 | AE30: 59 | AF30: 0 | AG30: 886 | AH30: 38 | AI30: 1656 | AJ30: 1656 | AK30: 802 | AL30: 1603 | AM30: 1136 | AN30: 1505 | AO30: 1505 | AP30: 250 | AQ30: 250 | AR30: 113 | AS30: 101
C363: [냉동] 우유튀김(1kg*10ea)

Sheet 조미식초
B2: 조미식초 | F2: 총 필요량 | G2: =SUM(D8,M14,O20) -> 53414.35
B4: 삼각 | C4: 삼각)전주비빔
B5: 원물중량 | C5: 0.72
B6: 예상수량 | C6: =INDEX('야채 계산기'!3:3,MATCH(조미식초!C4,'야채 계산기'!2:2,0)) -> 3150
B7: 1.1 | C7: =C6*$B$7 -> 3465
B8: 필요량 | C8: =C5*C7 -> 2494.8 | D8: =SUM(C8:C8) -> 2494.8
B10: 풀삼각 | C10: 더큰)스팸계란볶음밥 | D10: 더큰)스팸김치볶음밥 | E10: NEW스팸무스비 | F10: 무스비)햄&참치김치볶음밥 | G10: 무스비)햄&청양불고기 | H10: 더큰)오징어&제육깻잎쌈밥 | I10: 더큰)리챔참치마요 | J10: 종가)들기름묵은지참치 | K10: 더큰)추석맥적구이한상 | L10: 슈퍼)착한제육비빔밥
B11: 원물중량 | C11: 1.09 | D11: 1.16 | E11: 1.22 | F11: 0.37 | G11: 1.22 | H11: 1.03 | I11: 1.03 | J11: 1.12 | K11: 0.4 | L11: 1.8
B12: 예상수량 | C12: =INDEX('야채 계산기'!3:3,MATCH(C10,'야채 계산기'!2:2,0)) -> 4900 | D12: =INDEX('야채 계산기'!3:3,MATCH(D10,'야채 계산기'!2:2,0)) -> 6030 | E12: =INDEX('야채 계산기'!3:3,MATCH(E10,'야채 계산기'!2:2,0)) -> 2090 | F12: =INDEX('야채 계산기'!3:3,MATCH(F10,'야채 계산기'!2:2,0)) -> 1100 | G12: =INDEX('야채 계산기'!3:3,MATCH(G10,'야채 계산기'!2:2,0)) -> 440 | H12: =INDEX('야채 계산기'!3:3,MATCH(H10,'야채 계산기'!2:2,0)) -> 1840 | I12: =INDEX('야채 계산기'!3:3,MATCH(I10,'야채 계산기'!2:2,0)) -> 3620 | J12: =INDEX('야채 계산기'!3:3,MATCH(J10,'야채 계산기'!2:2,0)) -> 4420 | ... L12: =INDEX('야채 계산기'!3:3,MATCH(L10,'야채 계산기'!2:2,0)) -> 55
B13: 1.1 | C13: =C12*$B$13 -> 5390 | D13: =D12*$B$13 -> 6633 | E13: =E12*$B$13 -> 2299 | F13: =F12*$B$13 -> 1210 | G13: =G12*$B$13 -> 484 | H13: =H12*$B$13 -> 2024 | I13: =I12*$B$13 -> 3982 | J13: =J12*$B$13 -> 4862 | ... L13: =L12*$B$13 -> 60.5
B14: 필요량 | C14: =C11*C13 -> 5875.1 | D14: =D11*D13 -> 7694.28 | E14: =E11*E13 -> 2804.78 | F14: =F11*F13 -> 447.7 | G14: =G11*G13 -> 590.48 | H14: =H11*H13 -> 2084.72 | I14: =I11*I13 -> 4101.46 | J14: =J11*J13 -> 5445.44 | ... L14: =L11*L13 -> 108.9 | M14: =SUM(C14:L14) -> 29870.06
B16: 도시락 | C16: 혜자)돌아온명불허전 | D16: 뭘좋아할지몰라다넣어봤어 | E16: N혜자)불고기오징어제육 | F16: 혜자)돌아온등심돈까스 | G16: 착한마파두부덮밥 | H16: 착한제육덮밥 | I16: 혜자)반반제육 | J16: 혜자)통등심돈까스&치킨까스도시락 | K16: 혜자)두툼돈까스&순창제육도시락 | L16: NEW혜자)백설갈비양념제육 | M16: 참치김치볶음김밥 | N16: 이달의도시락10월
B17: 원물중량 | C17: ='[1]혜자)돌아온 명불허전(25.8.12)'!$B$4 -> 2.06 | D17: 2.04 | E17: 1.04 | F17: 2.09 | G17: 1.8 | H17: 1.71 | I17: 0.94 | J17: 2.04 | K17: 1.04 | L17: 0.99 | M17: 1.12 | N17: 2.27
B18: 예상수량 | C18: =INDEX('야채 계산기'!3:3,MATCH(C16,'야채 계산기'!2:2,0)) -> 2200 | D18: =INDEX('야채 계산기'!3:3,MATCH(D16,'야채 계산기'!2:2,0)) -> 1080 | E18: =INDEX('야채 계산기'!3:3,MATCH(E16,'야채 계산기'!2:2,0)) -> 0 | F18: =INDEX('야채 계산기'!3:3,MATCH(F16,'야채 계산기'!2:2,0)) -> 640 | G18: =INDEX('야채 계산기'!3:3,MATCH(G16,'야채 계산기'!2:2,0)) -> 0 | H18: =INDEX('야채 계산기'!3:3,MATCH(H16,'야채 계산기'!2:2,0)) -> 30 | I18: =INDEX('야채 계산기'!3:3,MATCH(I16,'야채 계산기'!2:2,0)) -> 1170 | J18: =INDEX('야채 계산기'!3:3,MATCH(J16,'야채 계산기'!2:2,0)) -> 2020 | ... N18: =INDEX('야채 계산기'!3:3,MATCH(N16,'야채 계산기'!2:2,0)) -> 550
B19: 1.1 | C19: =C18*$B$19 -> 2420 | D19: =D18*$B$19 -> 1188 | E19: =E18*$B$19 -> 0 | F19: =F18*$B$19 -> 704 | G19: =G18*$B$19 -> 0 | H19: =H18*$B$19 -> 33 | I19: =I18*$B$19 -> 1287 | J19: =J18*$B$19 -> 2222 | ... N19: =N18*$B$19 -> 605
B20: 필요량 | C20: =C17*C19 -> 4985.2 | D20: =D17*D19 -> 2423.52 | E20: =E17*E19 -> 0 | F20: =F17*F19 -> 1471.36 | G20: =G17*G19 -> 0 | H20: =H17*H19 -> 56.43 | I20: =I17*I19 -> 1209.78 | J20: =J17*J19 -> 4532.88 | ... N20: =N17*N19 -> 1373.35 | O20: =SUM(C20:N20) -> 21049.49
C381: [냉동] 우유튀김(1kg*10ea)
C1212: [상온] 오도리가쓰오부시(500g*4ea) | E1212: 4 | H1212: =ROUNDUP((B1213*C1213)/500,0) -> 0
C1213: ='[1]유우카의알찬정식(25.7.15)'!$B$27 -> 0.51

Sheet Sheet2

Sheet 발주시트
A1: 거래처명 | B1: 제품수량 | C1: 품목 | D1: 발주량박스 | E1: 입수량 | F1: 발주량입수 | G1: 발주일수 | H1: 일사용량 | I1: 입고량(입수) | J1: 금일재고(봉) | K1: 총재고량 | L1: 필요 값 | M1: 차이 | N1: 재고유지일 | O1: 발주량 | P1: 입수량 | Q1: 단가(봉) | R1: 금액 | S1: 1 | T1: 월(26) | U1: 화(27) | V1: 수(28) | W1: 목(29) | X1: 금(30) | Y1: 토(31) | Z1: 일(01) | AA1: 일사용량(박스)
J2: =IFERROR(VLOOKUP(C2,[2]Sheet1!$D:$J,7,0),"") | S2: =SUM(Y2,T2) -> 0
A3: 진주햄 (D-1) 월화수목금토 | B3: 진주전산 13시 | J3: =IFERROR(VLOOKUP(C3,[2]Sheet1!$D:$J,7,0),"") | N3: =IFERROR((K3/H3),"")
C4: [냉장] 골드88세절K(1kg*10봉) | D4: =IFERROR((F4/E4),"") -> 5.4 | E4: 10 | F4: =IFERROR((L4-K4),"") -> 54 | G4: 3.5 | H4: =ROUNDUP(SUMPRODUCT(B5:B7, C5:C7)/1000,1) -> 44 | I4: =IFERROR((S4*E4),"") -> 40 | J4: =IFERROR(VLOOKUP(C4,[2]Sheet1!$D:$J,7,0),"") -> 60 | K4: =IFERROR((I4+J4),"") -> 100 | L4: =IFERROR((G4*H4),"") -> 154 | M4: =IFERROR(K4-L4,"") -> -54 | N4: =IFERROR((K4/H4),"") -> 2.2727273 | P4: 10 | Q4: 5150 | R4: =O4*P4*Q4 -> 0 | S4: =SUM(Y4,T4:X4) -> 4 | U4: 4 | AA4: =IFERROR(H4*7.5/E4/7,"") -> 4.7142857
A5: THE근본김밥 | B5: =ROUNDUP(HLOOKUP(A5,'야채 계산기'!$2:$3,2,0),0) -> 2840 | C5: 8.16 | D5: =IFERROR((F5/E5),"") | I5: =IFERROR((S5*E5),"") -> 0 | J5: =IFERROR(VLOOKUP(C5,[2]Sheet1!$D:$J,7,0),"") | K5: =IFERROR((I5+J5),"") | L5: =IFERROR((G5*H5),"") -> 0 | M5: =IFERROR(K5-L5,"") | S5: =SUM(Y5,T5:X5) -> 226600 | T5: =51500*1.1*T4 -> 0 | U5: =51500*1.1*U4 -> 226600 | V5: =51500*1.1*V4 -> 0 | W5: =51500*1.1*W4 -> 0 | X5: =51500*1.1*X4 -> 0 | Y5: =51500*1.1*Y4 -> 0 | AA5: =IFERROR(H5*7.5/E5/7,"")
A6: 참치김치볶음김밥 | B6: =ROUNDUP(HLOOKUP(A6,'야채 계산기'!$2:$3,2,0),0) -> 1780 | C6: 8.39 | D6: =IFERROR((F6/E6),"") | I6: =IFERROR((S6*E6),"") -> 0 | J6: =IFERROR(VLOOKUP(C6,[2]Sheet1!$D:$J,7,0),"") | K6: =IFERROR((I6+J6),"") | L6: =IFERROR((G6*H6),"") -> 0 | M6: =IFERROR(K6-L6,"") | S6: =SUM(Y6,T6:X6) -> 0 | AA6: =IFERROR(H6*7.5/E6/7,"")
A7: 필름)진미채치즈김밥 | B7: =ROUNDUP(HLOOKUP(A7,'야채 계산기'!$2:$3,2,0),0) -> 720 | C7: ='[1]플름)진미채치즈김밥(26.08.25)'!$B$15 -> 8.16 | D7: =IFERROR((F7/E7),"") | I7: =IFERROR((S7*E7),"") -> 0 | J7: =IFERROR(VLOOKUP(C7,[2]Sheet1!$D:$J,7,0),"") | K7: =IFERROR((I7+J7),"") | L7: =IFERROR((G7*H7),"") -> 0 | M7: =IFERROR(K7-L7,"") | S7: =SUM(Y7,T7:X7) -> 0 | AA7: =IFERROR(H7*7.5/E7/7,"")
C8: [냉장]숯불갈비맛스모크햄세절48(1KG*10) | D8: =IFERROR((F8/E8),"") | E8: 10 | F8: =IFERROR((L8-K8),"") | G8: 3.5 | H8: =ROUNDUP(SUMPRODUCT(B9:B11, C9:C11)/1000,1) -> 0 | I8: =IFERROR((S8*E8),"") -> 40 | J8: =IFERROR(VLOOKUP(C8,[2]Sheet1!$D:$J,7,0),"") | K8: =IFERROR((I8+J8),"") | L8: =IFERROR((G8*H8),"") -> 0 | M8: =IFERROR(K8-L8,"") | N8: =IFERROR((K8/H8),"") | P8: 10 | Q8: 6900 | R8: =O8*P8*Q8 -> 0 | S8: =SUM(Y8,T8:X8) -> 4 | U8: 2 | V8: 2 | AA8: =IFERROR(H8*7.5/E8/7,"") -> 0
A9: 용기)에그햄꼬마김밥 | B9: =ROUNDUP(HLOOKUP(A9,'야채 계산기'!$2:$3,2,0),0) -> 0 | C9: 7.5 | D9: =IFERROR((F9/E9),"") | I9: =IFERROR((S9*E9),"") -> 0 | J9: =IFERROR(VLOOKUP(C9,[2]Sheet1!$D:$J,7,0),"") | K9: =IFERROR((I9+J9),"") | L9: =IFERROR((G9*H9),"") -> 0 | M9: =IFERROR(K9-L9,"") | S9: =SUM(Y9,T9:X9) -> 303600 | T9: =69000*1.1*T8 -> 0 | U9: =69000*1.1*U8 -> 151800 | V9: =69000*1.1*V8 -> 151800 | W9: =69000*1.1*W8 -> 0 | X9: =69000*1.1*X8 -> 0 | Y9: =69000*1.1*Y8 -> 0 | AA9: =IFERROR(H9*7.5/E9/7,"")
C10: [냉장] 알뜰주부진주줄줄이(1kg*10봉) | D10: =IFERROR((F10/E10),"") -> 0.285 | E10: 10 | F10: =IFERROR((L10-K10),"") -> 2.85 | G10: =G4 -> 3.5 | H10: =ROUNDUP(SUMPRODUCT(B12,C12)/1000,1) -> 11.1 | I10: =IFERROR((S10*E10),"") -> 0 | J10: =IFERROR(VLOOKUP(C10,[2]Sheet1!$D:$J,7,0),"") -> 36 | K10: =IFERROR((I10+J10),"") -> 36 | L10: =IFERROR((G10*H10),"") -> 38.85 | M10: =IFERROR(K10-L10,"") -> -2.85 | N10: =IFERROR((K10/H10),"") -> 3.2432432 | P10: 10 | Q10: 5500 | R10: =O10*P10*Q10 -> 0 | S10: =SUM(Y10,T10:X10) -> 0 | AA10: =IFERROR(H10*7.5/E10/7,"") -> 1.1892857
D11: =IFERROR((F11/E11),"") | I11: =IFERROR((S11*E11),"") -> 0 | J11: =IFERROR(VLOOKUP(C11,[2]Sheet1!$D:$J,7,0),"") | K11: =IFERROR((I11+J11),"") | L11: =IFERROR((G11*H11),"") -> 0 | M11: =IFERROR(K11-L11,"") | N11: =IFERROR((K11/H11),"") | R11: =O11*P11*Q11 -> 0 | S11: =SUM(Y11,T11:X11) -> 0 | T11: =55000*1.1*T10 -> 0 | U11: =55000*1.1*U10 -> 0 | V11: =55000*1.1*V10 -> 0 | W11: =55000*1.1*W10 -> 0 | X11: =55000*1.1*X10 -> 0 | Y11: =55000*1.1*Y10 -> 0 | AA11: =IFERROR(H11*7.5/E11/7,"")
A12: 혜자)반반제육 | B12: =ROUNDUP(HLOOKUP(A12,'야채 계산기'!$2:$3,2,0),0) -> 1170 | C12: 9.44 | D12: =IFERROR((F12/E12),"") | I12: =IFERROR((S12*E12),"") -> 0 | J12: =IFERROR(VLOOKUP(C12,[2]Sheet1!$D:$J,7,0),"") | K12: =IFERROR((I12+J12),"") | L12: =IFERROR((G12*H12),"") -> 0 | M12: =IFERROR(K12-L12,"") | S12: =SUM(Y12,T12:X12) -> 908600 | T12: 378400 | U12: =U5+U11+U9 -> 378400 | V12: =V5+V11+V9 -> 151800 | W12: =W5+W11+W9 -> 0 | X12: =X5+X11+X9 -> 0 | Y12: =Y5+Y11+Y9 -> 0 | AA12: =IFERROR(H12*7.5/E12/7,"")
D13: =IFERROR((F13/E13),"") | I13: =IFERROR((S13*E13),"") -> 0 | J13: =IFERROR(VLOOKUP(C13,[2]Sheet1!$D:$J,7,0),"") | K13: =IFERROR((I13+J13),"") | L13: =IFERROR((G13*H13),"") -> 0 | M13: =IFERROR(K13-L13,"") | S13: =SUM(Y13,T13:X13) -> 0 | AA13: =IFERROR(H13*7.5/E13/7,"")
A14: 씨제이제일제당 (D-1) 월화수목금토 | B14: CJ전산 11시 | D14: =IFERROR((F14/E14),"") | I14: =IFERROR((S14*E14),"") -> 0 | J14: =IFERROR(VLOOKUP(C14,[2]Sheet1!$D:$J,7,0),"") | K14: =IFERROR((I14+J14),"") | L14: =IFERROR((G14*H14),"") -> 0 | M14: =IFERROR(K14-L14,"") | N14: =IFERROR((K14/H14),"") | R14: =O14*P14*Q14 -> 0 | S14: =SUM(Y14,T14:X14) -> 0 | AA14: =IFERROR(H14*7.5/E14/7,"")
C15: [냉동] 간장돼지불고기(3KG*3EA) | D15: =IFERROR((F15/E15),"") -> 34.283333 | E15: 3 | F15: =IFERROR((L15-K15),"") -> 102.85 | G15: 5.5 | H15: =ROUNDUP(SUMPRODUCT(B16:B17,C16:C17)/3000,1) -> 18.7 | I15: =IFERROR((S15*E15),"") -> 0 | J15: =IFERROR(VLOOKUP(C15,[2]Sheet1!$D:$J,7,0),"") -> 0 | K15: =IFERROR((I15+J15),"") -> 0 | L15: =IFERROR((G15*H15),"") -> 102.85 | M15: =IFERROR(K15-L15,"") -> -102.85 | N15: =IFERROR((K15/H15),"") -> 0 | Q15: 21000 | R15: =O15*P15*Q15 -> 0 | S15: =SUM(Y15,T15:X15) -> 0 | AA15: =IFERROR(H15*7.5/E15/7,"") -> 6.6785714
A16: NEW혜자)백설갈비양념제육 | C16: ='[1]NEW혜자)백설갈비양념제육(26.07.28)'!$B$7 -> 125.54 | I16: =IFERROR((S16*E16),"") -> 0 | J16: =IFERROR(VLOOKUP(C16,[2]Sheet1!$D:$J,7,0),"") | K16: =IFERROR((I16+J16),"") | L16: =IFERROR((G16*H16),"") -> 0 | M16: =IFERROR(K16-L16,"") | S16: =SUM(Y16,T16:X16) -> 318600 | T16: 53100 | U16: 53100 | V16: 53100 | W16: 53100 | X16: 53100 | Y16: 53100 | AA16: =IFERROR(H16*7.5/E16/7,"")
A17: 뭘좋아할지몰라다넣어봤어 | B17: =ROUNDUP(HLOOKUP(A17,'야채 계산기'!$2:$3,2,0)*1.03,0) -> 1113 | C17: ='[1]뭘좋아할지몰라다넣어봤어(26.08.11)'!$B$6 -> 50.22 | I17: =IFERROR((S17*E17),"") -> 0 | J17: =IFERROR(VLOOKUP(C17,[2]Sheet1!$D:$J,7,0),"") | K17: =IFERROR((I17+J17),"") | L17: =IFERROR((G17*H17),"") -> 0 | M17: =IFERROR(K17-L17,"") | S17: =SUM(Y17,T17:X17) -> 0 | AA17: =IFERROR(H17*7.5/E17/7,"")
C18: [냉동]계란옷입은동그랑땡(1kg*8ea) | D18: =IFERROR((F18/E18),"") -> 18.5625 | E18: 8 | F18: =IFERROR((L18-K18),"") -> 148.5 | G18: =G15 -> 5.5 | H18: =ROUNDUP((B19*C19)/46,0) -> 27 | I18: =IFERROR((S18*E18),"") -> 0 | J18: =IFERROR(VLOOKUP(C18,[2]Sheet1!$D:$J,7,0),"") -> 0 | K18: =IFERROR((I18+J18),"") -> 0 | L18: =IFERROR((G18*H18),"") -> 148.5 | M18: =IFERROR(K18-L18,"") -> -148.5 | N18: =IFERROR((K18/H18),"") -> 0 | Q18: 7100 | R18: =O18*P18*Q18 -> 0 | S18: =SUM(Y18,T18:X18) -> 0 | AA18: =IFERROR(H18*7.5/E18/7,"") -> 3.6160714
A19: 혜자)반반제육 | B19: =ROUNDUP(HLOOKUP(A19,'야채 계산기'!$2:$3,2,0)*1.03,0) -> 1206 | C19: 1 | I19: =IFERROR((S19*E19),"") -> 0 | J19: =IFERROR(VLOOKUP(C19,[2]Sheet1!$D:$J,7,0),"") | K19: =IFERROR((I19+J19),"") | L19: =IFERROR((G19*H19),"") -> 0 | M19: =IFERROR(K19-L19,"") | S19: =SUM(Y19,T19:X19) -> 0 | AA19: =IFERROR(H19*7.5/E19/7,"")
C20: [냉동] 크레잇)고추장돼지불고기(3KG*3EA) | D20: =IFERROR((F20/E20),"") -> 2.75 | E20: 3 | F20: =IFERROR((L20-K20),"") -> 8.25 | G20: =G15 -> 5.5 | H20: =ROUNDUP(SUMPRODUCT(B21,C21)/3000,1) -> 1.5 | I20: =IFERROR((S20*E20),"") -> 0 | J20: =IFERROR(VLOOKUP(C20,[2]Sheet1!$D:$J,7,0),"") -> 0 | K20: =IFERROR((I20+J20),"") -> 0 | L20: =IFERROR((G20*H20),"") -> 8.25 | M20: =IFERROR(K20-L20,"") -> -8.25 | N20: =IFERROR((K20/H20),"") -> 0 | Q20: 18323 | R20: =O20*P20*Q20 -> 0 | S20: =SUM(Y20,T20:X20) -> 0 | AA20: =IFERROR(H20*7.5/E20/7,"") -> 0.53571429
A21: 착한제육덮밥 | B21: =ROUNDUP(HLOOKUP(A21,'야채 계산기'!$2:$3,2,0)*1.03,0) -> 31 | C21: 140.97 | I21: =IFERROR((S21*E21),"") -> 0 | J21: =IFERROR(VLOOKUP(C21,[2]Sheet1!$D:$J,7,0),"") | K21: =IFERROR((I21+J21),"") | L21: =IFERROR((G21*H21),"") -> 0 | M21: =IFERROR(K21-L21,"") | S21: =SUM(Y21,T21:X21) -> 0
A22: 직화)한돈제육쌈김밥 | B22: =ROUNDUP(HLOOKUP(A22,'야채 계산기'!$2:$3,2,0),0) -> 1190 | C22: =73.27*0.78 -> 57.1506 | D22: =IFERROR((F22/E22),"") | I22: =IFERROR((S22*E22),"") -> 0 | J22: =IFERROR(VLOOKUP(C22,[2]Sheet1!$D:$J,7,0),"") | K22: =IFERROR((I22+J22),"") | L22: =IFERROR((G22*H22),"") -> 0 | M22: =IFERROR(K22-L22,"") | N22: =IFERROR((K22/H22),"") | R22: =O22*P22*Q22 -> 0 | S22: =SUM(Y22,T22:X22) -> 0 | AA22: =IFERROR(H22*7.5/E22/7,"")
B23: 갯수토핑 | C23: [냉동] 크레잇꼬마돈카츠(1kg(90ea)*8봉) | D23: =IFERROR((F23/E23),"") -> 28.18125 | E23: 8 | F23: =IFERROR((L23-K23),"") -> 225.45 | G23: 5.5 | H23: =ROUNDUP(SUMPRODUCT(B24:B25,C24:C25)/90,1) -> 75.9 | I23: =IFERROR((S23*E23),"") -> 80 | J23: =IFERROR(VLOOKUP(C23,[2]Sheet1!$D:$J,7,0),"") -> 112 | K23: =IFERROR((I23+J23),"") -> 192 | L23: =IFERROR((G23*H23),"") -> 417.45 | M23: =IFERROR(K23-L23,"") -> -225.45 | N23: =IFERROR((K23/H23),"") -> 2.5296443 | Q23: 4900 | R23: =O23*P23*Q23 -> 0 | S23: =SUM(Y23,T23:X23) -> 10 | V23: 10 | AA23: =IFERROR(H23*7.5/E23/7,"") -> 10.165179
A24: 혜자)돌아온명불허전 | B24: =ROUNDUP(HLOOKUP(A24,'야채 계산기'!$2:$3,2,0),0) -> 2200 | C24: 2 | I24: =IFERROR((S24*E24),"") -> 0 | J24: =IFERROR(VLOOKUP(C24,[2]Sheet1!$D:$J,7,0),"") | K24: =IFERROR((I24+J24),"") | L24: =IFERROR((G24*H24),"") -> 0 | M24: =IFERROR(K24-L24,"") | S24: =SUM(Y24,T24:X24) -> 235200 | T24: 39200 | U24: 39200 | V24: 39200 | W24: 39200 | X24: 39200 | Y24: 39200 | AA24: =IFERROR(H24*7.5/E24/7,"")
A25: NEW혜자)백설갈비양념제육 | B25: =ROUNDUP(HLOOKUP(A25,'야채 계산기'!$2:$3,2,0),0) -> 810 | C25: 3 | I25: =IFERROR((S25*E25),"") -> 0 | J25: =IFERROR(VLOOKUP(C25,[2]Sheet1!$D:$J,7,0),"") | K25: =IFERROR((I25+J25),"") | L25: =IFERROR((G25*H25),"") -> 0 | M25: =IFERROR(K25-L25,"") | S25: =SUM(Y25,T25:X25) -> 0 | AA25: =IFERROR(H25*7.5/E25/7,"")
D26: =IFERROR((F26/E26),"") | I26: =IFERROR((S26*E26),"") -> 0 | J26: =IFERROR(VLOOKUP(C26,[2]Sheet1!$D:$J,7,0),"") | K26: =IFERROR((I26+J26),"") | L26: =IFERROR((G26*H26),"") -> 0 | M26: =IFERROR(K26-L26,"") | S26: =SUM(Y26,T26:X26) -> 0 | AA26: =IFERROR(H26*7.5/E26/7,"")
D27: =IFERROR((F27/E27),"") | I27: =IFERROR((S27*E27),"") -> 0 | J27: =IFERROR(VLOOKUP(C27,[2]Sheet1!$D:$J,7,0),"") | K27: =IFERROR((I27+J27),"") | L27: =IFERROR((G27*H27),"") -> 0 | S27: =SUM(Y27,T27:X27) -> 0 | AA27: =IFERROR(H27*7.5/E27/7,"")
B28: 갯수토핑 | C28: [냉장]칼집두툼비엔나(1KG*10봉) | D28: =IFERROR((F28/E28),"") | E28: 10 | F28: =IFERROR((L28-K28),"") | G28: =G19 -> 0 | H28: =ROUNDUP((B29*C29+B30*C30)/50,1) -> #N/A | I28: =IFERROR((S28*E28),"") -> 0 | J28: =IFERROR(VLOOKUP(C28,[2]Sheet1!$D:$J,7,0),"") | K28: =IFERROR((I28+J28),"") | L28: =IFERROR((G28*H28),"") | M28: =IFERROR(K28-L28,"") | N28: =IFERROR((K28/H28),"") | Q28: 6300 | R28: =O28*P28*Q28 -> 0 | S28: =SUM(Y28,T28:X28) -> 0 | AA28: =IFERROR(H28*7.5/E28/7,"")
A29: NEW혜자)돈까스고추장제육 | B29: =ROUNDUP(HLOOKUP(A29,'야채 계산기'!$2:$3,2,0)*1.03,0) -> #N/A | C29: 1 | I29: =IFERROR((S29*E29),"") -> 0 | J29: =IFERROR(VLOOKUP(C29,[2]Sheet1!$D:$J,7,0),"") | K29: =IFERROR((I29+J29),"") | L29: =IFERROR((G29*H29),"") -> 0 | M29: =IFERROR(K29-L29,"") | S29: =SUM(Y29,T29:X29) -> 0 | AA29: =IFERROR(H29*7.5/E29/7,"")
A30: 혜자)돌아온등심돈까스 | B30: =ROUNDUP(HLOOKUP(A30,'야채 계산기'!$2:$3,2,0)*1.03,0) -> 660 | C30: 0.5 | I30: =IFERROR((S30*E30),"") -> 0 | J30: =IFERROR(VLOOKUP(C30,[2]Sheet1!$D:$J,7,0),"") | K30: =IFERROR((I30+J30),"") | L30: =IFERROR((G30*H30),"") -> 0 | M30: =IFERROR(K30-L30,"") | S30: =SUM(Y30,T30:X30) -> 0 | AA30: =IFERROR(H30*7.5/E30/7,"")
D31: =IFERROR((F31/E31),"") | I31: =IFERROR((S31*E31),"") -> 0 | J31: =IFERROR(VLOOKUP(C31,[2]Sheet1!$D:$J,7,0),"") | K31: =IFERROR((I31+J31),"") | L31: =IFERROR((G31*H31),"") -> 0 | M31: =IFERROR(K31-L31,"") | S31: =SUM(Y31,T31:X31) -> 0 | AA31: =IFERROR(H31*7.5/E31/7,"")
D32: =IFERROR((F32/E32),"") | I32: =IFERROR((S32*E32),"") -> 0 | J32: =IFERROR(VLOOKUP(C32,[2]Sheet1!$D:$J,7,0),"") | K32: =IFERROR((I32+J32),"") | L32: =IFERROR((G32*H32),"") -> 0 | M32: =IFERROR(K32-L32,"") | S32: =SUM(Y32,T32:X32) -> 0 | AA32: =IFERROR(H32*7.5/E32/7,"")
A33: 씨제이제일제당 (D-1) 월화수목금토 | B33: CJ전산 16시 | D33: =IFERROR((F33/E33),"") | I33: =IFERROR((S33*E33),"") -> 0 | J33: =IFERROR(VLOOKUP(C33,[2]Sheet1!$D:$J,7,0),"") | K33: =IFERROR((I33+J33),"") | L33: =IFERROR((G33*H33),"") -> 0 | M33: =IFERROR(K33-L33,"") | N33: =IFERROR((K33/H33),"") | R33: =O33*P33*Q33 -> 0 | S33: =SUM(Y33,T33:X33) -> 0 | AA33: =IFERROR(H33*7.5/E33/7,"")
C34: [상온] 대두유(18L*통) | D34: =IFERROR((F34/E34),"") -> -52 | E34: 1 | F34: =IFERROR((L34-K34),"") -> -52 | G34: 3.5 | H34: 24 | I34: =IFERROR((S34*E34),"") -> 30 | J34: =IFERROR(VLOOKUP(C34,[2]Sheet1!$D:$J,7,0),"") -> 106 | K34: =IFERROR((I34+J34),"") -> 136 | L34: =IFERROR((G34*H34),"") -> 84 | M34: =IFERROR(K34-L34,"") -> 52 | N34: =IFERROR((K34/H34),"") -> 5.6666667 | Q34: 35742 | R34: =O34*P34*Q34 -> 0 | S34: =SUM(Y34,T34:X34) -> 30 | U34: 30 | AA34: =IFERROR(H34*7.5/E34/7,"") -> 25.714286
A35: 일사용량+튀김실+취반실 | D35: =IFERROR((F35/E35),"") | I35: =IFERROR((S35*E35),"") -> 0 | J35: =IFERROR(VLOOKUP(C35,[2]Sheet1!$D:$J,7,0),"") | K35: =IFERROR((I35+J35),"") | L35: =IFERROR((G35*H35),"") -> 0 | M35: =IFERROR(K35-L35,"") | N35: =IFERROR((K35/H35),"") | R35: =O35*P35*Q35 -> 0 | S35: =SUM(Y35,T35:X35) -> 240000 | T35: 40000 | U35: 40000 | V35: 40000 | W35: 40000 | X35: 40000 | Y35: 40000 | AA35: =IFERROR(H35*7.5/E35/7,"")
C36: [상온] 스팸(340g*20캔) | D36: =IFERROR((F36/E36),"") -> 158.9 | E36: 20 | F36: =IFERROR((L36-K36),"") -> 3178 | G36: =G34 -> 3.5 | H36: =ROUNDUP(SUMPRODUCT(B37:B41, C37:C41)/340,1) -> 908 | I36: =IFERROR((S36*E36),"") -> 0 | J36: =IFERROR(VLOOKUP(C36,[2]Sheet1!$D:$J,7,0),"") -> 0 | K36: =IFERROR((I36+J36),"") -> 0 | L36: =IFERROR((G36*H36),"") -> 3178 | M36: =IFERROR(K36-L36,"") -> -3178 | N36: =IFERROR((K36/H36),"") -> 0 | Q36: 3150 | R36: =O36*P36*Q36 -> 0 | S36: =SUM(Y36,T36:X36) -> 0 | AA36: =IFERROR(H36*7.5/E36/7,"") -> 48.642857
A37: 더큰)스팸계란볶음밥 | B37: =ROUNDUP(HLOOKUP(A37,'야채 계산기'!$2:$3,2,0),0) -> 4900 | C37: 18.76 | D37: =IFERROR((F37/E37),"") | I37: =IFERROR((S37*E37),"") -> 0 | J37: =IFERROR(VLOOKUP(C37,[2]Sheet1!$D:$J,7,0),"") | K37: =IFERROR((I37+J37),"") | L37: =IFERROR((G37*H37),"") -> 0 | M37: =IFERROR(K37-L37,"") | N37: =IFERROR((K37/H37),"") | S37: =SUM(Y37,T37:X37) -> 0 | AA37: =IFERROR(H37*7.5/E37/7,"")
A38: 더큰)스팸김치볶음밥 | B38: =ROUNDUP(HLOOKUP(A38,'야채 계산기'!$2:$3,2,0),0) -> 6030 | C38: 19 | I38: =IFERROR((S38*E38),"") -> 0 | J38: =IFERROR(VLOOKUP(C38,[2]Sheet1!$D:$J,7,0),"") | K38: =IFERROR((I38+J38),"") | L38: =IFERROR((G38*H38),"") -> 0 | M38: =IFERROR(K38-L38,"") | S38: =SUM(Y38,T38:X38) -> 0 | AA38: =IFERROR(H38*7.5/E38/7,"")
A39: 스팸계란치즈김밥 | B39: =ROUNDUP(HLOOKUP(A39,'야채 계산기'!$2:$3,2,0),0) -> 1340 | C39: 32.1 | I39: =IFERROR((S39*E39),"") -> 0 | J39: =IFERROR(VLOOKUP(C39,[2]Sheet1!$D:$J,7,0),"") | K39: =IFERROR((I39+J39),"") | L39: =IFERROR((G39*H39),"") -> 0 | M39: =IFERROR(K39-L39,"") | S39: =SUM(Y39,T39:X39) -> 0 | AA39: =IFERROR(H39*7.5/E39/7,"")
A40: NEW스팸무스비 | B40: =ROUNDUP(HLOOKUP(A40,'야채 계산기'!$2:$3,2,0),0) -> 2090 | C40: ='[1]스팸무스비(25.8.26)'!$B$11 -> 28.33 | I40: =IFERROR((S40*E40),"") -> 0 | J40: =IFERROR(VLOOKUP(C40,[2]Sheet1!$D:$J,7,0),"") | K40: =IFERROR((I40+J40),"") | L40: =IFERROR((G40*H40),"") -> 0 | M40: =IFERROR(K40-L40,"") | S40: =SUM(Y40,T40:X40) -> 0 | AA40: =IFERROR(H40*7.5/E40/7,"")
...

Sheet 마요네즈, 참치
B2: 마요네즈 | D2: 총 필요량 | E2: =SUM(F5:F14) -> 304224.25 | H2: 참치 | J2: 총 필요량 | K2: =SUM(L5:L9) -> 198567.93
B4: 예상수량 | C4: 제품명 | D4: 원물중량 | E4: 1.1 | F4: 필요량 | H4: 예상수량 | I4: 제품명 | J4: 원물중량 | K4: 1.1 | L4: 필요량
B5: =INDEX('야채 계산기'!$3:$3,MATCH(C5,'야채 계산기'!$2:$2,0)) -> 6030 | C5: 더큰)스팸김치볶음밥 | D5: 12.62 | E5: =B5*$E$4 -> 6633 | F5: =D5*E5 -> 83708.46 | H5: =INDEX('야채 계산기'!$3:$3,MATCH(I5,'야채 계산기'!$2:$2,0)) -> 170 | I5: 슈퍼)착한참치마요김밥 | J5: 43.99 | K5: =H5*$E$4 -> 187 | L5: =J5*K5 -> 8226.13
B6: =INDEX('야채 계산기'!$3:$3,MATCH(C6,'야채 계산기'!$2:$2,0)) -> 104 | C6: 슈퍼)착한핫도그(사라다) | D6: ='[1]슈퍼)착한1900핫도그-사라다(25.09.02)'!$B$6 -> 9.7 | E6: =B6*$E$4 -> 114.4 | F6: =D6*E6 -> 1109.68 | H6: =INDEX('야채 계산기'!$3:$3,MATCH(I6,'야채 계산기'!$2:$2,0)) -> 3620 | I6: 더큰)리챔참치마요 | J6: 19.42 | K6: =H6*$E$4 -> 3982 | L6: =J6*K6 -> 77330.44
B7: =INDEX('야채 계산기'!$3:$3,MATCH(C7,'야채 계산기'!$2:$2,0)) -> 1100 | C7: 왕돈까스김밥 | D7: 11.34 | E7: =B7*$E$4 -> 1210 | F7: =D7*E7 -> 13721.4 | H7: =INDEX('야채 계산기'!$3:$3,MATCH(I7,'야채 계산기'!$2:$2,0)) -> 4420 | I7: 종가)들기름묵은지참치 | J7: 11.66 | K7: =H7*$E$4 -> 4862 | L7: =J7*K7 -> 56690.92
B8: =INDEX('야채 계산기'!$3:$3,MATCH(C8,'야채 계산기'!$2:$2,0)) -> 170 | C8: 슈퍼)착한참치마요김밥 | D8: 19.05 | E8: =B8*$E$4 -> 187 | F8: =D8*E8 -> 3562.35 | H8: =INDEX('야채 계산기'!$3:$3,MATCH(I8,'야채 계산기'!$2:$2,0)) -> 1780 | I8: 참치김치볶음김밥 | J8: 21.88 | K8: =H8*$E$4 -> 1958 | L8: =J8*K8 -> 42841.04
B9: =INDEX('야채 계산기'!$3:$3,MATCH(C9,'야채 계산기'!$2:$2,0)) -> 3620 | C9: 더큰)리챔참치마요 | D9: 8.98 | E9: =B9*$E$4 -> 3982 | F9: =D9*E9 -> 35758.36 | H9: =INDEX('야채 계산기'!$3:$3,MATCH(I9,'야채 계산기'!$2:$2,0)) -> 1100 | I9: 무스비)햄&참치김치볶음밥 | J9: 11.14 | K9: =H9*$E$4 -> 1210 | L9: =J9*K9 -> 13479.4
B10: =INDEX('야채 계산기'!$3:$3,MATCH(C10,'야채 계산기'!$2:$2,0)) -> 4420 | C10: 종가)들기름묵은지참치 | D10: 5.39 | E10: =B10*$E$4 -> 4862 | F10: =D10*E10 -> 26206.18
A11: 오뚜기 | B11: =INDEX('야채 계산기'!$3:$3,MATCH(C11,'야채 계산기'!$2:$2,0)) -> 4900 | C11: 더큰)스팸계란볶음밥 | D11: 9.56 | E11: =B11*$E$4 -> 5390 | F11: =D11*E11 -> 51528.4
A12: 오뚜기 | B12: =INDEX('야채 계산기'!$3:$3,MATCH(C12,'야채 계산기'!$2:$2,0)) -> 1780 | C12: 참치김치볶음김밥 | D12: 22.17 | E12: =B12*$E$4 -> 1958 | F12: =D12*E12 -> 43408.86
A13: 오뚜기 | B13: =INDEX('야채 계산기'!$3:$3,MATCH(C13,'야채 계산기'!$2:$2,0)) -> 1100 | C13: 무스비)햄&참치김치볶음밥 | D13: 5.39 | E13: =B13*$E$4 -> 1210 | F13: =D13*E13 -> 6521.9
B14: =INDEX('야채 계산기'!$3:$3,MATCH(C14,'야채 계산기'!$2:$2,0)) -> 1820 | C14: 넷플)K스타일떡갈비김밥 | D14: 19.33 | E14: =B14*$E$4 -> 2002 | F14: =D14*E14 -> 38698.66
C1193: [상온] 오도리가쓰오부시(500g*4ea) | E1193: 4
C1194: ='[1]유우카의알찬정식(25.7.15)'!$B$27 -> 0.51
H1204: =ROUNDUP((B1194*C1194)/500,0) -> 0

Sheet 정제염
B2: 정제염 | D2: 총 필요량 | E2: =SUM(F5:F22) -> 24367.255 | F2: =E2/25000 -> 0.9746902
B4: 예상수량 | C4: 제품명 | D4: 원물중량 | E4: 1.1 | F4: 필요량
B5: =INDEX('야채 계산기'!$3:$3,MATCH(C5,'야채 계산기'!$2:$2,0)) -> 3150 | C5: 삼각)전주비빔 | D5: 0.18 | E5: =B5*$E$4 -> 3465 | F5: =D5*E5 -> 623.7
B6: =INDEX('야채 계산기'!$3:$3,MATCH(C6,'야채 계산기'!$2:$2,0)) -> 1190 | C6: 직화)한돈제육쌈김밥 | D6: 0.82 | E6: =B6*$E$4 -> 1309 | F6: =D6*E6 -> 1073.38 | H6: 취반염수,데침
B7: =INDEX('야채 계산기'!$3:$3,MATCH(C7,'야채 계산기'!$2:$2,0)) -> 6030 | C7: 더큰)스팸김치볶음밥 | D7: 0.37 | E7: =B7*$E$4 -> 6633 | F7: =D7*E7 -> 2454.21
B8: =INDEX('야채 계산기'!$3:$3,MATCH(C8,'야채 계산기'!$2:$2,0)) -> 2090 | C8: NEW스팸무스비 | D8: ='[1]스팸무스비(25.8.26)'!$B$6 -> 0.37 | E8: =B8*$E$4 -> 2299 | F8: =D8*E8 -> 850.63
B9: =INDEX('야채 계산기'!$3:$3,MATCH(C9,'야채 계산기'!$2:$2,0)) -> 2840 | C9: THE근본김밥 | D9: 0.99 | E9: =B9*$E$4 -> 3124 | F9: =D9*E9 -> 3092.76
B10: =INDEX('야채 계산기'!$3:$3,MATCH(C10,'야채 계산기'!$2:$2,0)) -> 1170 | C10: 혜자)반반제육 | D10: 0.09 | E10: =B10*$E$4 -> 1287 | F10: =D10*E10 -> 115.83
B11: =INDEX('야채 계산기'!$3:$3,MATCH(C11,'야채 계산기'!$2:$2,0)) -> 3620 | C11: 더큰)리챔참치마요 | D11: 0.75 | E11: =B11*$E$4 -> 3982 | F11: =D11*E11 -> 2986.5 | H11: 취반염수
B12: =INDEX('야채 계산기'!$3:$3,MATCH(C12,'야채 계산기'!$2:$2,0)) -> 4420 | C12: 종가)들기름묵은지참치 | D12: 0.82 | E12: =B12*$E$4 -> 4862 | F12: =D12*E12 -> 3986.84 | H12: 볶음용
B13: =INDEX('야채 계산기'!$3:$3,MATCH(C13,'야채 계산기'!$2:$2,0)) -> 4900 | C13: 더큰)스팸계란볶음밥 | D13: 0.33 | E13: =B13*$E$4 -> 5390 | F13: =D13*E13 -> 1778.7 | H13: 취반염수
B14: =INDEX('야채 계산기'!$3:$3,MATCH(C14,'야채 계산기'!$2:$2,0)) -> 170 | C14: 슈퍼)착한참치마요김밥 | D14: 2.7 | E14: =B14*$E$4 -> 187 | F14: =D14*E14 -> 504.9 | H14: 취반염수
B15: =INDEX('야채 계산기'!$3:$3,MATCH(C15,'야채 계산기'!$2:$2,0)) -> 1100 | C15: 왕돈까스김밥 | D15: 0.54 | E15: =B15*$E$4 -> 1210 | F15: =D15*E15 -> 653.4 | H15: 데침용
B16: =INDEX('야채 계산기'!$3:$3,MATCH(C16,'야채 계산기'!$2:$2,0)) -> 1050 | C16: 불고기치즈김밥 | D16: 0.9 | E16: =B16*$E$4 -> 1155 | F16: =D16*E16 -> 1039.5
B17: =INDEX('야채 계산기'!$3:$3,MATCH(C17,'야채 계산기'!$2:$2,0)) -> 55 | C17: 슈퍼)착한제육비빔밥 | D17: ='[1]착한비빔밥(25.10.23)'!$B$15 -> 0.17 | E17: =B17*$E$4 -> 60.5 | F17: =D17*E17 -> 10.285
B18: =INDEX('야채 계산기'!$3:$3,MATCH(C18,'야채 계산기'!$2:$2,0)) -> 1290 | C18: 더블치즈소시지김밥 | D18: 0.54 | E18: =B18*$E$4 -> 1419 | F18: =D18*E18 -> 766.26
B19: =INDEX('야채 계산기'!$3:$3,MATCH(C19,'야채 계산기'!$2:$2,0)) -> 1780 | C19: 참치김치볶음김밥 | D19: 0.59 | E19: =B19*$E$4 -> 1958 | F19: =D19*E19 -> 1155.22
B20: =INDEX('야채 계산기'!$3:$3,MATCH(C20,'야채 계산기'!$2:$2,0)) -> 1340 | C20: 스팸계란치즈김밥 | D20: =0.59+0.52+0.25 -> 1.36 | E20: =B20*$E$4 -> 1474 | F20: =D20*E20 -> 2004.64
B21: =INDEX('야채 계산기'!$3:$3,MATCH(C21,'야채 계산기'!$2:$2,0)) -> 140 | C21: 슈퍼)착한김치김밥 | D21: ='[1]착한김치김밥(250612)슈퍼'!$B$5 -> 3.3 | E21: =B21*$E$4 -> 154 | F21: =D21*E21 -> 508.2 | H21: 취반염수,데침
B22: =INDEX('야채 계산기'!$3:$3,MATCH(C22,'야채 계산기'!$2:$2,0)) -> 1100 | C22: 용기)광장시장꼬마김밥 | D22: 0.63 | E22: =B22*$E$4 -> 1210 | F22: =D22*E22 -> 762.3
C375: [냉동] 우유튀김(1kg*10ea)
H1199: =ROUNDUP((B1207*C1207)/500,0) -> 0
C1206: [상온] 오도리가쓰오부시(500g*4ea) | E1206: 4
C1207: ='[1]유우카의알찬정식(25.7.15)'!$B$27 -> 0.51

Sheet 바코드
B2: 삼각바코드 | D2: 총 필요량 | E2: =SUM(F5:F12) -> 25845.9 | H2: 김밥바코드 | J2: 총 필요량 | K2: =SUM(L5:L14) -> 11736.2 | N2: 도시락 바코드 | P2: 총 필요량 | Q2: =SUM(R5:R23) -> 16834.68
B4: 예상수량 | C4: 제품명 | D4: 수량(매수) | E4: 1.01 | F4: 필요량 | H4: 예상수량 | I4: 제품명 | J4: 수량(매수) | K4: 1.01 | L4: 필요량 | N4: 예상수량 | O4: 제품명 | P4: 수량(매수) | Q4: 1.01 | R4: 필요량
B5: =INDEX('야채 계산기'!$3:$3,MATCH(C5,'야채 계산기'!$2:$2,0)) -> 3150 | C5: 삼각)전주비빔 | D5: 1 | E5: =B5*$E$4 -> 3181.5 | F5: =D5*E5 -> 3181.5 | H5: =INDEX('야채 계산기'!$3:$3,MATCH(I5,'야채 계산기'!$2:$2,0)) -> 1290 | I5: 더블치즈소시지김밥 | J5: 1 | K5: =H5*$E$4 -> 1302.9 | L5: =J5*K5 -> 1302.9 | N5: =INDEX('야채 계산기'!$3:$3,MATCH(O5,'야채 계산기'!$2:$2,0)) -> 2200 | O5: 혜자)돌아온명불허전 | P5: 1 | Q5: =N5*$E$4 -> 2222 | R5: =P5*Q5 -> 2222
B6: =INDEX('야채 계산기'!$3:$3,MATCH(C6,'야채 계산기'!$2:$2,0)) -> 6030 | C6: 더큰)스팸김치볶음밥 | D6: 1 | E6: =B6*$E$4 -> 6090.3 | F6: =D6*E6 -> 6090.3 | H6: =INDEX('야채 계산기'!$3:$3,MATCH(I6,'야채 계산기'!$2:$2,0)) -> 170 | I6: 슈퍼)착한참치마요김밥 | J6: 1 | K6: =H6*$E$4 -> 171.7 | L6: =J6*K6 -> 171.7 | N6: =INDEX('야채 계산기'!$3:$3,MATCH(O6,'야채 계산기'!$2:$2,0)) -> 55 | O6: 슈퍼)착한제육비빔밥 | P6: 1 | Q6: =N6*$E$4 -> 55.55 | R6: =P6*Q6 -> 55.55
B7: =INDEX('야채 계산기'!$3:$3,MATCH(C7,'야채 계산기'!$2:$2,0)) -> 4420 | C7: 종가)들기름묵은지참치 | D7: 1 | E7: =B7*$E$4 -> 4464.2 | F7: =D7*E7 -> 4464.2 | H7: =INDEX('야채 계산기'!$3:$3,MATCH(I7,'야채 계산기'!$2:$2,0)) -> 1100 | I7: 왕돈까스김밥 | J7: 1 | K7: =H7*$E$4 -> 1111 | L7: =J7*K7 -> 1111 | N7: =INDEX('야채 계산기'!$3:$3,MATCH(O7,'야채 계산기'!$2:$2,0)) -> 2020 | O7: 혜자)통등심돈까스&치킨까스도시락 | P7: 1 | Q7: =N7*$E$4 -> 2040.2 | R7: =P7*Q7 -> 2040.2
B8: =INDEX('야채 계산기'!$3:$3,MATCH(C8,'야채 계산기'!$2:$2,0)) -> 4900 | C8: 더큰)스팸계란볶음밥 | D8: 1 | E8: =B8*$E$4 -> 4949 | F8: =D8*E8 -> 4949 | H8: =INDEX('야채 계산기'!$3:$3,MATCH(I8,'야채 계산기'!$2:$2,0)) -> 140 | I8: 슈퍼)착한김치김밥 | J8: 1 | K8: =H8*$E$4 -> 141.4 | L8: =J8*K8 -> 141.4 | N8: =INDEX('야채 계산기'!$3:$3,MATCH(O8,'야채 계산기'!$2:$2,0)) -> 810 | O8: NEW혜자)백설갈비양념제육 | P8: 1 | Q8: =N8*$E$4 -> 818.1 | R8: =P8*Q8 -> 818.1
B9: =INDEX('야채 계산기'!$3:$3,MATCH(C9,'야채 계산기'!$2:$2,0)) -> 1630 | C9: 더큰)추석맥적구이한상 | D9: 1 | E9: =B9*$E$4 -> 1646.3 | F9: =D9*E9 -> 1646.3 | H9: =INDEX('야채 계산기'!$3:$3,MATCH(I9,'야채 계산기'!$2:$2,0)) -> 1190 | I9: 직화)한돈제육쌈김밥 | J9: 1 | K9: =H9*$E$4 -> 1201.9 | L9: =J9*K9 -> 1201.9 | N9: =INDEX('야채 계산기'!$3:$3,MATCH(O9,'야채 계산기'!$2:$2,0)) -> 30 | O9: 착한제육덮밥 | P9: 1 | Q9: =N9*$E$4 -> 30.3 | R9: =P9*Q9 -> 30.3
B10: =INDEX('야채 계산기'!$3:$3,MATCH(C10,'야채 계산기'!$2:$2,0)) -> 3620 | C10: 더큰)리챔참치마요 | D10: 1 | E10: =B10*$E$4 -> 3656.2 | F10: =D10*E10 -> 3656.2 | H10: =INDEX('야채 계산기'!$3:$3,MATCH(I10,'야채 계산기'!$2:$2,0)) -> 1050 | I10: 불고기치즈김밥 | J10: 1 | K10: =H10*$E$4 -> 1060.5 | L10: =J10*K10 -> 1060.5 | N10: =INDEX('야채 계산기'!$3:$3,MATCH(O10,'야채 계산기'!$2:$2,0)) -> 640 | O10: 혜자)돌아온등심돈까스 | P10: 1 | Q10: =N10*$E$4 -> 646.4 | R10: =P10*Q10 -> 646.4
B11: =INDEX('야채 계산기'!$3:$3,MATCH(C11,'야채 계산기'!$2:$2,0)) -> 1840 | C11: 더큰)오징어&제육깻잎쌈밥 | D11: 1 | E11: =B11*$E$4 -> 1858.4 | F11: =D11*E11 -> 1858.4 | H11: =INDEX('야채 계산기'!$3:$3,MATCH(I11,'야채 계산기'!$2:$2,0)) -> 1340 | I11: 스팸계란치즈김밥 | J11: 1 | K11: =H11*$E$4 -> 1353.4 | L11: =J11*K11 -> 1353.4 | N11: =INDEX('야채 계산기'!$3:$3,MATCH(O11,'야채 계산기'!$2:$2,0)) -> 1100 | O11: 용기)광장시장꼬마김밥 | P11: 1 | Q11: =N11*$E$4 -> 1111 | R11: =P11*Q11 -> 1111
B12: =INDEX('야채 계산기'!$3:$3,MATCH(C12,'야채 계산기'!$2:$2,0)) -> 0 | C12: 커플)곱창김참치마요&전주비빔 | D12: 2 | E12: =B12*$E$4 -> 0 | F12: =D12*E12 -> 0 | H12: =INDEX('야채 계산기'!$3:$3,MATCH(I12,'야채 계산기'!$2:$2,0)) -> 2840 | I12: THE근본김밥 | J12: 1 | K12: =H12*$E$4 -> 2868.4 | L12: =J12*K12 -> 2868.4 | N12: =INDEX('야채 계산기'!$3:$3,MATCH(O12,'야채 계산기'!$2:$2,0)) -> 0 | O12: 용기)에그햄꼬마김밥 | P12: 1 | Q12: =N12*$E$4 -> 0 | R12: =P12*Q12 -> 0
H13: =INDEX('야채 계산기'!$3:$3,MATCH(I13,'야채 계산기'!$2:$2,0)) -> 1780 | I13: 참치김치볶음김밥 | J13: 1 | K13: =H13*$E$4 -> 1797.8 | L13: =J13*K13 -> 1797.8 | N13: =INDEX('야채 계산기'!$3:$3,MATCH(O13,'야채 계산기'!$2:$2,0)) -> 1080 | O13: 뭘좋아할지몰라다넣어봤어 | P13: 1 | Q13: =N13*$E$4 -> 1090.8 | R13: =P13*Q13 -> 1090.8
H14: =INDEX('야채 계산기'!$3:$3,MATCH(I14,'야채 계산기'!$2:$2,0)) -> 720 | I14: 필름)진미채치즈김밥 | J14: 1 | K14: =H14*$E$4 -> 727.2 | L14: =J14*K14 -> 727.2 | N14: =INDEX('야채 계산기'!$3:$3,MATCH(O14,'야채 계산기'!$2:$2,0)) -> 2090 | O14: NEW스팸무스비 | P14: 1 | Q14: =N14*$E$4 -> 2110.9 | R14: =P14*Q14 -> 2110.9
N15: =INDEX('야채 계산기'!$3:$3,MATCH(O15,'야채 계산기'!$2:$2,0)) -> 440 | O15: 무스비)햄&청양불고기 | P15: 1 | Q15: =N15*$E$4 -> 444.4 | R15: =P15*Q15 -> 444.4
N16: =INDEX('야채 계산기'!$3:$3,MATCH(O16,'야채 계산기'!$2:$2,0)) -> 1100 | O16: 무스비)햄&참치김치볶음밥 | P16: 1 | Q16: =N16*$E$4 -> 1111 | R16: =P16*Q16 -> 1111
N17: =INDEX('야채 계산기'!$3:$3,MATCH(O17,'야채 계산기'!$2:$2,0)) -> 1170 | O17: 혜자)반반제육 | P17: 1 | Q17: =N17*$E$4 -> 1181.7 | R17: =P17*Q17 -> 1181.7
N18: =INDEX('야채 계산기'!$3:$3,MATCH(O18,'야채 계산기'!$2:$2,0)) -> 129 | O18: 슈퍼)착한핫도그(오리지널) | P18: 1 | Q18: =N18*$E$4 -> 130.29 | R18: =P18*Q18 -> 130.29
N19: =INDEX('야채 계산기'!$3:$3,MATCH(O19,'야채 계산기'!$2:$2,0)) -> 1470 | O19: 두부김치제육 | P19: 1 | Q19: =N19*$E$4 -> 1484.7 | R19: =P19*Q19 -> 1484.7
N20: =INDEX('야채 계산기'!$3:$3,MATCH(O20,'야채 계산기'!$2:$2,0)) -> 104 | O20: 슈퍼)착한핫도그(사라다) | P20: 1 | Q20: =N20*$E$4 -> 105.04 | R20: =P20*Q20 -> 105.04
N21: =INDEX('야채 계산기'!$3:$3,MATCH(O21,'야채 계산기'!$2:$2,0)) -> 1680 | O21: 혜자)두툼돈까스&순창제육도시락 | P21: 1 | Q21: =N21*$E$4 -> 1696.8 | R21: =P21*Q21 -> 1696.8
N22: =INDEX('야채 계산기'!$3:$3,MATCH(O22,'야채 계산기'!$2:$2,0)) -> 0 | O22: 쯔양)매콤흑당치킨&골뱅이 | P22: 1 | Q22: =N22*$E$4 -> 0 | R22: =P22*Q22 -> 0
N23: =INDEX('야채 계산기'!$3:$3,MATCH(O23,'야채 계산기'!$2:$2,0)) -> 550 | O23: 이달의도시락10월 | P23: 1 | Q23: =N23*$E$4 -> 555.5 | R23: =P23*Q23 -> 555.5

Sheet 볶음참깨, 참기름
B2: 볶음참깨 | D2: 총 필요량 | E2: =SUM(F5:F26) -> 30112.5 | H2: 참기름(1.8L) | J2: 총 필요량 | K2: =SUM(L5:L27) -> 52254.785 | P2: 참기름(16.5KG/통) | R2: 총 필요량 | S2: =SUM(T5:T20) -> 5516.83
B4: 예상수량 | C4: 제품명 | D4: 원물중량 | E4: 1.1 | F4: 필요량 | H4: 예상수량 | I4: 제품명 | J4: 원물중량 | K4: 1.1 | L4: 필요량 | P4: 예상수량 | Q4: 제품명 | R4: 원물중량 | S4: 1.1 | T4: 필요량
B5: =INDEX('야채 계산기'!$3:$3,MATCH(C5,'야채 계산기'!$2:$2,0)) -> 3150 | C5: 삼각)전주비빔 | D5: 0.51 | E5: =B5*$E$4 -> 3465 | F5: =D5*E5 -> 1767.15 | H5: =INDEX('야채 계산기'!$3:$3,MATCH(I5,'야채 계산기'!$2:$2,0)) -> 3150 | I5: 삼각)전주비빔 | J5: 1.02 | K5: =H5*$E$4 -> 3465 | L5: =J5*K5 -> 3534.3 | P5: =INDEX('야채 계산기'!$3:$3,MATCH(Q5,'야채 계산기'!$2:$2,0)) -> 3150 | Q5: 삼각)전주비빔 | S5: =P5*$E$4 -> 3465 | T5: =R5*S5 -> 0
B6: =INDEX('야채 계산기'!$3:$3,MATCH(C6,'야채 계산기'!$2:$2,0)) -> 3620 | C6: 더큰)리챔참치마요 | D6: 0.17 | E6: =B6*$E$4 -> 3982 | F6: =D6*E6 -> 676.94 | H6: =INDEX('야채 계산기'!$3:$3,MATCH(I6,'야채 계산기'!$2:$2,0)) -> 3620 | I6: 더큰)리챔참치마요 | J6: 0 | K6: =H6*$E$4 -> 3982 | L6: =J6*K6 -> 0 | P6: =INDEX('야채 계산기'!$3:$3,MATCH(Q6,'야채 계산기'!$2:$2,0)) -> 3620 | Q6: 더큰)리챔참치마요 | R6: 0.32 | S6: =P6*$E$4 -> 3982 | T6: =R6*S6 -> 1274.24
A7: 취반용 | B7: =INDEX('야채 계산기'!$3:$3,MATCH(C7,'야채 계산기'!$2:$2,0)) -> 1340 | C7: 스팸계란치즈김밥 | D7: 1.03 | E7: =B7*$E$4 -> 1474 | F7: =D7*E7 -> 1518.22 | H7: =INDEX('야채 계산기'!$3:$3,MATCH(I7,'야채 계산기'!$2:$2,0)) -> 2090 | I7: NEW스팸무스비 | J7: ='[1]스팸무스비(25.8.26)'!$B$9 -> 1.98 | K7: =H7*$E$4 -> 2299 | L7: =J7*K7 -> 4552.02 | P7: =INDEX('야채 계산기'!$3:$3,MATCH(Q7,'야채 계산기'!$2:$2,0)) -> 4420 | Q7: 종가)들기름묵은지참치 | R7: 0.35 | S7: =P7*$E$4 -> 4862 | T7: =R7*S7 -> 1701.7
A8: 취반용 | B8: =INDEX('야채 계산기'!$3:$3,MATCH(C8,'야채 계산기'!$2:$2,0)) -> 1100 | C8: 왕돈까스김밥 | D8: 2.5 | E8: =B8*$E$4 -> 1210 | F8: =D8*E8 -> 3025 | H8: =INDEX('야채 계산기'!$3:$3,MATCH(I8,'야채 계산기'!$2:$2,0)) -> 170 | I8: 슈퍼)착한참치마요김밥 | J8: 1.82 | K8: =H8*$E$4 -> 187 | L8: =J8*K8 -> 340.34 | P8: =INDEX('야채 계산기'!$3:$3,MATCH(Q8,'야채 계산기'!$2:$2,0)) -> 2090 | Q8: NEW스팸무스비 | S8: =P8*$E$4 -> 2299 | T8: =R8*S8 -> 0
A9: 취반용 | B9: =INDEX('야채 계산기'!$3:$3,MATCH(C9,'야채 계산기'!$2:$2,0)) -> 1050 | C9: 불고기치즈김밥 | D9: 1.2 | E9: =B9*$E$4 -> 1155 | F9: =D9*E9 -> 1386 | H9: =INDEX('야채 계산기'!$3:$3,MATCH(I9,'야채 계산기'!$2:$2,0)) -> 1100 | I9: 용기)광장시장꼬마김밥 | J9: 2.56 | K9: =H9*$E$4 -> 1210 | L9: =J9*K9 -> 3097.6 | P9: =INDEX('야채 계산기'!$3:$3,MATCH(Q9,'야채 계산기'!$2:$2,0)) -> 170 | Q9: 슈퍼)착한참치마요김밥 | S9: =P9*$E$4 -> 187 | T9: =R9*S9 -> 0
A10: 취반용 | B10: =INDEX('야채 계산기'!$3:$3,MATCH(C10,'야채 계산기'!$2:$2,0)) -> 1170 | C10: 혜자)반반제육 | D10: 1.39 | E10: =B10*$E$4 -> 1287 | F10: =D10*E10 -> 1788.93 | H10: =INDEX('야채 계산기'!$3:$3,MATCH(I10,'야채 계산기'!$2:$2,0)) -> 0 | I10: 용기)에그햄꼬마김밥 | J10: 2.56 | K10: =H10*$E$4 -> 0 | L10: =J10*K10 -> 0 | P10: =INDEX('야채 계산기'!$3:$3,MATCH(Q10,'야채 계산기'!$2:$2,0)) -> 0 | Q10: N혜자)불고기오징어제육 | S10: =P10*$E$4 -> 0 | T10: =R10*S10 -> 0
A11: 취반용 | B11: =INDEX('야채 계산기'!$3:$3,MATCH(C11,'야채 계산기'!$2:$2,0)) -> 1100 | C11: 용기)광장시장꼬마김밥 | D11: 1.71 | E11: =B11*$E$4 -> 1210 | F11: =D11*E11 -> 2069.1 | H11: =INDEX('야채 계산기'!$3:$3,MATCH(I11,'야채 계산기'!$2:$2,0)) -> 6030 | I11: 더큰)스팸김치볶음밥 | J11: 1.13 | K11: =H11*$E$4 -> 6633 | L11: =J11*K11 -> 7495.29 | P11: =INDEX('야채 계산기'!$3:$3,MATCH(Q11,'야채 계산기'!$2:$2,0)) -> 6030 | Q11: 더큰)스팸김치볶음밥 | S11: =P11*$E$4 -> 6633 | T11: =R11*S11 -> 0
B12: =INDEX('야채 계산기'!$3:$3,MATCH(C12,'야채 계산기'!$2:$2,0)) -> 0 | C12: 용기)에그햄꼬마김밥 | D12: 2.22 | E12: =B12*$E$4 -> 0 | F12: =D12*E12 -> 0 | H12: =INDEX('야채 계산기'!$3:$3,MATCH(I12,'야채 계산기'!$2:$2,0)) -> 55 | I12: 슈퍼)착한제육비빔밥 | J12: ='[1]착한비빔밥(25.10.23)'!$B$14 -> 0.47 | K12: =H12*$E$4 -> 60.5 | L12: =J12*K12 -> 28.435 | N12: 로터리용 | P12: =INDEX('야채 계산기'!$3:$3,MATCH(Q12,'야채 계산기'!$2:$2,0)) -> 55 | Q12: 슈퍼)착한제육비빔밥 | S12: =P12*$E$4 -> 60.5 | T12: =R12*S12 -> 0
B13: =INDEX('야채 계산기'!$3:$3,MATCH(C13,'야채 계산기'!$2:$2,0)) -> 2200 | C13: 혜자)돌아온명불허전 | D13: 1.05 | E13: =B13*$E$4 -> 2420 | F13: =D13*E13 -> 2541 | H13: =INDEX('야채 계산기'!$3:$3,MATCH(I13,'야채 계산기'!$2:$2,0)) -> 1190 | I13: 직화)한돈제육쌈김밥 | J13: 0.51 | K13: =H13*$E$4 -> 1309 | L13: =J13*K13 -> 667.59 | N13: 유장용 | P13: =INDEX('야채 계산기'!$3:$3,MATCH(Q13,'야채 계산기'!$2:$2,0)) -> 1190 | Q13: 직화)한돈제육쌈김밥 | R13: 0.89 | S13: =P13*$E$4 -> 1309 | T13: =R13*S13 -> 1165.01
A14: 볶음용,토핑용 | B14: =INDEX('야채 계산기'!$3:$3,MATCH(C14,'야채 계산기'!$2:$2,0)) -> 55 | C14: 슈퍼)착한제육비빔밥 | D14: 0.42 | E14: =B14*$E$4 -> 60.5 | F14: =D14*E14 -> 25.41 | H14: =INDEX('야채 계산기'!$3:$3,MATCH(I14,'야채 계산기'!$2:$2,0)) -> 1170 | I14: 혜자)반반제육 | J14: 0.85 | K14: =H14*$E$4 -> 1287 | L14: =J14*K14 -> 1093.95 | N14: 볶음용 | P14: =INDEX('야채 계산기'!$3:$3,MATCH(Q14,'야채 계산기'!$2:$2,0)) -> 2840 | Q14: THE근본김밥 | S14: =P14*$E$4 -> 3124 | T14: =R14*S14 -> 0
A15: 로터리용 | B15: =INDEX('야채 계산기'!$3:$3,MATCH(C15,'야채 계산기'!$2:$2,0)) -> 810 | C15: NEW혜자)백설갈비양념제육 | D15: 0.51 | E15: =B15*$E$4 -> 891 | F15: =D15*E15 -> 454.41 | H15: =INDEX('야채 계산기'!$3:$3,MATCH(I15,'야채 계산기'!$2:$2,0)) -> 2840 | I15: THE근본김밥 | J15: 3.07 | K15: =H15*$E$4 -> 3124 | L15: =J15*K15 -> 9590.68 | N15: 로터리용 | P15: =INDEX('야채 계산기'!$3:$3,MATCH(Q15,'야채 계산기'!$2:$2,0)) -> 1290 | Q15: 더블치즈소시지김밥 | S15: =P15*$E$4 -> 1419 | T15: =R15*S15 -> 0
B16: =INDEX('야채 계산기'!$3:$3,MATCH(C16,'야채 계산기'!$2:$2,0)) -> 2840 | C16: THE근본김밥 | D16: 1.2 | E16: =B16*$E$4 -> 3124 | F16: =D16*E16 -> 3748.8 | H16: =INDEX('야채 계산기'!$3:$3,MATCH(I16,'야채 계산기'!$2:$2,0)) -> 1290 | I16: 더블치즈소시지김밥 | J16: 1 | K16: =H16*$E$4 -> 1419 | L16: =J16*K16 -> 1419 | P16: =INDEX('야채 계산기'!$3:$3,MATCH(Q16,'야채 계산기'!$2:$2,0)) -> 30 | Q16: 착한제육덮밥 | R16: 1.94 | S16: =P16*$E$4 -> 33 | T16: =R16*S16 -> 64.02
B17: =INDEX('야채 계산기'!$3:$3,MATCH(C17,'야채 계산기'!$2:$2,0)) -> 1190 | C17: 직화)한돈제육쌈김밥 | D17: 1.03 | E17: =B17*$E$4 -> 1309 | F17: =D17*E17 -> 1348.27 | H17: =INDEX('야채 계산기'!$3:$3,MATCH(I17,'야채 계산기'!$2:$2,0)) -> 4900 | I17: 더큰)스팸계란볶음밥 | J17: 1.18 | K17: =H17*$E$4 -> 5390 | L17: =J17*K17 -> 6360.2 | P17: =INDEX('야채 계산기'!$3:$3,MATCH(Q17,'야채 계산기'!$2:$2,0)) -> 1100 | Q17: 왕돈까스김밥 | S17: =P17*$E$4 -> 1210 | T17: =R17*S17 -> 0 | V17: 취반용
B18: =INDEX('야채 계산기'!$3:$3,MATCH(C18,'야채 계산기'!$2:$2,0)) -> 1290 | C18: 더블치즈소시지김밥 | D18: 0.95 | E18: =B18*$E$4 -> 1419 | F18: =D18*E18 -> 1348.05 | H18: =INDEX('야채 계산기'!$3:$3,MATCH(I18,'야채 계산기'!$2:$2,0)) -> 1100 | I18: 왕돈까스김밥 | J18: 0.51 | K18: =H18*$E$4 -> 1210 | L18: =J18*K18 -> 617.1 | N18: 계량용 | P18: =INDEX('야채 계산기'!$3:$3,MATCH(Q18,'야채 계산기'!$2:$2,0)) -> 1050 | Q18: 불고기치즈김밥 | S18: =P18*$E$4 -> 1155 | T18: =R18*S18 -> 0
B19: =INDEX('야채 계산기'!$3:$3,MATCH(C19,'야채 계산기'!$2:$2,0)) -> 4420 | C19: 종가)들기름묵은지참치 | D19: 0.18 | E19: =B19*$E$4 -> 4862 | F19: =D19*E19 -> 875.16 | H19: =INDEX('야채 계산기'!$3:$3,MATCH(I19,'야채 계산기'!$2:$2,0)) -> 1050 | I19: 불고기치즈김밥 | J19: 0.51 | K19: =H19*$E$4 -> 1155 | L19: =J19*K19 -> 589.05 | N19: 계량용 | P19: =INDEX('야채 계산기'!$3:$3,MATCH(Q19,'야채 계산기'!$2:$2,0)) -> 1340 | Q19: 스팸계란치즈김밥 | R19: 0.89 | S19: =P19*$E$4 -> 1474 | T19: =R19*S19 -> 1311.86
B20: =INDEX('야채 계산기'!$3:$3,MATCH(C20,'야채 계산기'!$2:$2,0)) -> 2020 | C20: 혜자)통등심돈까스&치킨까스도시락 | D20: 0.1 | E20: =B20*$E$4 -> 2222 | F20: =D20*E20 -> 222.2 | H20: =INDEX('야채 계산기'!$3:$3,MATCH(I20,'야채 계산기'!$2:$2,0)) -> 1340 | I20: 스팸계란치즈김밥 | J20: 0.52 | K20: =H20*$E$4 -> 1474 | L20: =J20*K20 -> 766.48 | N20: 유장용 | P20: =INDEX('야채 계산기'!$3:$3,MATCH(Q20,'야채 계산기'!$2:$2,0)) -> 140 | Q20: 슈퍼)착한김치김밥 | S20: =P20*$E$4 -> 154 | T20: =R20*S20 -> 0
B21: =INDEX('야채 계산기'!$3:$3,MATCH(C21,'야채 계산기'!$2:$2,0)) -> 1100 | C21: 무스비)햄&참치김치볶음밥 | D21: 0.59 | E21: =B21*$E$4 -> 1210 | F21: =D21*E21 -> 713.9 | H21: =INDEX('야채 계산기'!$3:$3,MATCH(I21,'야채 계산기'!$2:$2,0)) -> 140 | I21: 슈퍼)착한김치김밥 | J21: ='[1]착한김치김밥(250612)슈퍼'!$B$23 -> 0.68 | K21: =H21*$E$4 -> 154 | L21: =J21*K21 -> 104.72 | N21: 유장용
A22: 취반용 | B22: =INDEX('야채 계산기'!$3:$3,MATCH(C22,'야채 계산기'!$2:$2,0)) -> 550 | C22: 이달의도시락10월 | D22: 0.31 | E22: =B22*$E$4 -> 605 | F22: =D22*E22 -> 187.55 | H22: =INDEX('야채 계산기'!$3:$3,MATCH(I22,'야채 계산기'!$2:$2,0)) -> 1630 | I22: 더큰)추석맥적구이한상 | J22: 2.5 | K22: =H22*$E$4 -> 1793 | L22: =J22*K22 -> 4482.5 | N22: 유장용
B23: =INDEX('야채 계산기'!$3:$3,MATCH(C23,'야채 계산기'!$2:$2,0)) -> 720 | C23: 필름)진미채치즈김밥 | D23: 1.03 | E23: =B23*$E$4 -> 792 | F23: =D23*E23 -> 815.76 | H23: =INDEX('야채 계산기'!$3:$3,MATCH(I23,'야채 계산기'!$2:$2,0)) -> 1100 | I23: 무스비)햄&참치김치볶음밥 | J23: 1.98 | K23: =H23*$E$4 -> 1210 | L23: =J23*K23 -> 2395.8 | N23: 유장용 | V23: 취반용
A24: 취반용 | B24: =INDEX('야채 계산기'!$3:$3,MATCH(C24,'야채 계산기'!$2:$2,0)) -> 1680 | C24: 혜자)두툼돈까스&순창제육도시락 | D24: 0.77 | E24: =B24*$E$4 -> 1848 | F24: =D24*E24 -> 1422.96 | H24: =INDEX('야채 계산기'!$3:$3,MATCH(I24,'야채 계산기'!$2:$2,0)) -> 1780 | I24: 참치김치볶음김밥 | J24: 1.25 | K24: =H24*$E$4 -> 1958 | L24: =J24*K24 -> 2447.5 | N24: 믹싱용
B25: =INDEX('야채 계산기'!$3:$3,MATCH(C25,'야채 계산기'!$2:$2,0)) -> 1630 | C25: 더큰)추석맥적구이한상 | D25: 2.33 | E25: =B25*$E$4 -> 1793 | F25: =D25*E25 -> 4177.69 | H25: =INDEX('야채 계산기'!$3:$3,MATCH(I25,'야채 계산기'!$2:$2,0)) -> 720 | I25: 필름)진미채치즈김밥 | J25: 0.89 | K25: =H25*$E$4 -> 792 | L25: =J25*K25 -> 704.88
B26: =INDEX('야채 계산기'!$3:$3,MATCH(C26,'야채 계산기'!$2:$2,0)) -> 0 | C26: 쯔양)매콤흑당치킨&골뱅이 | D26: 0.51 | E26: =B26*$E$4 -> 0 | F26: =D26*E26 -> 0 | H26: =INDEX('야채 계산기'!$3:$3,MATCH(I26,'야채 계산기'!$2:$2,0)) -> 2020 | I26: 혜자)통등심돈까스&치킨까스도시락 | J26: 0.85 | K26: =H26*$E$4 -> 2222 | L26: =J26*K26 -> 1888.7
H27: =INDEX('야채 계산기'!$3:$3,MATCH(I27,'야채 계산기'!$2:$2,0)) -> 550 | I27: 이달의도시락10월 | J27: 0.13 | K27: =H27*$E$4 -> 605 | L27: =J27*K27 -> 78.65
