Workbook

Sheet 발주현황(카톡보내기)
B2: 매 출 현 황
J3: (단위 : 수량, 원, %) | M3: 아래 수식 건들지 마세요~!!!
B4: 분류 | C4: 품명 | D4: =TODAY() -> 46324 | E4: =D4+1 -> 46325 | G4: 비고 | I4: 제품명 | J4: 1편 | K4: 2편 | L4: 1편합계 | M4: 2편합계
D5: 1편(오후) | E5: 2편 (오전) | F5: 합계 수량
B6: 삼각 | C6: 삼각)전주비빔 | D6: =L6 -> 1583 | E6: =M6 -> 1094 | F6: =D6+E6 -> 2677 | G6: =IFERROR(F6/#REF!,"") | I6: 삼각)전주비빔 | J6: =IFERROR(IF(I6="","",SUMIF([1]작업지시서!$D$7:$D$118,"*"&$I6,[1]작업지시서!$E$7:$E$119)),"") -> 1583 | K6: =IFERROR(IF(I6="","",SUMIF([2]작업지시서!$D$7:$D$123,"*"&$I6,[2]작업지시서!$E$7:$E$123)),"") -> 1094 | L6: =J6 -> 1583 | M6: =K6 -> 1094
D7: =L7 | E7: =M7 | J7: =IFERROR(IF(I7="","",SUMIF([1]작업지시서!$D$7:$D$118,"*"&$I7,[1]작업지시서!$E$7:$E$119)),"") | K7: =IFERROR(IF(I7="","",SUMIF([2]작업지시서!$D$7:$D$123,"*"&$I7,[2]작업지시서!$E$7:$E$123)),"") | L7: =J7 | M7: =K7
D8: =L8 | E8: =M8 | J8: =IFERROR(IF(I8="","",SUMIF([1]작업지시서!$D$7:$D$118,"*"&$I8,[1]작업지시서!$E$7:$E$119)),"") | K8: =IFERROR(IF(I8="","",SUMIF([2]작업지시서!$D$7:$D$123,"*"&$I8,[2]작업지시서!$E$7:$E$123)),"") | L8: =J8 | M8: =K8
C9: 삼각)저당전주비빔 | D9: =L9 -> 0 | E9: =M9 -> 0 | F9: =D9+E9 -> 0 | I9: 삼각)저당전주비빔 | J9: =IFERROR(IF(I9="","",SUMIF([1]작업지시서!$D$7:$D$118,"*"&$I9,[1]작업지시서!$E$7:$E$119)),"") -> 0 | K9: =IFERROR(IF(I9="","",SUMIF([2]작업지시서!$D$7:$D$123,"*"&$I9,[2]작업지시서!$E$7:$E$123)),"") -> 0 | L9: =J9 -> 0 | M9: =K9 -> 0
D10: =L10 | E10: =M10 | G10: =IFERROR(F10/#REF!,"") | J10: =IFERROR(IF(I10="","",SUMIF([1]작업지시서!$D$7:$D$118,"*"&$I10,[1]작업지시서!$E$7:$E$119)),"") | K10: =IFERROR(IF(I10="","",SUMIF([2]작업지시서!$D$7:$D$123,"*"&$I10,[2]작업지시서!$E$7:$E$123)),"") | L10: =J10 | M10: =K10
D11: =L11 | E11: =M11 | G11: =IFERROR(F11/#REF!,"") | J11: =IFERROR(IF(I11="","",SUMIF([1]작업지시서!$D$7:$D$118,"*"&$I11,[1]작업지시서!$E$7:$E$119)),"") | K11: =IFERROR(IF(I11="","",SUMIF([2]작업지시서!$D$7:$D$123,"*"&$I11,[2]작업지시서!$E$7:$E$123)),"") | L11: =J11 | M11: =K11
D12: =L12 | E12: =M12 | G12: =IFERROR(F12/#REF!,"") | J12: =IFERROR(IF(I12="","",SUMIF([1]작업지시서!$D$7:$D$118,""&$I12,[1]작업지시서!$E$7:$E$119)),"") | K12: =IFERROR(IF(I12="","",SUMIF([2]작업지시서!$D$7:$D$123,"*"&$I12,[2]작업지시서!$E$7:$E$123)),"") | L12: =J12 | M12: =K12
D13: =L13 | E13: =M13 | G13: =IFERROR(F13/#REF!,"") | J13: =IFERROR(IF(I13="","",SUMIF([1]작업지시서!$D$7:$D$118,""&$I13,[1]작업지시서!$E$7:$E$119)),"") | K13: =IFERROR(IF(I13="","",SUMIF([2]작업지시서!$D$7:$D$123,"*"&$I13,[2]작업지시서!$E$7:$E$123)),"") | L13: =J13 | M13: =K13
D14: =L14 | E14: =M14 | J14: =IFERROR(IF(I14="","",SUMIF([1]작업지시서!$D$7:$D$118,""&$I14,[1]작업지시서!$E$7:$E$119)),"") | K14: =IFERROR(IF(I14="","",SUMIF([2]작업지시서!$D$7:$D$123,"*"&$I14,[2]작업지시서!$E$7:$E$123)),"") | L14: =J14 | M14: =K14
D15: =L15 | E15: =M15 | J15: =IFERROR(IF(I15="","",SUMIF([1]작업지시서!$D$7:$D$118,"*"&$I15,[1]작업지시서!$E$7:$E$119)),"") | K15: =IFERROR(IF(I15="","",SUMIF([2]작업지시서!$D$7:$D$123,"*"&$I15,[2]작업지시서!$E$7:$E$123)),"") | L15: =J15 | M15: =K15
D16: =L16 | E16: =M16 | G16: =IFERROR(F16/#REF!,"") | J16: =IFERROR(IF(I16="","",SUMIF([1]작업지시서!$D$7:$D$118,"*"&$I16,[1]작업지시서!$E$7:$E$119)),"") | K16: =IFERROR(IF(I16="","",SUMIF([2]작업지시서!$D$7:$D$123,"*"&$I16,[2]작업지시서!$E$7:$E$123)),"") | L16: =J16 | M16: =K16
D17: =L17 | E17: =M17 | G17: =IFERROR(F17/#REF!,"") | J17: =IFERROR(IF(I17="","",SUMIF([1]작업지시서!$D$7:$D$118,""&$I17,[1]작업지시서!$E$7:$E$119)),"") | K17: =IFERROR(IF(I17="","",SUMIF([2]작업지시서!$D$7:$D$123,"*"&$I17,[2]작업지시서!$E$7:$E$123)),"") | L17: =J17 | M17: =K17
D18: =L18 | E18: =M18 | G18: =IFERROR(F18/#REF!,"") | J18: =IFERROR(IF(I18="","",SUMIF([1]작업지시서!$D$7:$D$118,"*"&$I18,[1]작업지시서!$E$7:$E$119)),"") | K18: =IFERROR(IF(I18="","",SUMIF([2]작업지시서!$D$7:$D$123,"*"&$I18,[2]작업지시서!$E$7:$E$123)),"") | L18: =J18 | M18: =K18
D19: =L19 | E19: =M19 | G19: =IFERROR(F19/#REF!,"") | J19: =IFERROR(IF(I19="","",SUMIF([1]작업지시서!$D$7:$D$118,"*"&$I19,[1]작업지시서!$E$7:$E$119)),"") | K19: =IFERROR(IF(I19="","",SUMIF([2]작업지시서!$D$7:$D$123,"*"&$I19,[2]작업지시서!$E$7:$E$123)),"") | L19: =J19 | M19: =K19
D20: =L20 | E20: =M20 | G20: =IFERROR(F20/#REF!,"") | J20: =IFERROR(IF(I20="","",SUMIF([1]작업지시서!$D$7:$D$118,"*"&$I20,[1]작업지시서!$E$7:$E$119)),"") | K20: =IFERROR(IF(I20="","",SUMIF([2]작업지시서!$D$7:$D$123,"*"&$I20,[2]작업지시서!$E$7:$E$123)),"") | L20: =J20 | M20: =K20
D21: =L21 | E21: =M21 | G21: =IFERROR(F21/#REF!,"") | J21: =IFERROR(IF(I21="","",SUMIF([1]작업지시서!$D$7:$D$118,"*"&$I21,[1]작업지시서!$E$7:$E$119)),"") | K21: =IFERROR(IF(I21="","",SUMIF([2]작업지시서!$D$7:$D$123,"*"&$I21,[2]작업지시서!$E$7:$E$123)),"") | L21: =J21 | M21: =K21
D22: =L22 | E22: =M22 | G22: =IFERROR(F22/#REF!,"") | J22: =IFERROR(IF(I22="","",SUMIF([1]작업지시서!$D$7:$D$118,"*"&$I22,[1]작업지시서!$E$7:$E$119)),"") | K22: =IFERROR(IF(I22="","",SUMIF([2]작업지시서!$D$7:$D$123,"*"&$I22,[2]작업지시서!$E$7:$E$123)),"") | L22: =J22 | M22: =K22
D23: =L23 | E23: =M23 | G23: =IFERROR(F23/#REF!,"") | J23: =IFERROR(IF(I23="","",SUMIF([1]작업지시서!$D$7:$D$118,"*"&$I23,[1]작업지시서!$E$7:$E$119)),"") | K23: =IFERROR(IF(I23="","",SUMIF([2]작업지시서!$D$7:$D$123,"*"&$I23,[2]작업지시서!$E$7:$E$123)),"") | L23: =J23 | M23: =K23
D24: =L24 | E24: =M24 | G24: =IFERROR(F24/#REF!,"") | J24: =IFERROR(IF(I24="","",SUMIF([1]작업지시서!$D$7:$D$118,"*"&$I24,[1]작업지시서!$E$7:$E$119)),"") | K24: =IFERROR(IF(I24="","",SUMIF([2]작업지시서!$D$7:$D$123,"*"&$I24,[2]작업지시서!$E$7:$E$123)),"") | L24: =J24 | M24: =K24
C25: =B6&" 소계" -> 삼각 소계 | D25: =SUM(D6:D24) -> 1583 | E25: =SUM(E6:E24) -> 1094 | F25: =SUM(F6:F24) -> 2677 | G25: =IFERROR(F25/#REF!,"") | J25: =IFERROR(IF(I25="","",SUMIF([1]작업지시서!$D$7:$D$118,"*"&$I25,[1]작업지시서!$E$7:$E$119)),"") | K25: =IFERROR(IF(I25="","",SUMIF([2]작업지시서!$D$7:$D$123,"*"&$I25,[2]작업지시서!$E$7:$E$123)),"") | L25: =J25 | M25: =K25
D26: =L26 | E26: =M26 | G26: =IFERROR(F26/#REF!,"") | J26: =IFERROR(IF(I26="","",SUMIF([1]작업지시서!$D$7:$D$118,"*"&$I26,[1]작업지시서!$E$7:$E$119)),"") | K26: =IFERROR(IF(I26="","",SUMIF([2]작업지시서!$D$7:$D$123,"*"&$I26,[2]작업지시서!$E$7:$E$123)),"") | L26: =J26 | M26: =K26
D27: =L27 | E27: =M27 | G27: =IFERROR(F27/#REF!,"") | J27: =IFERROR(IF(I27="","",SUMIF([1]작업지시서!$D$7:$D$118,"*"&$I27,[1]작업지시서!$E$7:$E$119)),"") | K27: =IFERROR(IF(I27="","",SUMIF([2]작업지시서!$D$7:$D$123,"*"&$I27,[2]작업지시서!$E$7:$E$123)),"") | L27: =J27 | M27: =K27
D28: =L28 | E28: =M28 | G28: =IFERROR(F28/#REF!,"") | J28: =IFERROR(IF(I28="","",SUMIF([1]작업지시서!$D$7:$D$118,"*"&$I28,[1]작업지시서!$E$7:$E$119)),"") | K28: =IFERROR(IF(I28="","",SUMIF([2]작업지시서!$D$7:$D$123,"*"&$I28,[2]작업지시서!$E$7:$E$123)),"") | L28: =J28 | M28: =K28
D29: =L29 | E29: =M29 | G29: =IFERROR(F29/#REF!,"") | J29: =IFERROR(IF(I29="","",SUMIF([1]작업지시서!$D$7:$D$118,"*"&$I29,[1]작업지시서!$E$7:$E$119)),"") | K29: =IFERROR(IF(I29="","",SUMIF([2]작업지시서!$D$7:$D$123,"*"&$I29,[2]작업지시서!$E$7:$E$123)),"") | L29: =J29 | M29: =K29
G30: =IFERROR(F30/#REF!,"")
G31: =IFERROR(F31/#REF!,"")
B32: 더큰 삼각 | C32: 더큰)스팸김치볶음밥 | D32: =L32 -> 2881 | E32: =M32 -> 2128 | F32: =D32+E32 -> 5009 | G32: =IFERROR(F32/#REF!,"") | I32: 더큰)스팸김치볶음밥 | J32: =IFERROR(IF(I32="","",SUMIF([1]작업지시서!$D$7:$D$118,"*"&$I32,[1]작업지시서!$E$7:$E$119)),"") -> 2881 | K32: =IFERROR(IF(I32="","",SUMIF([2]작업지시서!$D$7:$D$123,"*"&$I32,[2]작업지시서!$E$7:$E$123)),"") -> 2128 | L32: =J32 -> 2881 | M32: =K32 -> 2128
C33: NEW스팸무스비 | D33: =L33 -> 935 | E33: =M33 -> 691 | F33: =D33+E33 -> 1626 | G33: =IFERROR(F33/#REF!,"") | I33: NEW스팸무스비 | J33: =IFERROR(IF(I33="","",SUMIF([1]작업지시서!$D$7:$D$118,"*"&$I33,[1]작업지시서!$E$7:$E$119)),"") -> 935 | K33: =IFERROR(IF(I33="","",SUMIF([2]작업지시서!$D$7:$D$123,"*"&$I33,[2]작업지시서!$E$7:$E$123)),"") -> 691 | L33: =J33 -> 935 | M33: =K33 -> 691
C34: 무스비)햄&참치김치볶음밥 | D34: =L34 -> 458 | E34: =M34 -> 392 | F34: =D34+E34 -> 850 | G34: =IFERROR(F34/#REF!,"") | I34: 무스비)햄&참치김치볶음밥 | J34: =IFERROR(IF(I34="","",SUMIF([1]작업지시서!$D$7:$D$118,"*"&$I34,[1]작업지시서!$E$7:$E$119)),"") -> 458 | K34: =IFERROR(IF(I34="","",SUMIF([2]작업지시서!$D$7:$D$123,"*"&$I34,[2]작업지시서!$E$7:$E$123)),"") -> 392 | L34: =J34 -> 458 | M34: =K34 -> 392
C35: 무스비)햄&청양불고기 | D35: =L35 -> 141 | E35: =M35 -> 149 | F35: =D35+E35 -> 290 | G35: =IFERROR(F35/#REF!,"") | I35: 무스비)햄&청양불고기 | J35: =IFERROR(IF(I35="","",SUMIF([1]작업지시서!$D$7:$D$118,"*"&$I35,[1]작업지시서!$E$7:$E$119)),"") -> 141 | K35: =IFERROR(IF(I35="","",SUMIF([2]작업지시서!$D$7:$D$123,"*"&$I35,[2]작업지시서!$E$7:$E$123)),"") -> 149 | L35: =J35 -> 141 | M35: =K35 -> 149
C36: 더큰)들기름묵은지참치 | D36: =L36 -> 2430 | E36: =M36 -> 1680 | F36: =D36+E36 -> 4110 | G36: =IFERROR(F36/#REF!,"") | I36: 더큰)들기름묵은지참치 | J36: =IFERROR(IF(I36="","",SUMIF([1]작업지시서!$D$7:$D$118,"*"&$I36,[1]작업지시서!$E$7:$E$119)),"") -> 2430 | K36: =IFERROR(IF(I36="","",SUMIF([2]작업지시서!$D$7:$D$123,"*"&$I36,[2]작업지시서!$E$7:$E$123)),"") -> 1680 | L36: =J36 -> 2430 | M36: =K36 -> 1680
C37: 더큰)스팸계란볶음밥 | D37: =L37 -> 2522 | E37: =M37 -> 1776 | F37: =D37+E37 -> 4298 | G37: =IFERROR(F37/#REF!,"") | I37: 더큰)스팸계란볶음밥 | J37: =IFERROR(IF(I37="","",SUMIF([1]작업지시서!$D$7:$D$118,"*"&$I37,[1]작업지시서!$E$7:$E$119)),"") -> 2522 | K37: =IFERROR(IF(I37="","",SUMIF([2]작업지시서!$D$7:$D$123,"*"&$I37,[2]작업지시서!$E$7:$E$123)),"") -> 1776 | L37: =J37 -> 2522 | M37: =K37 -> 1776
C38: 더큰)오징어제육깻잎쌈밥 | D38: =L38 -> 888 | E38: =M38 -> 541 | F38: =D38+E38 -> 1429 | G38: =IFERROR(F38/#REF!,"") | I38: 더큰)오징어제육깻잎쌈밥 | J38: =IFERROR(IF(I38="","",SUMIF([1]작업지시서!$D$7:$D$118,"*"&$I38,[1]작업지시서!$E$7:$E$119)),"") -> 888 | K38: =IFERROR(IF(I38="","",SUMIF([2]작업지시서!$D$7:$D$123,"*"&$I38,[2]작업지시서!$E$7:$E$123)),"") -> 541 | L38: =J38 -> 888 | M38: =K38 -> 541
C39: 더큰)리챔참치마요 | D39: =L39 -> 1735 | E39: =M39 -> 1178 | F39: =D39+E39 -> 2913 | G39: =IFERROR(F39/#REF!,"") | I39: 더큰)리챔참치마요 | J39: =IFERROR(IF(I39="","",SUMIF([1]작업지시서!$D$7:$D$118,"*"&$I39,[1]작업지시서!$E$7:$E$119)),"") -> 1735 | K39: =IFERROR(IF(I39="","",SUMIF([2]작업지시서!$D$7:$D$123,"*"&$I39,[2]작업지시서!$E$7:$E$123)),"") -> 1178 | L39: =J39 -> 1735 | M39: =K39 -> 1178
C40: 더큰)맥적구이한상 | D40: =L40 -> 730 | E40: =M40 -> 472 | F40: =D40+E40 -> 1202 | G40: =IFERROR(F40/#REF!,"") | I40: 더큰)맥적구이한상 | J40: =IFERROR(IF(I40="","",SUMIF([1]작업지시서!$D$7:$D$118,"*"&$I40,[1]작업지시서!$E$7:$E$119)),"") -> 730 | K40: =IFERROR(IF(I40="","",SUMIF([2]작업지시서!$D$7:$D$123,"*"&$I40,[2]작업지시서!$E$7:$E$123)),"") -> 472 | L40: =J40 -> 730 | M40: =K40 -> 472
C41: 커플)곱창김참치&비빔밥 | D41: =L41 -> 2234 | E41: =M41 -> 1927 | F41: =D41+E41 -> 4161 | G41: =IFERROR(F41/#REF!,"") | I41: 커플)곱창김참치&비빔밥 | J41: =IFERROR(IF(I41="","",SUMIF([1]작업지시서!$D$7:$D$118,"*"&$I41,[1]작업지시서!$E$7:$E$119)),"") -> 2234 | K41: =IFERROR(IF(I41="","",SUMIF([2]작업지시서!$D$7:$D$123,"*"&$I41,[2]작업지시서!$E$7:$E$123)),"") -> 1927 | L41: =J41 -> 2234 | M41: =K41 -> 1927
...

Sheet 신상현황
B1: 구분 | C1: 코드 | D1: 품명 | E1: 목 | F1: 금 | G1: 토 | H1: 일 | I1: 월 | J1: 화 | K1: 수 | L1: 목 | M1: 특이사항 | N1: 금 | O1: 토 | P1: 일 | Q1: 월 | R1: 화 | S1: 수 | T1: 목 | U1: 금 | V1: 토 | W1: 일 | X1: 월 | Y1: 화 | Z1: 수 | AA1: 목 | AB1: 금 | AC1: 토 | AD1: 일 | AE1: 월 | AF1: 화 | AG1: 수 | AH1: 목 | AI1: 금 | AJ1: 토 | AK1: 일 | AL1: 월 | AM1: 화 | AN1: 수 | AO1: 목 | AP1: 금 | AQ1: 토 | AR1: 일 | AS1: 월 | AT1: 화 | AU1: 수 | AV1: 목 | AW1: 금 | AX1: 토 | AY1: 일 | AZ1: 월 | BA1: 화 | BB1: 수 | BC1: 목 | BD1: 금 | BE1: 토 | BF1: 일 | BG1: 월 | BH1: 화 | BI1: 수 | BJ1: 목 | BK1: 금 | BL1: 토 | BM1: 일 | BN1: 월 | BO1: 화 | BP1: 수 | BQ1: 목 | BR1: 금 | BS1: 토 | BT1: 일 | BU1: 월 | BV1: 화 | BW1: 수 | BX1: 목 | BY1: 금 | BZ1: 토 | CA1: 일 | CB1: 월 | CC1: 화 | CD1: 수 | CE1: 목 | CF1: 금 | CG1: 토 | CH1: 일 | CI1: 월 | CJ1: 화 | CK1: 수 | CL1: 목 | CM1: 금 | CN1: 토 | CO1: 일 | CP1: 월 | CQ1: 화 | CR1: 수 | CS1: 목 | CT1: 금 | CU1: 토 | CV1: 일 | CW1: 월 | CX1: 화 | CY1: 수 | CZ1: 목 | DA1: 금 | DB1: 토 | DC1: 일 | DD1: 월 | DE1: 화 | DF1: 수
B2: 도시락 | C2: 2700038833486 | D2: 매콤닭강정도시락1편 | J2: 2576 | K2: 1279 | L2: 1444 | M2: 전일 대비 발주량 증가
C3: 2700038833486 | K3: =K2/J2 -> 0.49650621 | L3: =L2/K2 -> 1.129007 | N3: =N2/L2 -> 0 | O3: =O2/N2 -> #DIV/0! | P3: =P2/O2 -> #DIV/0! | Q3: =Q2/P2 -> #DIV/0! | R3: =R2/Q2 -> #DIV/0! | S3: =S2/R2 -> #DIV/0! | T3: =T2/S2 -> #DIV/0! | U3: =U2/T2 -> #DIV/0! | V3: =V2/U2 -> #DIV/0! | ... AD3: =AD2/AC2 -> #DIV/0!
B4: 도시락 | C4: 2700038833486 | D4: 매콤닭강정도시락2편 | J4: 1886 | K4: 1163 | L4: 1103
K5: =K4/J4 -> 0.61664899 | L5: =L4/K4 -> 0.94840929 | N5: =N4/L4 -> 0 | O5: =O4/N4 -> #DIV/0! | P5: =P4/O4 -> #DIV/0! | Q5: =Q4/P4 -> #DIV/0! | R5: =R4/Q4 -> #DIV/0! | S5: =S4/R4 -> #DIV/0! | T5: =T4/S4 -> #DIV/0! | U5: =U4/T4 -> #DIV/0! | V5: =V4/U4 -> #DIV/0! | ... AD5: =AD4/AC4 -> #DIV/0!
D6: 합계 | J6: =J2+J4 -> 4462 | K6: =K2+K4 -> 2442 | L6: =L2+L4 -> 2547
D7: 평균 | K7: =K6/J6 -> 0.54728821 | L7: =L6/K6 -> 1.0429975 | N7: =N6/L6 -> 0 | O7: =O6/N6 -> #DIV/0! | P7: =P6/O6 -> #DIV/0! | Q7: =Q6/P6 -> #DIV/0! | R7: =R6/Q6 -> #DIV/0! | S7: =S6/R6 -> #DIV/0! | T7: =T6/S6 -> #DIV/0! | U7: =U6/T6 -> #DIV/0! | V7: =V6/U6 -> #DIV/0! | ... AD7: =AD6/AC6 -> #DIV/0!
B8: FF간편식 | C8: 2700038833936 | D8: 고등급식)함박스파게티1편 | J8: 1945 | K8: 601 | L8: 969 | M8: 전일 대비 발주량 증가
B9: FF간편식 | C9: 2700038833936 | D9: 고등급식)함박스파게티1편 | K9: =K8/J8 -> 0.30899743 | L9: =L8/K8 -> 1.6123128 | N9: =N8/L8 -> 0 | O9: =O8/N8 -> #DIV/0! | P9: =P8/O8 -> #DIV/0! | Q9: =Q8/P8 -> #DIV/0! | R9: =R8/Q8 -> #DIV/0! | S9: =S8/R8 -> #DIV/0! | T9: =T8/S8 -> #DIV/0! | U9: =U8/T8 -> #DIV/0! | V9: =V8/U8 -> #DIV/0! | ... AD9: =AD8/AC8 -> #DIV/0!
B10: FF간편식 | C10: 2700038833936 | D10: 고등급식)함박스파게티2편 | J10: 1630 | K10: 415 | L10: 761
B11: FF간편식 | C11: 2700038833936 | D11: 고등급식)함박스파게티2편 | K11: =K10/J10 -> 0.25460123 | L11: =L10/K10 -> 1.8337349 | N11: =N10/L10 -> 0 | O11: =O10/N10 -> #DIV/0! | P11: =P10/O10 -> #DIV/0! | Q11: =Q10/P10 -> #DIV/0! | R11: =R10/Q10 -> #DIV/0! | S11: =S10/R10 -> #DIV/0! | T11: =T10/S10 -> #DIV/0! | U11: =U10/T10 -> #DIV/0! | V11: =V10/U10 -> #DIV/0! | ... AD11: =AD10/AC10 -> #DIV/0!
D12: 합계 | J12: =J8+J10 -> 3575 | K12: =K8+K10 -> 1016 | L12: =L8+L10 -> 1730
K13: =K12/J12 -> 0.2841958 | L13: =L12/K12 -> 1.7027559 | N13: =N12/L12 -> 0 | O13: =O12/N12 -> #DIV/0! | P13: =P12/O12 -> #DIV/0! | Q13: =Q12/P12 -> #DIV/0! | R13: =R12/Q12 -> #DIV/0! | S13: =S12/R12 -> #DIV/0! | T13: =T12/S12 -> #DIV/0! | U13: =U12/T12 -> #DIV/0! | V13: =V12/U12 -> #DIV/0! | ... AD13: =AD12/AC12 -> #DIV/0!

Sheet 발주현황(카톡보내기) (2)
B2: 매 출 현 황
J3: (단위 : 수량, 원, %) | M3: 아래 수식 건들지 마세요~!!!
B4: 분류 | C4: 품명 | D4: 44396 | G4: 44397 | J4: 전일 | L4: 제품명 | M4: 1편 | N4: 2편 | O4: 2편(긴급) | P4: 2편합계
D5: 1편 수량 | E5: 2편 수량 | F5: 합계 수량 | G5: 1편 수량 | H5: 2편 수량 | I5: 합계 수량 | J5: 대비
B6: 삼각 | C6: 삼각)뉴전주비빔 | D6: 3046 | E6: 2966 | F6: 6012 | G6: =M6 -> 0 | H6: =P6 -> 4 | I6: =G6+H6 -> 4 | J6: =IFERROR(I6/F6,"") -> 0.00066533599 | L6: 삼각)뉴전주비빔 | M6: =IFERROR(IF(L6="","",SUMIF([1]작업지시서!$D$8:$D$118,"*"&$L6,[1]작업지시서!$E$8:$E$119)),"") -> 0 | N6: =IFERROR(IF(L6="","",SUMIF([2]작업지시서!$D$8:$D$122,"*"&$L6,[2]작업지시서!$E$8:$E$123)),"") -> 0 | O6: 4 | P6: =N6+O6 -> 4
C7: 삼각)국민대표참치대란 | D7: 1712 | E7: 1599 | F7: 3311 | G7: =M7 -> 0 | H7: =P7 -> 0 | I7: =G7+H7 -> 0 | J7: =IFERROR(I7/F7,"") -> 0 | L7: 삼각)국민대표참치대란 | M7: =IFERROR(IF(L7="","",SUMIF([1]작업지시서!$D$8:$D$118,"*"&$L7,[1]작업지시서!$E$8:$E$119)),"") -> 0 | N7: =IFERROR(IF(L7="","",SUMIF([2]작업지시서!$D$8:$D$122,"*"&$L7,[2]작업지시서!$E$8:$E$123)),"") -> 0 | P7: =N7+O7 -> 0
C8: 삼각)스팸계란볶음밥 | D8: 1352 | E8: 1222 | F8: 2574 | G8: =M8 -> 0 | H8: =P8 -> 0 | I8: =G8+H8 -> 0 | J8: =IFERROR(I8/F8,"") -> 0 | L8: 삼각)스팸계란볶음밥 | M8: =IFERROR(IF(L8="","",SUMIF([1]작업지시서!$D$8:$D$118,"*"&$L8,[1]작업지시서!$E$8:$E$119)),"") -> 0 | N8: =IFERROR(IF(L8="","",SUMIF([2]작업지시서!$D$8:$D$122,"*"&$L8,[2]작업지시서!$E$8:$E$123)),"") -> 0 | P8: =N8+O8 -> 0
C9: 삼각)베이컨참치마요 | D9: 1299 | E9: 1238 | F9: 2537 | G9: =M9 -> 0 | H9: =P9 -> 2 | I9: =G9+H9 -> 2 | J9: =IFERROR(I9/F9,"") -> 0.00078833268 | L9: 삼각)베이컨참치마요 | M9: =IFERROR(IF(L9="","",SUMIF([1]작업지시서!$D$8:$D$118,"*"&$L9,[1]작업지시서!$E$8:$E$119)),"") -> 0 | N9: =IFERROR(IF(L9="","",SUMIF([2]작업지시서!$D$8:$D$122,"*"&$L9,[2]작업지시서!$E$8:$E$123)),"") -> 0 | O9: 2 | P9: =N9+O9 -> 2
C10: 더큰)소불고기주먹밥 | D10: 2675 | E10: 2439 | F10: 5114 | G10: =M10 -> 0 | H10: =P10 -> 0 | I10: =G10+H10 -> 0 | J10: =IFERROR(I10/F10,"") -> 0 | L10: 더큰)소불고기주먹밥 | M10: =IFERROR(IF(L10="","",SUMIF([1]작업지시서!$D$8:$D$118,"*"&$L10,[1]작업지시서!$E$8:$E$119)),"") -> 0 | N10: =IFERROR(IF(L10="","",SUMIF([2]작업지시서!$D$8:$D$122,"*"&$L10,[2]작업지시서!$E$8:$E$123)),"") -> 0 | P10: =N10+O10 -> 0
C11: 더큰)스팸김치볶음밥 | D11: 3187 | E11: 3169 | F11: 6356 | G11: =M11 -> 2881 | H11: =P11 -> 2132 | I11: =G11+H11 -> 5013 | J11: =IFERROR(I11/F11,"") -> 0.78870359 | L11: 더큰)스팸김치볶음밥 | M11: =IFERROR(IF(L11="","",SUMIF([1]작업지시서!$D$8:$D$118,"*"&$L11,[1]작업지시서!$E$8:$E$119)),"") -> 2881 | N11: =IFERROR(IF(L11="","",SUMIF([2]작업지시서!$D$8:$D$122,"*"&$L11,[2]작업지시서!$E$8:$E$123)),"") -> 2128 | O11: 4 | P11: =N11+O11 -> 2132
C12: 더큰)치즈닭갈비볶음밥 | D12: 2528 | E12: 2413 | F12: 4941 | G12: =M12 -> 0 | H12: =P12 -> 0 | I12: =G12+H12 -> 0 | J12: =IFERROR(I12/F12,"") -> 0 | L12: 더큰)치즈닭갈비볶음밥 | M12: =IFERROR(IF(L12="","",SUMIF([1]작업지시서!$D$8:$D$118,"*"&$L12,[1]작업지시서!$E$8:$E$119)),"") -> 0 | N12: =IFERROR(IF(L12="","",SUMIF([2]작업지시서!$D$8:$D$122,"*"&$L12,[2]작업지시서!$E$8:$E$123)),"") -> 0 | P12: =N12+O12 -> 0
C13: 삼각)오뚜기카레&깍두기 | D13: 168 | E13: 136 | F13: 304 | G13: =M13 -> 0 | H13: =P13 -> 0 | I13: =G13+H13 -> 0 | J13: =IFERROR(I13/F13,"") -> 0 | L13: 삼각)오뚜기카레&깍두기 | M13: =IFERROR(IF(L13="","",SUMIF([1]작업지시서!$D$8:$D$118,"*"&$L13,[1]작업지시서!$E$8:$E$119)),"") -> 0 | N13: =IFERROR(IF(L13="","",SUMIF([2]작업지시서!$D$8:$D$122,"*"&$L13,[2]작업지시서!$E$8:$E$123)),"") -> 0 | P13: =N13+O13 -> 0
C14: 삼각)모짜콘치즈 | D14: 957 | E14: 847 | F14: 1804 | G14: =M14 -> 0 | H14: =P14 -> 0 | I14: =G14+H14 -> 0 | J14: =IFERROR(I14/F14,"") -> 0 | L14: 삼각)모짜콘치즈 | M14: =IFERROR(IF(L14="","",SUMIF([1]작업지시서!$D$8:$D$118,"*"&$L14,[1]작업지시서!$E$8:$E$119)),"") -> 0 | N14: =IFERROR(IF(L14="","",SUMIF([2]작업지시서!$D$8:$D$122,"*"&$L14,[2]작업지시서!$E$8:$E$123)),"") -> 0 | P14: =N14+O14 -> 0
C15: =B6&" 소계" -> 삼각 소계 | D15: 16924 | E15: 16029 | F15: 32953 | G15: =SUM(G6:G14) -> 2881 | H15: =SUM(H6:H14) -> 2138 | I15: =SUM(I6:I14) -> 5019 | J15: =IFERROR(I15/F15,"") -> 0.15230783
B16: 김밥 | C16: 참치마요김밥 | D16: 3150 | E16: 2879 | F16: 6029 | G16: =M16 -> 254 | H16: =P16 -> 2 | I16: =G16+H16 -> 256 | J16: =IFERROR(I16/F16,"") -> 0.042461436 | L16: 참치마요김밥 | M16: =IFERROR(IF(L16="","",SUMIF([1]작업지시서!$D$8:$D$118,"*"&$L16,[1]작업지시서!$E$8:$E$119)),"") -> 254 | N16: =IFERROR(IF(L16="","",SUMIF([2]작업지시서!$D$8:$D$122,"*"&$L16,[2]작업지시서!$E$8:$E$123)),"") -> 0 | O16: 2 | P16: =N16+O16 -> 2
C17: 매콤어묵듬뿍김밥 | D17: 1748 | E17: 1483 | F17: 3231 | G17: =M17 -> 0 | H17: =P17 -> 0 | I17: =G17+H17 -> 0 | J17: =IFERROR(I17/F17,"") -> 0 | L17: 매콤어묵듬뿍김밥 | M17: =IFERROR(IF(L17="","",SUMIF([1]작업지시서!$D$8:$D$118,"*"&$L17,[1]작업지시서!$E$8:$E$119)),"") -> 0 | N17: =IFERROR(IF(L17="","",SUMIF([2]작업지시서!$D$8:$D$122,"*"&$L17,[2]작업지시서!$E$8:$E$123)),"") -> 0 | P17: =N17+O17 -> 0
C18: 소고기고추장김밥 | D18: 1225 | E18: 1008 | F18: 2233 | G18: =M18 -> 0 | H18: =P18 -> 0 | I18: =G18+H18 -> 0 | J18: =IFERROR(I18/F18,"") -> 0 | L18: 소고기고추장김밥 | M18: =IFERROR(IF(L18="","",SUMIF([1]작업지시서!$D$8:$D$118,"*"&$L18,[1]작업지시서!$E$8:$E$119)),"") -> 0 | N18: =IFERROR(IF(L18="","",SUMIF([2]작업지시서!$D$8:$D$122,"*"&$L18,[2]작업지시서!$E$8:$E$123)),"") -> 0 | P18: =N18+O18 -> 0
C19: 참치김치김밥 | D19: 1624 | E19: 1376 | F19: 3000 | G19: =M19 -> 0 | H19: =P19 -> 0 | I19: =G19+H19 -> 0 | J19: =IFERROR(I19/F19,"") -> 0 | L19: 참치김치김밥 | M19: =IFERROR(IF(L19="","",SUMIF([1]작업지시서!$D$8:$D$118,"*"&$L19,[1]작업지시서!$E$8:$E$119)),"") -> 0 | N19: =IFERROR(IF(L19="","",SUMIF([2]작업지시서!$D$8:$D$122,"*"&$L19,[2]작업지시서!$E$8:$E$123)),"") -> 0 | P19: =N19+O19 -> 0
C20: 모짜콘치즈김밥 | D20: 614 | E20: 524 | F20: 1138 | G20: =M20 -> 0 | H20: =P20 -> 0 | I20: =G20+H20 -> 0 | J20: =IFERROR(I20/F20,"") -> 0 | L20: 모짜콘치즈김밥 | M20: =IFERROR(IF(L20="","",SUMIF([1]작업지시서!$D$8:$D$118,"*"&$L20,[1]작업지시서!$E$8:$E$119)),"") -> 0 | N20: =IFERROR(IF(L20="","",SUMIF([2]작업지시서!$D$8:$D$122,"*"&$L20,[2]작업지시서!$E$8:$E$123)),"") -> 0 | P20: =N20+O20 -> 0
C21: =B16&" 소계" -> 김밥 소계 | D21: 8361 | E21: 7270 | F21: 15631 | G21: =SUM(G16:G20) -> 254 | H21: =SUM(H16:H20) -> 2 | I21: =SUM(I16:I20) -> 256 | J21: =IFERROR(I21/F21,"") -> 0.016377711
B22: 도시락 | C22: NEW고진많도시락 | D22: 1667 | E22: 1613 | F22: 3280 | G22: =M22 -> 0 | H22: =P22 -> 2 | I22: =G22+H22 -> 2 | J22: =IFERROR(I22/F22,"") -> 0.0006097561 | L22: NEW고진많도시락 | M22: =IFERROR(IF(L22="","",SUMIF([1]작업지시서!$D$8:$D$118,"*"&$L22,[1]작업지시서!$E$8:$E$119)),"") -> 0 | N22: =IFERROR(IF(L22="","",SUMIF([2]작업지시서!$D$8:$D$122,"*"&$L22,[2]작업지시서!$E$8:$E$123)),"") -> 0 | O22: 2 | P22: =N22+O22 -> 2
C23: 매콤닭강정도시락 | D23: 236 | E23: 205 | F23: 441 | G23: =M23 -> 0 | H23: =P23 -> 0 | I23: =G23+H23 -> 0 | J23: =IFERROR(I23/F23,"") -> 0 | L23: 매콤닭강정도시락 | M23: =IFERROR(IF(L23="","",SUMIF([1]작업지시서!$D$8:$D$118,"*"&$L23,[1]작업지시서!$E$8:$E$119)),"") -> 0 | N23: =IFERROR(IF(L23="","",SUMIF([2]작업지시서!$D$8:$D$122,"*"&$L23,[2]작업지시서!$E$8:$E$123)),"") -> 0 | P23: =N23+O23 -> 0
C24: 함박&치킨도시락 | D24: 676 | E24: 666 | F24: 1342 | G24: =M24 -> 0 | H24: =P24 -> 0 | I24: =G24+H24 -> 0 | J24: =IFERROR(I24/F24,"") -> 0 | L24: 함박&치킨도시락 | M24: =IFERROR(IF(L24="","",SUMIF([1]작업지시서!$D$8:$D$118,"*"&$L24,[1]작업지시서!$E$8:$E$119)),"") -> 0 | N24: =IFERROR(IF(L24="","",SUMIF([2]작업지시서!$D$8:$D$122,"*"&$L24,[2]작업지시서!$E$8:$E$123)),"") -> 0 | P24: =N24+O24 -> 0
C25: 국립공원)내장산새송이떡갈비 | D25: 192 | E25: 215 | F25: 407 | G25: =M25 -> 0 | H25: =P25 -> 0 | I25: =G25+H25 -> 0 | J25: =IFERROR(I25/F25,"") -> 0 | L25: 국립공원)내장산새송이떡갈비 | M25: =IFERROR(IF(L25="","",SUMIF([1]작업지시서!$D$8:$D$118,"*"&RIGHT($L25,6),[1]작업지시서!$E$8:$E$119)),"") -> 0 | N25: =IFERROR(IF(L25="","",SUMIF([2]작업지시서!$D$8:$D$122,"*"&RIGHT(L25,6),[2]작업지시서!$E$8:$E$123)),"") -> 0 | P25: =N25+O25 -> 0
C26: 밥반고기반)통마늘불고기 | D26: 231 | E26: 252 | F26: 483 | G26: =M26 -> 0 | H26: =P26 -> 0 | I26: =G26+H26 -> 0 | J26: =IFERROR(I26/F26,"") -> 0 | L26: 밥반고기반)통마늘불고기 | M26: =IFERROR(IF(L26="","",SUMIF([1]작업지시서!$D$8:$D$118,"*"&$L26,[1]작업지시서!$E$8:$E$119)),"") -> 0 | N26: =IFERROR(IF(L26="","",SUMIF([2]작업지시서!$D$8:$D$122,"*"&$L26,[2]작업지시서!$E$8:$E$123)),"") -> 0 | P26: =N26+O26 -> 0
C27: 나시고랭미고랭 | D27: 104 | E27: 140 | F27: 244 | G27: =M27 -> 0 | H27: =P27 -> 0 | I27: =G27+H27 -> 0 | J27: =IFERROR(I27/F27,"") -> 0 | L27: 나시고랭미고랭 | M27: =IFERROR(IF(L27="","",SUMIF([1]작업지시서!$D$8:$D$118,"*"&$L27,[1]작업지시서!$E$8:$E$119)),"") -> 0 | N27: =IFERROR(IF(L27="","",SUMIF([2]작업지시서!$D$8:$D$122,"*"&$L27,[2]작업지시서!$E$8:$E$123)),"") -> 0 | P27: =N27+O27 -> 0
C28: 고등급식)이불돈까스 | D28: 162 | E28: 195 | F28: 357 | G28: =M28 -> 0 | H28: =P28 -> 0 | I28: =G28+H28 -> 0 | J28: =IFERROR(I28/F28,"") -> 0 | L28: 고등급식)이불돈까스 | M28: =IFERROR(IF(L28="","",SUMIF([1]작업지시서!$D$8:$D$118,"*"&$L28,[1]작업지시서!$E$8:$E$119)),"") -> 0 | N28: =IFERROR(IF(L28="","",SUMIF([2]작업지시서!$D$8:$D$122,"*"&$L28,[2]작업지시서!$E$8:$E$123)),"") -> 0 | P28: =N28+O28 -> 0
C29: 더블고기도시락 | D29: 1022 | E29: 861 | F29: 1883 | G29: =M29 -> 0 | H29: =P29 -> 0 | I29: =G29+H29 -> 0 | J29: =IFERROR(I29/F29,"") -> 0 | L29: 더블고기도시락 | M29: =IFERROR(IF(L29="","",SUMIF([1]작업지시서!$D$8:$D$118,"*"&$L29,[1]작업지시서!$E$8:$E$119)),"") -> 0 | N29: =IFERROR(IF(L29="","",SUMIF([2]작업지시서!$D$8:$D$122,"*"&$L29,[2]작업지시서!$E$8:$E$123)),"") -> 0 | P29: =N29+O29 -> 0
C30: 황금왕돈까스도시락 | D30: 386 | E30: 410 | F30: 796 | G30: =M30 -> 0 | H30: =P30 -> 0 | I30: =G30+H30 -> 0 | J30: =IFERROR(I30/F30,"") -> 0 | L30: 황금왕돈까스도시락 | M30: =IFERROR(IF(L30="","",SUMIF([1]작업지시서!$D$8:$D$118,"*"&$L30,[1]작업지시서!$E$8:$E$119)),"") -> 0 | N30: =IFERROR(IF(L30="","",SUMIF([2]작업지시서!$D$8:$D$122,"*"&$L30,[2]작업지시서!$E$8:$E$123)),"") -> 0 | P30: =N30+O30 -> 0
C31: =B22&" 소계" -> 도시락 소계 | D31: 4676 | E31: 4557 | F31: 9233 | G31: =SUM(G22:G30) -> 0 | H31: =SUM(H22:H30) -> 2 | I31: =SUM(I22:I30) -> 2 | J31: =IFERROR(I31/F31,"") -> 0.00021661432
B32: HMR | C32: 판돌리고싶은중화요리 | D32: 39 | E32: 66 | F32: 105 | G32: =M32 -> 0 | H32: =P32 -> 0 | I32: =G32+H32 -> 0 | J32: =IFERROR(I32/F32,"") -> 0 | L32: 판돌리고싶은중화요리 | M32: =IFERROR(IF(L32="","",SUMIF([1]작업지시서!$D$8:$D$118,"*"&$L32,[1]작업지시서!$E$8:$E$119)),"") -> 0 | N32: =IFERROR(IF(L32="","",SUMIF([2]작업지시서!$D$8:$D$122,"*"&$L32,[2]작업지시서!$E$8:$E$123)),"") -> 0 | P32: =N32+O32 -> 0
C33: 도토리묵사발 | D33: 164 | E33: 142 | F33: 306 | G33: =M33 -> 0 | H33: =P33 -> 0 | I33: =G33+H33 -> 0 | J33: =IFERROR(I33/F33,"") -> 0 | L33: 도토리묵사발 | M33: =IFERROR(IF(L33="","",SUMIF([1]작업지시서!$D$8:$D$118,"*"&$L33,[1]작업지시서!$E$8:$E$119)),"") -> 0 | N33: =IFERROR(IF(L33="","",SUMIF([2]작업지시서!$D$8:$D$122,"*"&$L33,[2]작업지시서!$E$8:$E$123)),"") -> 0 | P33: =N33+O33 -> 0
C34: =B32&" 소계" -> HMR 소계 | D34: 203 | E34: 208 | F34: 411 | G34: =SUM(G32:G33) -> 0 | H34: =SUM(H32:H33) -> 0 | I34: =SUM(I32:I33) -> 0 | J34: =IFERROR(I34/F34,"") -> 0
B35: 버거 | C35: 치즈폭탄버거 | D35: 496 | E35: 693 | F35: 1189 | G35: =M35 -> 0 | H35: =P35 -> 0 | I35: =G35+H35 -> 0 | J35: =IFERROR(I35/F35,"") -> 0 | L35: 치즈폭탄버거 | M35: =IFERROR(IF(L35="","",SUMIF([1]작업지시서!$D$8:$D$118,"*"&$L35,[1]작업지시서!$E$8:$E$119)),"") -> 0 | N35: =IFERROR(IF(L35="","",SUMIF([2]작업지시서!$D$8:$D$122,"*"&$L35,[2]작업지시서!$E$8:$E$123)),"") -> 0 | P35: =N35+O35 -> 0
C36: 고등급식)더블킹새우버거 | D36: 171 | E36: 191 | F36: 362 | G36: =M36 -> 0 | H36: =P36 -> 0 | I36: =G36+H36 -> 0 | J36: =IFERROR(I36/F36,"") -> 0 | L36: 고등급식)더블킹새우버거 | M36: =IFERROR(IF(L36="","",SUMIF([1]작업지시서!$D$8:$D$118,"*"&$L36,[1]작업지시서!$E$8:$E$119)),"") -> 0 | N36: =IFERROR(IF(L36="","",SUMIF([2]작업지시서!$D$8:$D$122,"*"&$L36,[2]작업지시서!$E$8:$E$123)),"") -> 0 | P36: =N36+O36 -> 0
C37: 빅)소불고기버거 | D37: 737 | E37: 711 | F37: 1448 | G37: =M37 -> 0 | H37: =P37 -> 0 | I37: =G37+H37 -> 0 | J37: =IFERROR(I38/F37,"") -> 0 | L37: 빅)소불고기버거 | M37: =IFERROR(IF(L37="","",SUMIF([1]작업지시서!$D$8:$D$118,"*"&$L37,[1]작업지시서!$E$8:$E$119)),"") -> 0 | N37: =IFERROR(IF(L37="","",SUMIF([2]작업지시서!$D$8:$D$122,"*"&$L37,[2]작업지시서!$E$8:$E$123)),"") -> 0 | P37: =N37+O37 -> 0
C38: 포크까스버거 | G38: =M38 -> 0 | H38: =P38 -> 0 | I38: =G38+H38 -> 0 | J38: =IFERROR(I39/F38,"") | L38: 포크까스버거 | M38: =IFERROR(IF(L38="","",SUMIF([1]작업지시서!$D$8:$D$118,"*"&$L38,[1]작업지시서!$E$8:$E$119)),"") -> 0 | N38: =IFERROR(IF(L38="","",SUMIF([2]작업지시서!$D$8:$D$122,"*"&$L38,[2]작업지시서!$E$8:$E$123)),"") -> 0 | P38: =N38+O38 -> 0
C39: =B35&" 소계" -> 버거 소계 | D39: 1404 | E39: 1595 | F39: 2999 | G39: =SUM(G35:G38) -> 0 | H39: =SUM(H35:H38) -> 0 | I39: =SUM(I35:I38) -> 0 | J39: =IFERROR(I39/F39,"") -> 0
B40: 샌드 위치 | C40: 고등급식)치킨데리샌드 | D40: 201 | E40: 213 | F40: 414 | G40: =M40 -> 0 | H40: =P40 -> 2 | I40: =G40+H40 -> 2 | J40: =IFERROR(I40/F40,"") -> 0.0048309179 | L40: 고등급식)치킨데리샌드 | M40: =IFERROR(IF(L40="","",SUMIF([1]작업지시서!$D$8:$D$118,"*"&$L40,[1]작업지시서!$E$8:$E$119)),"") -> 0 | N40: =IFERROR(IF(L40="","",SUMIF([2]작업지시서!$D$8:$D$122,"*"&$L40,[2]작업지시서!$E$8:$E$123)),"") -> 0 | O40: 2 | P40: =N40+O40 -> 2
C41: NEW계란듬뿍샌드위치 | D41: 212 | E41: 148 | F41: 360 | G41: =M41 -> 0 | H41: =P41 -> 0 | I41: =G41+H41 -> 0 | J41: =IFERROR(I41/F41,"") -> 0 | L41: NEW계란듬뿍샌드위치 | M41: =IFERROR(IF(L41="","",SUMIF([1]작업지시서!$D$8:$D$118,"*"&$L41,[1]작업지시서!$E$8:$E$119)),"") -> 0 | N41: =IFERROR(IF(L41="","",SUMIF([2]작업지시서!$D$8:$D$122,"*"&$L41,[2]작업지시서!$E$8:$E$123)),"") -> 0 | P41: =N41+O41 -> 0
...
