Workbook

Sheet 부자재
A1: 부자재 | D1: =TODAY() -> 46324 | J1: 작성 | K1: 검토 | L1: 승인
A3: 재고조사자 | F3: 6/14 기준 | H3: 재고조사 시간
A4: 구분 | B4: 거래처 | C4: ID | D4: 제품명 | E4: 입고일 | F4: 일 사용량 (박스) | G4: 카테고리 | H4: 박스 | I4: 낱개(봉) | J4: 현재고(봉) | K4: 입수량 | L4: 완제품명 | M4: 봉단가 | N4: 금액
A5: 1 | B5: 글로벌코리아 | D5: 54*45 적색(삼각) 3500장 (20롤*1박스) | E5: D+2 | F5: =IFERROR(VLOOKUP(C5,[1]Sheet1!$A$1:$D$65536,3,0)/K5,"") | G5: 바코드 | J5: =H5*K5+I5 -> 0 | K5: 20 | N5: =M5*J5 -> 0
A6: 2 | B6: 글로벌코리아 | D6: 54*45 청색(삼각) 3500장 (20롤*1박스) | E6: D+2 | F6: =IFERROR(VLOOKUP(C6,[1]Sheet1!$A$1:$D$65536,3,0)/K6,"") | G6: 바코드 | J6: =H6*K6+I6 -> 0 | K6: 20 | N6: =M6*J6 -> 0
A7: 3 | B7: 글로벌코리아 | D7: 56*45 적색(김밥) 3500장 (20롤*1박스) | E7: D+2 | F7: =IFERROR(VLOOKUP(C7,[1]Sheet1!$A$1:$D$65536,3,0)/K7,"") | G7: 바코드 | J7: =H7*K7+I7 -> 0 | K7: 20 | N7: =M7*J7 -> 0
A8: 4 | B8: 글로벌코리아 | D8: 56*45 청색(김밥) 3500장 (20롤*1박스) | E8: D+2 | F8: =IFERROR(VLOOKUP(C8,[1]Sheet1!$A$1:$D$65536,3,0)/K8,"") | G8: 바코드 | J8: =H8*K8+I8 -> 0 | K8: 20 | N8: =M8*J8 -> 0
A9: 5 | B9: 글로벌코리아 | D9: 60*35 적색(도시락) 4000장 (20롤*1박스) | E9: D+2 | F9: =IFERROR(VLOOKUP(C9,[1]Sheet1!$A$1:$D$65536,3,0)/K9,"") | G9: 바코드 | J9: =H9*K9+I9 -> 0 | K9: 20 | N9: =M9*J9 -> 0
A10: 6 | B10: 글로벌코리아 | D10: 60*35 청색(도시락) 4000장 (20롤*1박스) | E10: D+2 | F10: =IFERROR(VLOOKUP(C10,[1]Sheet1!$A$1:$D$65536,3,0)/K10,"") | G10: 바코드 | J10: =H10*K10+I10 -> 0 | K10: 20 | N10: =M10*J10 -> 0
A11: 7 | B11: GMRO | D11: 에코피드수축필름 (12mic*16inch*1500m) (1롤*1박스) | E11: D+2 | F11: =IFERROR(VLOOKUP(C11,[1]Sheet1!$A$1:$D$65536,3,0)/K11,"") | G11: 수축필름 | J11: =H11*K11+I11 -> 0 | K11: 1 | N11: =M11*J11 -> 0
A12: 8 | B12: 대동전산폼 | D12: QCS 감열지(흰색) 400장 (40롤*1박스) | E12: D+7 | F12: =IFERROR(VLOOKUP(C12,[1]Sheet1!$A$1:$D$65536,3,0)/K12,"") | G12: 소모품 | J12: =H12*K12+I12 -> 0 | K12: 40 | N12: =M12*J12 -> 0
A13: 9 | B13: 비닐월드 | D13: 쓰레기봉투 (400매) | E13: D+2 | F13: =IFERROR(VLOOKUP(C13,[1]Sheet1!$A$1:$D$65536,3,0)/K13,"") | G13: 소모품 | J13: =H13*K13+I13 -> 0 | K13: 1 | N13: =M13*J13 -> 0
A14: 10 | B14: 비닐월드 | D14: 밥비닐/윗트임(900매) 청색 | E14: D+2 | F14: =IFERROR(VLOOKUP(C14,[1]Sheet1!$A$1:$D$65536,3,0)/K14,"") | G14: 소모품 | J14: =H14*K14+I14 -> 0 | K14: 1 | N14: =M14*J14 -> 0
A15: 11 | B15: 비닐월드 | D15: 밥비닐/윗트임(900매) 적색 | E15: D+2 | F15: =IFERROR(VLOOKUP(C15,[1]Sheet1!$A$1:$D$65536,3,0)/K15,"") | G15: 소모품 | J15: =H15*K15+I15 -> 0 | K15: 1 | N15: =M15*J15 -> 0
A16: 12 | B16: 비닐월드 | D16: 밥비닐/옆트임(900매) 청색 | E16: D+2 | F16: =IFERROR(VLOOKUP(C16,[1]Sheet1!$A$1:$D$65536,3,0)/K16,"") | G16: 소모품 | J16: =H16*K16+I16 -> 0 | K16: 1 | N16: =M16*J16 -> 0
... A21: 17 | B21: 대영하이텍 | D21: 옆트임(적색)[110(10)*70] 900매 (18KG*1박스) | E21: D+2 | F21: =IFERROR(VLOOKUP(C21,[1]Sheet1!$A$1:$D$65536,3,0)/K21,"") | G21: 소모품 | J21: =H21*K21+I21 -> 0 | K21: 1 | N21: =M21*J21 -> 0
A22: 18 | B22: 한국아사히소교 | C22: 30003484 | D22: 통오이김밥)지함 800매*1박스 | E22: D+2 | F22: =IFERROR(VLOOKUP(C22,[1]Sheet1!$A$1:$D$65536,3,0),"") | G22: 지함 | J22: =H22*K22+I22 -> 0 | K22: 1 | L22: 통오이김밥 | N22: =M22*J22 -> 0
A23: 19 | B23: 한국아사히소교 | C23: 30003483 | D23: 통오이김밥)투명필름 8000매*1박스 (400장*20봉) | E23: D+2 | F23: =IFERROR(VLOOKUP(C23,[1]Sheet1!$A$1:$D$65536,3,0),"") | G23: 필름 | J23: =H23*K23+I23 -> 0 | K23: 20 | L23: 통오이김밥 | N23: =M23*J23 -> 0
A24: 18 | B24: 한국아사히소교 | C24: 30003539 | D24: 왕돈까스김밥 500매*12봉 | E24: D+2 | F24: =IFERROR(VLOOKUP(C24,[1]Sheet1!$A$1:$D$65536,3,0),"") -> 3.682 | G24: 필름 | J24: =H24*K24+I24 -> 0 | K24: 12 | N24: =M24*J24 -> 0
A25: 19 | B25: 한국아사히소교 | C25: 30003574 | D25: 종가)김치제육김밥 500매*12봉 | E25: D+2 | F25: =IFERROR(VLOOKUP(C25,[1]Sheet1!$A$1:$D$65536,3,0),"") -> 2.29 | G25: 필름 | J25: =H25*K25+I25 -> 0 | K25: 12 | N25: =M25*J25 -> 0
A26: 19 | B26: 한국아사히소교 | C26: 30003646 | D26: 참치김치볶음김밥 500매*12봉 | E26: D+2 | G26: 필름 | J26: =H26*K26+I26 -> 0 | K26: 12 | N26: =M26*J26 -> 0
A27: 19 | B27: 한국아사히소교 | C27: 30003682 | D27: 필름)진미채치즈김밥 500매*12봉 | E27: D+2 | G27: 필름 | J27: =H27*K27+I27 -> 0 | K27: 12 | N27: =M27*J27 -> 0
A28: 20 | B28: 골드필름(네트웍스) | C28: 30003097 | D28: 골드)델리캡/퍼스트/가온/GFS/제이비/삼영]간지 4.5*15 1,000매*1봉 | E28: D+2 | F28: =IFERROR(VLOOKUP(C28,[1]Sheet1!$A$1:$D$65536,3,0),"") -> 0.203 | G28: 소모품 | J28: =H28*K28+I28 -> 0 | K28: 1 | L28: 슈퍼핫도그 2종 | N28: =M28*J28 -> 0
A29: 21 | B29: 골드필름(네트웍스) | C29: 30003096 | D29: 골드)GFS]간지 9*9 1,000매*1봉 | E29: D+2 | F29: =IFERROR(VLOOKUP(C29,[1]Sheet1!$A$1:$D$65536,3,0),"") -> 0.884 | G29: 소모품 | J29: =H29*K29+I29 -> 0 | K29: 1 | L29: 혜자)돌아온 등심돈까스 | N29: =M29*J29 -> 0
A30: 21 | B30: 골드필름(네트웍스) | C30: 30003096 | D30: 골드)GFS]간지 6*6 1,000매*1봉 | E30: D+2 | F30: =IFERROR(VLOOKUP(C30,[1]Sheet1!$A$1:$D$65536,3,0),"") -> 0.884 | G30: 소모품 | J30: =H30*K30+I30 -> 0 | K30: 1 | N30: =M30*J30 -> 0
A31: 22 | B31: 골드필름(네트웍스) | C31: 30003529 | D31: 골드)한국/GFS]THE근본김밥 500매*20봉 | E31: D+2 | F31: =IFERROR(VLOOKUP(C31,[1]Sheet1!$A$1:$D$65536,3,0),"") -> 5.872 | G31: 필름 | J31: =H31*K31+I31 -> 0 | K31: 20 | N31: =M31*J31 -> 0
A32: 23 | B32: 골드필름(네트웍스) | C32: 30003538 | D32: 골드)델리/퍼스트/우리/GFS]더블치즈소시지김밥 500매*20봉 | E32: D+2 | F32: =IFERROR(VLOOKUP(C32,[1]Sheet1!$A$1:$D$65536,3,0),"") -> 3.024 | G32: 필름 | J32: =H32*K32+I32 -> 0 | K32: 20 | N32: =M32*J32 -> 0
A33: 24 | B33: 골드필름(네트웍스) | C33: 30003540 | D33: 골드)퍼스트/델리/GFS]불고기치즈김밥 500매*20봉 | E33: D+2 | F33: =IFERROR(VLOOKUP(C33,[1]Sheet1!$A$1:$D$65536,3,0),"") -> 3.092 | G33: 필름 | J33: =H33*K33+I33 -> 0 | K33: 20 | N33: =M33*J33 -> 0
A34: 25 | B34: 골드필름(네트웍스) | C34: 30003618 | D34: 골드)퍼스트/델리/GFS]스팸계란치즈김밥 500매*20봉 | E34: D+2 | F34: =IFERROR(VLOOKUP(C34,[1]Sheet1!$A$1:$D$65536,3,0),"") | G34: 필름 | J34: =H34*K34+I34 -> 0 | K34: 20 | N34: =M34*J34 -> 0
A35: 26 | B35: 골드필름(네트웍스) | C35: 30003598 | D35: 골드)GFS/서브]직화)한돈제육쌈김밥 500매*20봉 | E35: D+2 | F35: =IFERROR(VLOOKUP(C35,[1]Sheet1!$A$1:$D$65536,3,0),"") -> 6.77 | G35: 필름 | J35: =H35*K35+I35 -> 0 | K35: 20 | N35: =M35*J35 -> 0
A36: 27 | B36: 골드필름(네트웍스) | C36: 30003165 | D36: 골드)퍼스트/GFS]착한김치김밥 500매*20봉 | E36: D+2 | F36: =IFERROR(VLOOKUP(C36,[1]Sheet1!$A$1:$D$65536,3,0),"") -> 0.418 | G36: 필름 | J36: =H36*K36+I36 -> 0 | K36: 20 | N36: =M36*J36 -> 0
A37: 28 | B37: 골드필름(네트웍스) | C37: 30003166 | D37: 골드)퍼스트/GFS]착한참치마요김밥 500매*20봉 | E37: D+2 | F37: =IFERROR(VLOOKUP(C37,[1]Sheet1!$A$1:$D$65536,3,0),"") -> 0.52 | G37: 필름 | J37: =H37*K37+I37 -> 0 | K37: 20 | N37: =M37*J37 -> 0
A38: 29 | B38: 골드필름(네트웍스) | C38: 30003325 | D38: 골드)GFS]NEW스팸무스비 5000매*1롤 | E38: D+2 | F38: =IFERROR(VLOOKUP(C38,[1]Sheet1!$A$1:$D$65536,3,0),"") -> 0.413 | G38: 필름 | J38: =H38*K38+I38 -> 0 | K38: 1 | N38: =M38*J38 -> 0
A39: 30 | B39: 골드필름(네트웍스) | C39: 30003337 | D39: 골드)GFS/퍼스트]착한핫도그양배추사라다 3700매*1롤 | E39: D+2 | F39: =IFERROR(VLOOKUP(C39,[1]Sheet1!$A$1:$D$65536,3,0),"") -> 0.024 | G39: 필름 | J39: =H39*K39+I39 -> 0 | K39: 1 | N39: =M39*J39 -> 0
A40: 31 | B40: 골드필름(네트웍스) | C40: 30003336 | D40: 골드)GFS/퍼스트]착한핫도그오리지널 3700매*1롤 | E40: D+2 | F40: =IFERROR(VLOOKUP(C40,[1]Sheet1!$A$1:$D$65536,3,0),"") -> 0.031 | G40: 필름 | J40: =H40*K40+I40 -> 0 | K40: 1 | N40: =M40*J40 -> 0
A41: 32 | B41: 골드필름(네트웍스) | C41: 30003655 | D41: 골드)GFS]무스비)햄&참치김치볶음밥 5000매*1롤 | E41: D+2 | F41: =IFERROR(VLOOKUP(C41,[1]Sheet1!$A$1:$D$65536,3,0),"") | G41: 필름 | J41: =H41*K41+I41 -> 0 | K41: 1 | N41: =M41*J41 -> 0
... A51: 40 | B51: i-printing | C51: 30003604 | D51: 삼각)전주비빔 (4000) | E51: D+2 | F51: =IFERROR(VLOOKUP(C51,[1]Sheet1!$A$1:$D$65536,3,0),"") -> 1.014 | G51: 스티커 | J51: =H51*K51+I51 -> 0 | K51: 1 | N51: =M51*J51 -> 0
A52: 41 | B52: i-printing | C52: 30003615 | D52: 이달의도시락6월(미식편) (1500) | E52: D+2 | F52: =IFERROR(VLOOKUP(C52,[1]Sheet1!$A$1:$D$65536,3,0),"")/1500 -> 0.744 | G52: 스티커 | J52: =H52*K52+I52 -> 0 | K52: 1 | N52: =M52*J52 -> 0
A53: 42 | B53: i-printing | C53: 30003718 | D53: 종가)들기름묵은지참치 (3000) | E53: D+2 | F53: =IFERROR(VLOOKUP(C53,[1]Sheet1!$A$1:$D$65536,3,0),"") | G53: 스티커 | J53: =H53*K53+I53 -> 0 | K53: 1 | N53: =M53*J53 -> 0
A54: 44 | B54: i-printing | C54: 30003554 | D54: 착한)마파두부덮밥(3,900원) (1500) | E54: D+2 | F54: =IFERROR(VLOOKUP(C54,[1]Sheet1!$A$1:$D$65536,3,0),"") -> 0.023 | G54: 스티커 | J54: =H54*K54+I54 -> 0 | K54: 1 | N54: =M54*J54 -> 0
...

Sheet 냉장1
A1: 냉장1 | D1: =TODAY() -> 46324 | J1: 작성 | K1: 검토 | L1: 승인
A3: 재고조사자 | F3: 6/14 기준 | H3: 재고조사 시간
A4: 구분 | B4: 거래처 | C4: ID | D4: 제품명 | E4: 입고일 | F4: 일 사용량 (박스) | G4: 유통기한 | H4: 박스 | I4: 낱개 | J4: 현재고(봉) | K4: 입수량 | L4: 발주일 | M4: 봉단가 | N4: 금액
A5: 1 | B5: 농심태경(금행) | C5: 30002902 | D5: [냉장]토마토파스타소스(2kg*6ea) | E5: D+2 | F5: =IFERROR(VLOOKUP(C5,[1]Sheet1!$A$1:$D$65536,3,0)/K5,"") -> 2.0011667 | H5: 7 | I5: 5 | J5: =H5*K5+I5 -> 47 | K5: 6 | L5: 샐 | M5: 5150 | N5: =M5*J5 -> 242050
A6: 2 | B6: 다미푸드텍(금행) | C6: 30002904 | D6: [냉장] 할라피뇨칠리소스(3kg*5ea) | E6: D+2 | F6: =IFERROR(VLOOKUP(C6,[1]Sheet1!$A$1:$D$65536,3,0)/K6,"") -> 0.6116 | H6: 3 | I6: 2 | J6: =H6*K6+I6 -> 17 | K6: 5 | L6: 샐 | M6: 11400 | N6: =M6*J6 -> 193800 | O6: 3/17신상
A7: 3 | B7: 다미푸드텍(금행) | C7: 30003064 | D7: [냉장] 쌈장마요소스(3KG*5EA) | E7: D+2 | F7: =IFERROR(VLOOKUP(C7,[1]Sheet1!$A$1:$D$65536,3,0)/K7,"") -> 1.2412 | H7: 1 | I7: 2 | J7: =H7*K7+I7 -> 7 | K7: 5 | L7: 샐 | M7: =4900*3 -> 14700 | N7: =M7*J7 -> 102900
A8: 4 | B8: 다미푸드텍(금행) | C8: 30003367 | D8: [냉장] 잡채용소스_JH (3kg*5ea) | E8: D+2 | H8: 1 | I8: 3 | J8: =H8*K8+I8 -> 8 | K8: 5 | L8: 샐 | M8: 11400 | N8: =M8*J8 -> 91200 | O8: 3/17신상
A9: 5 | B9: 다미푸드텍(금행) | C9: 20194666 | D9: [냉장] 카츠도시락용소스 (3kg*5ea) | E9: D+2 | H9: 12 | J9: =H9*K9+I9 -> 60 | K9: 5 | L9: 샐 | M9: =4900*3 -> 14700 | N9: =M9*J9 -> 882000
A10: 6 | B10: 대상(리테일) | C10: 30002846 | D10: [냉장] 비빔밥용고추장소스 (2kg*5ea) | E10: D+2 | F10: =IFERROR(VLOOKUP(C10,[1]Sheet1!$A$1:$D$65536,3,0)/K10,"") -> 0.4422 | H10: 1 | I10: 2 | J10: =H10*K10+I10 -> 7 | K10: 5 | L10: 커 | M10: 8910 | N10: =M10*J10 -> 62370
A11: 7 | B11: 대상(리테일) | C11: 30003596 | D11: [냉장] 쉐프원 불맛베이스(캡파우치)(2kg*5ea) | E11: D+2 | F11: =IFERROR(VLOOKUP(C11,[1]Sheet1!$A$1:$D$65536,3,0)/K11,"") -> 1.1394 | H11: 1 | I11: 3 | J11: =H11*K11+I11 -> 8 | K11: 5 | L11: 샐 | M11: =80700/5 -> 16140 | N11: =M11*J11 -> 129120
A12: 8 | B12: 동방푸드마스타(금행) | C12: 30002896 | D12: [냉장]통통쏘야소스(3kg*4ea) | E12: D+2 | F12: =IFERROR(VLOOKUP(C12,[1]Sheet1!$A$1:$D$65536,3,0)/K12,"") -> 0.893 | H12: 3 | I12: 2 | J12: =H12*K12+I12 -> 14 | K12: 4 | L12: 커 | M12: 10200 | N12: =M12*J12 -> 142800
A13: 9 | B13: 동방푸드마스타(금행) | C13: 30003617 | D13: [냉장] 데리야끼마요소스-FS (3kg*4ea) | E13: D+2 | F13: =IFERROR(VLOOKUP(C13,[1]Sheet1!$A$1:$D$65536,3,0)/K13,"") | H13: 6 | J13: =H13*K13+I13 -> 24 | K13: 4 | L13: 샐 | M13: 14280 | N13: =M13*J13 -> 342720
A14: 10 | B14: 매일유업(리테일) | C14: 20195150 | D14: [냉장] 마일드체다SOS치즈(960g*16ea) | E14: D+3 | F14: =IFERROR(VLOOKUP(C14,[1]Sheet1!$A$1:$D$65536,3,0)/K14,"") -> 1.990875 | H14: 9 | I14: 11 | J14: =H14*K14+I14 -> 155 | K14: 16 | L14: 커 | M14: 7440 | N14: =M14*J14 -> 1153200
A15: 11 | B15: 반찬단지(리테일) | C15: 30003582 | D15: [냉장]8mm김밥단무지2.5kg(냉장)BOX(2.5KG*4EA) | E15: D+1 | F15: =IFERROR(VLOOKUP(C15,[1]Sheet1!$A$1:$D$65536,3,0)/K15,"") -> 10.21875 | H15: 14 | I15: 2 | J15: =H15*K15+I15 -> 58 | K15: 4 | L15: 커 | M15: 3950 | N15: =M15*J15 -> 229100 | O15: 5/5신상
A16: 11 | B16: 반찬단지(리테일) | C16: 30003582 | D16: [냉장] 세천팜)김밥단무지 (2.5kg*4ea) | E16: D+1 | F16: =IFERROR(VLOOKUP(C16,[1]Sheet1!$A$1:$D$65536,3,0)/K16,"") -> 10.21875 | H16: 34 | J16: =H16*K16+I16 -> 136 | K16: 4 | L16: 커 | M16: 3950 | N16: =M16*J16 -> 537200 | O16: 5/5신상
A17: 12 | B17: 부림 | C17: 20001846 | D17: [냉장] 당근채(4kg*3봉 - 1박스) | E17: D+1 | F17: =IFERROR(VLOOKUP(C17,[1]Sheet1!$A$1:$D$65536,3,0)/K17,"") -> 16.602 | H17: 15 | J17: =H17*K17+I17 -> 45 | K17: 3 | L17: 야 | M17: 7600 | N17: =M17*J17 -> 342000
A18: 13 | B18: 선진FS(리테일) | C18: 30002903 | D18: [냉장] 치즈콕콕소시지(1.4kg*8ea) (1봉=100g*14ea) | E18: D+2 | F18: =IFERROR(VLOOKUP(C18,[1]Sheet1!$A$1:$D$65536,3,0)/K18,"") -> 9.45 | H18: 24 | J18: =H18*K18+I18 -> 192 | K18: 8 | L18: 커 | M18: =81810/8 -> 10226.25 | N18: =M18*J18 -> 1963440 | O18: 3/17신상
A19: 14 | B19: 선진FS(리테일) | C19: 30003671 | D19: [냉장] 통통한칼집소시지 PK(990g) | E19: D+1 | F19: =IFERROR(VLOOKUP(C19,[1]Sheet1!$A$1:$D$65536,3,0)/K19,"") | H19: 20 | I19: 22 | J19: =H19*K19+I19 -> 222 | K19: 10 | L19: 커 | M19: 6300 | N19: =M19*J19 -> 1398600
A20: 15 | B20: 아워홈(리테일) | C20: 30003656 | D20: [냉장] 마당놀이2(사각어묵)(1kg*10ea) | E20: D+2 | F20: =IFERROR(VLOOKUP(C20,[1]Sheet1!$A$1:$D$65536,3,0)/K20,"") | G20: 변경 | H20: 6 | I20: 26 | J20: =H20*K20+I20 -> 86 | K20: 10 | M20: 3200 | N20: =M20*J20 -> 275200
A21: 16 | B21: 아워홈(리테일) | C21: 30001165 | D21: [냉장] 깍두기(10kg*box) | E21: D+2 | F21: =IFERROR(VLOOKUP(C21,[1]Sheet1!$A$1:$D$65536,3,0)/K21,"") -> 2.82 | H21: 4 | J21: =H21*K21+I21 -> 4 | K21: 1 | L21: 야 | M21: 19800 | N21: =M21*J21 -> 79200
A22: 17 | B22: 아워홈(리테일) | C22: 30002355 | D22: [냉장] 알뜰어묵볼대림 (1kg*10봉) | E22: D+2 | F22: =IFERROR(VLOOKUP(C22,[1]Sheet1!$A$1:$D$65536,3,0)/K22,"") -> 2.626 | G22: 변경 | J22: =H22*K22+I22 -> 0 | K22: 10 | L22: 커 | M22: 2230 | N22: =M22*J22 -> 0
A23: 18 | B23: 아워홈(리테일) | C23: 30003673 | D23: [냉장]숯불갈비맛소스_2kg 행복한맛남 | E23: D+2 | F23: =IFERROR(VLOOKUP(C23,[1]Sheet1!$A$1:$D$65536,3,0)/K23,"") | H23: 1 | J23: =H23*K23+I23 -> 1 | K23: 1 | L23: 커 | M23: 2230 | N23: =M23*J23 -> 2230
A24: 19 | B24: 아워홈(리테일) | C24: 30002684 | D24: [냉장] 아워홈)채어묵Ⅲ (1kg*10ea) | E24: D+2 | F24: =IFERROR(VLOOKUP(C24,[1]Sheet1!$A$1:$D$65536,3,0)/K24,"") | G24: 영풍김밥용 | J24: =H24*K24+I24 -> 0 | K24: 10 | M24: 2810 | N24: =M24*J24 -> 0
A25: 20 | B25: 엠디에스코리아 (CJ) | C25: 30002593 | D25: [냉장] 콘버터G (1kg*10봉) | E25: D+2 | F25: =IFERROR(VLOOKUP(C25,[1]Sheet1!$A$1:$D$65536,3,0)/K25,"") -> 2.6006 | H25: 12 | I25: 9 | J25: =H25*K25+I25 -> 129 | K25: 10 | L25: 커 | M25: 5200 | N25: =M25*J25 -> 670800
A26: 21 | B26: 엠디에스코리아 (CJ) | C26: 30002318 | D26: [냉장] 만능마카로니샐러드(1kg*10봉) | E26: D+2 | F26: 3.8 | H26: 9 | J26: =H26*K26+I26 -> 90 | K26: 10 | L26: 커 | M26: 4300 | N26: =M26*J26 -> 387000
A27: 22 | B27: 엠디에스코리아 (CJ) | C27: 30003566 | D27: [냉장]마카로니샐러드(1kg*10봉) | E27: D+2 | F27: 3.8 | H27: 2 | J27: =H27*K27+I27 -> 20 | K27: 10 | L27: 커 | M27: 4300 | N27: =M27*J27 -> 86000
A28: 23 | B28: 이레팜(네트웍스) | C28: 30002007 | D28: [냉장] 계란구이(세절)(1020g*12봉) | E28: D+2 | F28: =IFERROR(VLOOKUP(C28,[1]Sheet1!$A$1:$D$65536,3,0)/K28,"") -> 1.2630833 | I28: 10 | J28: =H28*K28+I28 -> 10 | K28: 12 | L28: 커 | M28: 5900 | N28: =M28*J28 -> 59000
A29: 24 | B29: 이레팜(네트웍스) | C29: 30000910 | D29: [냉장] 야채계란말이(900g*12봉) | E29: D+2 | F29: =IFERROR(VLOOKUP(C29,[1]Sheet1!$A$1:$D$65536,3,0)/K29,"") -> 2.4375833 | H29: 8 | I29: 9 | J29: =H29*K29+I29 -> 105 | K29: 12 | L29: 커 | M29: 6250 | N29: =M29*J29 -> 656250
A30: 25 | B30: 이레팜(네트웍스) | C30: 30003510 | D30: [냉장] 더커진계란구이(1.02kg*12ea) | E30: D+2 | F30: =IFERROR(VLOOKUP(C30,[1]Sheet1!$A$1:$D$65536,3,0)/K30,"") -> 7.81175 | H30: 9 | I30: 6 | J30: =H30*K30+I30 -> 114 | K30: 12 | L30: 커 | M30: 5900 | N30: =M30*J30 -> 672600 | O30: 3/10신상
A31: 26 | B31: 이우유통 | C31: 30003288 | D31: [냉장] 송송오이피클(1kg*6ea) | E31: D+1 | F31: =IFERROR(VLOOKUP(C31,[1]Sheet1!$A$1:$D$65536,3,0)/K31,"") -> 0.35616667 | H31: 1 | J31: =H31*K31+I31 -> 6 | K31: 6 | L31: 샐 | M31: 3900 | N31: =M31*J31 -> 23400
A32: 27 | B32: 이우유통 | C32: 30003599 | D32: [냉장] 조리편한조각두부(부침용) (3kg(88ea)*3pk) | E32: D+1 | F32: =IFERROR(VLOOKUP(C32,[1]Sheet1!$A$1:$D$65536,3,0)/K32,"") -> 8.4546667 | H32: 58 | J32: 2 | K32: 3 | L32: 샐 | M32: 3900 | N32: =M32*J32 -> 7800
A33: 27 | B33: 이우유통 | C33: 30003599 | D33: [냉장] 신슈단무지 찹핑 (1kg*10pk ) | E33: D+1 | F33: =IFERROR(VLOOKUP(C33,[1]Sheet1!$A$1:$D$65536,3,0)/K33,"") -> 2.5364 | H33: 7 | I33: 5 | J33: 2 | K33: 10 | L33: 샐 | M33: 3900 | N33: =M33*J33 -> 7800
A34: 28 | B34: 진주햄(동원) | C34: 30000376 | D34: [냉장] 골드88세절K(1kg*10봉) | E34: D+1 | F34: =IFERROR(VLOOKUP(C34,[1]Sheet1!$A$1:$D$65536,3,0)/K34,"") -> 3.2648 | H34: 7 | I34: 2 | J34: =H34*K34+I34 -> 72 | K34: 10 | L34: 커 | M34: 5150 | N34: =M34*J34 -> 370800
A35: 29 | B35: 진주햄(동원) | C35: 30002614 | D35: [냉장] 알뜰주부진주줄줄이(1kg*10봉) | E35: D+1 | F35: =IFERROR(VLOOKUP(C35,[1]Sheet1!$A$1:$D$65536,3,0)/K35,"") -> 5.9682 | G35: 대체품 | H35: 3 | I35: 10 | J35: =H35*K35+I35 -> 40 | K35: 10 | L35: 커 | M35: 5500 | N35: =M35*J35 -> 220000
A36: 29 | B36: 진주햄(동원) | C36: 30003766 | D36: [냉장]숯불갈비맛스모크햄세절48(1KG*10) | E36: D+1 | F36: =IFERROR(VLOOKUP(C36,[1]Sheet1!$A$1:$D$65536,3,0)/K36,"") | H36: 3 | I36: 6 | J36: =H36*K36+I36 -> 36 | K36: 10 | L36: 커 | M36: 6900 | N36: =M36*J36 -> 248400
A37: 30 | B37: 한성기업 (동원) | C37: 20001849 | D37: [냉장] 게맛살(1.2kg*10봉) | E37: D+2 | F37: =IFERROR(VLOOKUP(C37,[1]Sheet1!$A$1:$D$65536,3,0)/K37,"") -> 5.3747 | H37: 5 | I37: 4 | J37: =H37*K37+I37 -> 54 | K37: 10 | L37: 커 | M37: 4200 | N37: =M37*J37 -> 226800
A38: 31 | B38: 풍림푸드(리테일) | C38: 30003695 | D38: [냉장]계란말이G900gBOX(900g*10pk) | E38: D+1 | F38: =IFERROR(VLOOKUP(C38,[1]Sheet1!$A$1:$D$65536,3,0)/K38,"") | H38: 25 | J38: =H38*K38+I38 -> 250 | K38: 10 | L38: 커 | M38: 24400 | N38: =M38*J38 -> 6100000
A39: 32 | B39: 태원식품(금행) | C39: 30003556 | D39: [냉장] 마라상궈소스(2kg*5ea) | E39: D+2 | F39: =IFERROR(VLOOKUP(C39,[1]Sheet1!$A$1:$D$65536,3,0)/K39,"") -> 0.0074 | J39: =H39*K39+I39 -> 0 | K39: 5 | L39: 계 | M39: 19200 | N39: =M39*J39 -> 0 | O39: 3/26신상
A40: 33 | B40: 태원식품(금행) | C40: 30003528 | D40: [냉장] 불맛향미유 (2kg*5ea) | E40: D+2 | F40: =IFERROR(VLOOKUP(C40,[1]Sheet1!$A$1:$D$65536,3,0)/K40,"") -> 0.0454 | I40: 1 | J40: =H40*K40+I40 -> 1 | K40: 5 | L40: 계 | M40: 26500 | N40: =M40*J40 -> 26500 | O40: 4/07신상
A41: 34 | B41: 한성기업 (동원) | C41: 30003070 | D41: [냉장] 숯불구이맛김밥햄(200g*30ea) | E41: D+2 | F41: =IFERROR(VLOOKUP(C41,[1]Sheet1!$A$1:$D$65536,3,0)/K41,"") -> 0.4 | H41: 1 | I41: 20 | J41: =H41*K41+I41 -> 50 | K41: 30 | L41: 커 | M41: 1820 | N41: =M41*J41 -> 91000
...

Sheet 냉장2
A1: 냉장2 | D1: =냉장1!D1 -> 46324 | J1: 작성 | K1: 검토 | L1: 승인
A3: 재고조사자 | F3: =냉장1!F3 -> 6/14 기준 | H3: 재고조사 시간
A4: 구분 | B4: 거래처 | C4: ID | D4: 제품명 | E4: 발주주기 | F4: 일 사용량 (박스) | G4: 유통기한 | H4: 박스 | I4: 낱개 | J4: 현재고(봉) | K4: 입수량 | L4: 발주일 | M4: 봉단가 | N4: 금액
A5: 1 | B5: 한울(네트웍스) | C5: 30000121 | D5: [냉장] 볶음김치골드(5kg)*3 | E5: D+2 | F5: =IFERROR(VLOOKUP(C5,[1]Sheet1!$A$1:$D$65536,3,0)/K5,"") -> 16.944333 | H5: 10 | I5: 2 | J5: =H5*K5+I5 -> 32 | K5: 3 | L5: 커 | M5: 19700 | N5: =M5*J5 -> 630400
A6: 2 | B6: 한울(네트웍스) | C6: 30000096 | D6: [냉장] 다진맛김치(PBOX) 10KG*2개입 | E6: D+2 | H6: 7 | I6: 1 | J6: =H6*K6+I6 -> 15 | K6: 2 | L6: 커 | M6: 19700 | N6: =M6*J6 -> 295500
A7: 3 | B7: 한울(네트웍스) | C7: 30003681 | D7: [냉장]김밥용진미채무침(PBOX) 1KG*15봉 | E7: D+2 | H7: 3 | J7: =H7*K7+I7 -> 45 | K7: 15 | L7: 커 | M7: 19700 | N7: =M7*J7 -> 886500
A8: 4 | B8: 한울(네트웍스) | C8: 30003664 | D8: [냉장]진미채견과무침(PBOX) 1KG*15봉 | E8: D+2 | J8: =H8*K8+I8 -> 0 | K8: 15 | L8: 커 | M8: 19700 | N8: =M8*J8 -> 0
A9: 4 | B9: 한울(네트웍스) | C9: 30003744 | D9: [냉장]양념깻잎찜(PBOX) 1KG*15봉 | E9: D+2 | I9: 9 | J9: =H9*K9+I9 -> 9 | K9: 15 | L9: 커 | M9: 19700 | N9: =M9*J9 -> 177300
A10: 5 | B10: 천안fs(네트웍스) | C10: 30003607 | D10: [냉장] 가쓰오치킨데리소스(PBOX) 2KG*10개입 | E10: D+1 | F10: =IFERROR(VLOOKUP(C10,[1]Sheet1!$A$1:$D$65536,3,0)/K10,"") -> 0.3564 | H10: 1 | I10: 1 | J10: =H10*K10+I10 -> 11 | K10: 10 | L10: 계 | M10: 6000 | N10: =M10*J10 -> 66000
A11: 6 | B11: 천안fs(네트웍스) | C11: 30001057 | D11: [냉장] 간장소스K(2kg*10봉) | E11: D+1 | F11: =IFERROR(VLOOKUP(C11,[1]Sheet1!$A$1:$D$65536,3,0)/K11,"") -> 0.5099 | H11: 2 | I11: 3 | J11: =H11*K11+I11 -> 23 | K11: 10 | L11: 계 | M11: 7000 | N11: =M11*J11 -> 161000
A12: 7 | B12: 천안fs(네트웍스) | C12: 30002992 | D12: [냉장] 경양식돈까스소스H(소포장)(50g*240ea) | E12: D+1 | F12: =IFERROR(VLOOKUP(C12,[1]Sheet1!$A$1:$D$65536,3,0)/K12,"") -> 3.6833333 | H12: 10 | J12: =H12*K12+I12 -> 2400 | K12: 240 | L12: 샐 | M12: 265 | N12: =M12*J12 -> 636000
A13: 7 | B13: 천안fs(네트웍스) | C13: 30003716 | D13: [냉장]경양식돈까스소스B(PBOX) 30G*420개입 | E13: D+1 | F13: =IFERROR(VLOOKUP(C13,[1]Sheet1!$A$1:$D$65536,3,0)/K13,"") | H13: 10 | J13: =H13*K13+I13 -> 4200 | K13: 420 | L13: 샐 | M13: 265 | N13: =M13*J13 -> 1113000
A14: 8 | B14: 천안fs(네트웍스) | C14: 30000065 | D14: [냉장] 고추장불고기소스(2kg*10봉) | E14: D+1 | F14: =IFERROR(VLOOKUP(C14,[1]Sheet1!$A$1:$D$65536,3,0)/K14,"") -> 1.7284 | H14: 5 | J14: =H14*K14+I14 -> 50 | K14: 10 | L14: 샐 | M14: 8300 | N14: =M14*J14 -> 415000
A15: 10 | B15: 천안fs(네트웍스) | C15: 30003526 | D15: [냉장] 김밥용돈까스소스(PBOX) 2KG*10개입 | E15: D+1 | F15: =IFERROR(VLOOKUP(C15,[1]Sheet1!$A$1:$D$65536,3,0)/K15,"") -> 2.2544 | H15: 1 | J15: =H15*K15+I15 -> 10 | K15: 10 | L15: 샐 | M15: 4900 | N15: =M15*J15 -> 49000 | O15: 3/24신상
A16: 11 | B16: 천안fs(네트웍스) | C16: 30003509 | D16: [냉장] 김밥용조미에센스소스(PBOX) 2KG*10개입 | E16: D+1 | F16: =IFERROR(VLOOKUP(C16,[1]Sheet1!$A$1:$D$65536,3,0)/K16,"") -> 2.5044 | J16: =H16*K16+I16 -> 0 | K16: 10 | L16: 취 | M16: 5900 | N16: =M16*J16 -> 0 | O16: 3/10신상
A17: 12 | B17: 천안fs(네트웍스) | C17: 30000709 | D17: [냉장] 김치볶음밥용소스(PBOX) 2KG*10개입 | E17: D+1 | F17: =IFERROR(VLOOKUP(C17,[1]Sheet1!$A$1:$D$65536,3,0)/K17,"") -> 4.196 | H17: 18 | J17: =H17*K17+I17 -> 180 | K17: 10 | L17: 샐 | M17: 9000 | N17: =M17*J17 -> 1620000
A18: 14 | B18: 천안fs(네트웍스) | C18: 30002363 | D18: [냉장] 너비아니양념소스J(PBOX) 2KG*10개입 | E18: D+1 | F18: =IFERROR(VLOOKUP(C18,[1]Sheet1!$A$1:$D$65536,3,0)/K18,"") -> 0.9974 | I18: 9 | J18: =H18*K18+I18 -> 9 | K18: 10 | L18: 계 | M18: 7800 | N18: =M18*J18 -> 70200
A19: 15 | B19: 천안fs(네트웍스) | C19: 30002195 | D19: [냉장] 뉴비빔밥용고추장소스(PBOX) 2KG*10개입 | E19: D+1 | F19: =IFERROR(VLOOKUP(C19,[1]Sheet1!$A$1:$D$65536,3,0)/K19,"") -> 2.8006 | H19: 15 | I19: 7 | J19: =H19*K19+I19 -> 157 | K19: 10 | L19: 계 | M19: 7408 | N19: =M19*J19 -> 1163056
A20: 16 | B20: 천안fs(네트웍스) | C20: 30003011 | D20: [냉장] 다시마조미식초소스(PBOX) 2KG*10개입 | E20: D+1 | F20: =IFERROR(VLOOKUP(C20,[1]Sheet1!$A$1:$D$65536,3,0)/K20,"") -> 0.032 | J20: =H20*K20+I20 -> 0 | K20: 10 | L20: 샐 | M20: 5400 | N20: =M20*J20 -> 0
A21: 17 | B21: 천안fs(네트웍스) | C21: 30003508 | D21: [냉장] 대파크림소스(PBOX) 2KG*9개입 | E21: D+1 | F21: =IFERROR(VLOOKUP(C21,[1]Sheet1!$A$1:$D$65536,3,0)/K21,"") -> 1.8052222 | G21: 7/7삭제 | J21: =H21*K21+I21 -> 0 | K21: 9 | L21: 샐 | M21: =113400/9 -> 12600 | N21: =M21*J21 -> 0 | O21: 3/03신상
A22: 18 | B22: 천안fs(네트웍스) | C22: 30003443 | D22: [냉장] 돈까스소스(소포장) 30g*420개입 | E22: D+1 | F22: =IFERROR(VLOOKUP(C22,[1]Sheet1!$A$1:$D$65536,3,0)/K22,"") -> 4.5 | J22: =H22*K22+I22 -> 0 | K22: 420 | L22: 샐 | M22: 190 | N22: =M22*J22 -> 0
A23: 19 | B23: 천안fs(네트웍스) | C23: 30002096 | D23: [냉장] 돈까스소스-FS(PBOX) 2KG*10개입 | E23: D+1 | F23: =IFERROR(VLOOKUP(C23,[1]Sheet1!$A$1:$D$65536,3,0)/K23,"") -> 0.6565 | H23: 4 | I23: 8 | J23: =H23*K23+I23 -> 48 | K23: 10 | L23: 샐 | M23: 7800 | N23: =M23*J23 -> 374400
A24: 20 | B24: 천안fs(네트웍스) | C24: 30003662 | D24: [냉장]땡초간장소스(PBOX) 2KG*10개입 | E24: D+1 | F24: =IFERROR(VLOOKUP(C24,[1]Sheet1!$A$1:$D$65536,3,0)/K24,"") | I24: 9 | J24: =H24*K24+I24 -> 9 | K24: 10 | L24: 계 | M24: 9000
A25: 21 | B25: 천안fs(네트웍스) | C25: 30003299 | D25: [냉장] 매운돈까스소스 (2kg*10ea) | E25: D+1 | F25: =IFERROR(VLOOKUP(C25,[1]Sheet1!$A$1:$D$65536,3,0)/K25,"") -> 0.2902 | H25: 4 | I25: 1 | J25: =H25*K25+I25 -> 41 | K25: 10 | L25: 샐 | M25: 7400 | N25: =M25*J25 -> 303400
A26: 22 | B26: 천안fs(네트웍스) | C26: 30002077 | D26: [냉장] 매콤닭강정소스(2kg*10봉) | E26: D+1 | F26: =IFERROR(VLOOKUP(C26,[1]Sheet1!$A$1:$D$65536,3,0)/K26,"") -> 0.5576 | H26: 3 | I26: 3 | J26: =H26*K26+I26 -> 33 | K26: 10 | L26: 계 | M26: 7885 | N26: =M26*J26 -> 260205
A27: 23 | B27: 천안fs(네트웍스) | C27: 30003608 | D27: [냉장] NEW매콤닭강정소스(PBOX) 2KG*10개입 | E27: D+1 | F27: =IFERROR(VLOOKUP(C27,[1]Sheet1!$A$1:$D$65536,3,0)/K27,"") -> 0.5741 | G27: 6/26삭제 | J27: =H27*K27+I27 -> 0 | K27: 10 | L27: 샐 | M27: 7886 | N27: =M27*J27 -> 0
A28: 24 | B28: 천안fs(네트웍스) | C28: 30003684 | D28: [냉장]매콤흑당갈비치킨소스(PBOX) 2KG*10개입 | E28: D+1 | J28: =H28*K28+I28 -> 0 | K28: 10 | L28: 계 | M28: 9000
A29: 41 | B29: 천안fs(네트웍스) | C29: 20194658 | D29: [냉장]빨간어묵볶이소스(PBOX) 2KG*10개입 | E29: D+1 | F29: =IFERROR(VLOOKUP(C29,[1]Sheet1!$A$1:$D$65536,3,0)/K29,"") | H29: 4 | I29: 1 | J29: =H29*K29+I29 -> 33 | K29: 8 | L29: 샐 | M29: 11600 | N29: =M29*J29 -> 382800
A30: 26 | B30: 천안fs(네트웍스) | C30: 30003559 | D30: [냉장] 볶음김치소스Y(PBOX) 2KG*10개입 | E30: D+1 | F30: =IFERROR(VLOOKUP(C30,[1]Sheet1!$A$1:$D$65536,3,0)/K30,"") -> 0.3243 | J30: =H30*K30+I30 -> 0 | K30: 10 | L30: 계 | M30: 9200 | N30: =M30*J30 -> 0 | O30: 3/31신상
A31: 27 | B31: 천안fs(네트웍스) | C31: 30003579 | D31: [냉장] 비빔밥용고추장소스H(PBOX) 2KG*10개입 | E31: D+2 | F31: =IFERROR(VLOOKUP(C31,[1]Sheet1!$A$1:$D$65536,3,0)/K31,"") -> 0.9441 | J31: =H31*K31+I31 -> 0 | K31: 10 | L31: 계 | M31: 7600 | N31: =M31*J31 -> 0 | O31: 4/28신상
A32: 28 | B32: 천안fs(네트웍스) | C32: 30003543 | D32: [냉장] 삼각용다시마취반소스(PBOX) 2KG*10개입 | E32: D+1 | F32: =IFERROR(VLOOKUP(C32,[1]Sheet1!$A$1:$D$65536,3,0)/K32,"") -> 0.8812 | J32: =H32*K32+I32 -> 0 | K32: 10 | L32: 취 | M32: =156000/10 -> 15600 | N32: =M32*J32 -> 0 | O32: 3/26리뉴얼
A33: 29 | B33: 천안fs(네트웍스) | C33: 30002585 | D33: [냉장] 삼각치킨조미소스(PBOX) 2KG*10개입 | E33: D+1 | F33: =IFERROR(VLOOKUP(C33,[1]Sheet1!$A$1:$D$65536,3,0)/K33,"") -> 1.021 | H33: 3 | J33: =H33*K33+I33 -> 30 | K33: 10 | L33: 샐 | M33: 9600 | N33: =M33*J33 -> 288000
A34: 30 | B34: 천안fs(네트웍스) | C34: 30003634 | D34: [냉장]스윗닭강정소스(PBOX) 2KG*10개입 | E34: D+1 | G34: 9/1신상 | J34: =H34*K34+I34 -> 0 | K34: 10 | L34: 계 | M34: 9000
A35: 31 | B35: 천안fs(네트웍스) | C35: 30003439 | D35: [냉장] 쏘야볶음소스H (2kg*10ea) | E35: D+1 | F35: =IFERROR(VLOOKUP(C35,[1]Sheet1!$A$1:$D$65536,3,0)/K35,"") -> 0.4637 | J35: 5 | K35: 10 | L35: 계 | M35: 7600 | N35: =M35*J35 -> 38000
A36: 33 | B36: 천안fs(네트웍스) | C36: 30003653 | D36: [냉장] 오삼불고기소스(PBOX) 2KG*10개입 | E36: D+1 | F36: =IFERROR(VLOOKUP(C36,[1]Sheet1!$A$1:$D$65536,3,0)/K36,"") | H36: 3 | I36: 1 | J36: =H36*K36+I36 -> 31 | K36: 10 | L36: 계 | M36: 9000
A37: 34 | B37: 천안fs(네트웍스) | C37: 30003454 | D37: [냉장] 우엉볶음용간장소스(저염)(2kg*10ea) | E37: D+1 | F37: =IFERROR(VLOOKUP(C37,[1]Sheet1!$A$1:$D$65536,3,0)/K37,"") -> 0.405 | H37: 1 | I37: 4 | J37: =H37*K37+I37 -> 14 | K37: 10 | L37: 계 | M37: 6433 | N37: =M37*J37 -> 90062
A38: 35 | B38: 천안fs(네트웍스) | C38: 30003010 | D38: [냉장] 조미식초소스(2kg*10봉) | E38: D+1 | F38: =IFERROR(VLOOKUP(C38,[1]Sheet1!$A$1:$D$65536,3,0)/K38,"") -> 2.6841 | H38: 6 | J38: =H38*K38+I38 -> 60 | K38: 10 | L38: 취 | M38: 5000 | N38: =M38*J38 -> 300000
A39: 36 | B39: 천안fs(네트웍스) | C39: 30002875 | D39: [냉장]조청닭강정소스(2kg*10ea) | E39: D+1 | F39: =IFERROR(VLOOKUP(C39,[1]Sheet1!$A$1:$D$65536,3,0)/K39,"") -> 0.8059 | I39: 7 | J39: =H39*K39+I39 -> 7 | K39: 10 | L39: 샐 | M39: 7600 | N39: =M39*J39 -> 53200
A40: 38 | B40: 천안fs(네트웍스) | C40: 30002650 | D40: [냉장]청양식매운맛간장소스(PBOX) 2KG*10개입 | E40: D+1 | F40: =IFERROR(VLOOKUP(C40,[1]Sheet1!$A$1:$D$65536,3,0)/K40,"") -> 0.6338 | H40: 1 | I40: 3 | J40: =H40*K40+I40 -> 13 | K40: 10 | L40: 샐 | M40: 7000 | N40: =M40*J40 -> 91000
A41: 39 | B41: 천안fs(네트웍스) | C41: 30003310 | D41: [냉장] 츠쿠네소스 (2kg*10ea) | E41: D+1 | F41: =IFERROR(VLOOKUP(C41,[1]Sheet1!$A$1:$D$65536,3,0)/K41,"") -> 0.3755 | J41: =H41*K41+I41 -> 0 | K41: 10 | L41: 샐 | M41: 6200 | N41: =M41*J41 -> 0
...

Sheet 냉동
A1: 냉동 | D1: =냉장1!D1 -> 46324 | J1: 작성 | K1: 검토 | L1: 승인
A3: 재고조사자 | F3: =냉장1!F3 -> 6/14 기준 | H3: 재고조사 시간
A4: 구분 | B4: 거래처 | C4: ID | D4: 제품명 | E4: 발주주기 | F4: 일 사용량 (박스) | G4: 유통기한 | H4: 박스 | I4: 낱개 | J4: 현재고(봉) | K4: 입수량 | L4: 발주일 | M4: 봉단가 | N4: 금액
A5: 3 | B5: 현대그린푸드(네트웍스) | C5: 30003442 | D5: [냉동] 건새우마늘쫑볶음(1kg*6ea) | E5: D+2 | F5: =IFERROR(VLOOKUP(C5,[1]Sheet1!$A$1:$D$65536,3,0)/K5,"") -> 6.3 | H5: 8 | J5: =H5*K5+I5 -> 48 | K5: 6 | L5: 커 | M5: 8190 | N5: =M5*J5 -> 393120
A6: 4 | B6: 현대그린푸드(네트웍스) | C6: 30003393 | D6: [냉동] 열무나물(1KG*6봉) - 현대그린 | E6: D+2 | F6: =IFERROR(VLOOKUP(C6,[1]Sheet1!$A$1:$D$65536,3,0)/K6,"") -> 6.175 | J6: =H6*K6+I6 -> 0 | K6: 6 | L6: 계 | M6: 7500 | N6: =M6*J6 -> 0
A7: 5 | B7: 후레시미트(네트웍스) | C7: 30003294 | D7: [냉동] 매콤고추장제육불고기 (3kg*6ea) | E7: D+1 | F7: =IFERROR(VLOOKUP(C7,[1]Sheet1!$A$1:$D$65536,3,0)/K7,"") -> 2.2688333 | H7: 10 | J7: =H7*K7+I7 -> 60 | K7: 6 | L7: 계 | M7: 18600 | N7: =M7*J7 -> 1116000
A8: 5 | B8: 한울(네트웍스) | C8: 30003606 | D8: [냉동]곤드레나물(PBOX) 1KG*10개입 | E8: D+1 | F8: =IFERROR(VLOOKUP(C8,[1]Sheet1!$A$1:$D$65536,3,0)/K8,"") -> 0.5832 | H8: 2 | J8: =H8*K8+I8 -> 20 | K8: 10 | L8: 계 | M8: 18600 | N8: =M8*J8 -> 372000
A9: 4 | B9: 한울(네트웍스) | C9: 30003532 | D9: [냉동]유채나물무침(PBOX) 1KG*10개입 | E9: D+2 | G9: 9/1신상 | H9: 1 | I9: 7 | J9: =H9*K9+I9 -> 17 | K9: 10 | L9: 커 | M9: 19700 | N9: =M9*J9 -> 334900
A10: 4 | B10: 한울(네트웍스) | C10: 30003745 | D10: [냉동]궁채느타리들깨볶음(PBOX) 1KG*10개입 | E10: D+2 | H10: 1 | J10: =H10*K10+I10 -> 10 | K10: 10 | L10: 커 | M10: 19700 | N10: =M10*J10 -> 197000
A11: 4 | B11: 한울(네트웍스) | C11: 30003489 | D11: [냉동]무나물볶음(PBOX) 1KG*10봉 | E11: D+2 | H11: 1 | J11: =H11*K11+I11 -> 10 | K11: 10 | L11: 커 | M11: 19700 | N11: =M11*J11 -> 197000
A12: 6 | B12: 씨제이제일제당(CJ) | C12: 30003575 | D12: [냉동] 크레잇)고추장돼지불고기(3KG*3EA) | E12: D+1 | F12: =IFERROR(VLOOKUP(C12,[1]Sheet1!$A$1:$D$65536,3,0)/K12,"") -> 0.57166667 | J12: =H12*K12+I12 -> 0 | K12: 3 | L12: 계 | M12: =17700/3 -> 5900 | N12: =M12*J12 -> 0 | O12: 4/09신상
A13: 7 | B13: 씨제이제일제당(CJ) | C13: 30003391 | D13: [냉동] 간장돼지불고기(3KG*3EA) | E13: D+1 | F13: =IFERROR(VLOOKUP(C13,[1]Sheet1!$A$1:$D$65536,3,0)/K13,"") -> 11.672 | J13: =H13*K13+I13 -> 0 | K13: 3 | L13: 튀 | M13: 17700 | N13: =M13*J13 -> 0
A14: 8 | B14: 씨제이제일제당(CJ) | C14: 30002894 | D14: [냉동]계란옷입은동그랑땡(1kg*8ea) | E14: D+1 | F14: =IFERROR(VLOOKUP(C14,[1]Sheet1!$A$1:$D$65536,3,0)/K14,"") -> 3.603875 | J14: =H14*K14+I14 -> 0 | K14: 8 | L14: 튀 | M14: 7100 | N14: =M14*J14 -> 0
A15: 9 | B15: 씨제이제일제당(CJ) | C15: 30003072 | D15: [냉동] 크레잇꼬마돈카츠(1kg(90ea)*8봉) | E15: D+1 | F15: =IFERROR(VLOOKUP(C15,[1]Sheet1!$A$1:$D$65536,3,0)/K15,"") -> 6.472 | H15: 11 | I15: 6 | J15: =H15*K15+I15 -> 94 | K15: 8 | L15: 튀 | M15: 4900 | N15: =M15*J15 -> 460600
A16: 9 | B16: 씨제이제일제당(CJ) | C16: 30003072 | D16: [냉동] 크레잇직화함박스테이크 | E16: D+3 | F16: =IFERROR(VLOOKUP(C16,[1]Sheet1!$A$1:$D$65536,3,0)/K16,"") -> 0.45819469 | J16: =H16*K16+I16 -> 0 | K16: 113 | L16: 튀 | M16: 4900 | N16: =M16*J16 -> 0
A17: 12 | B17: 대상(DS유통) | C17: 20195320 | D17: [냉동]더진한고추장돼지불고기2kg | E17: D+2 | F17: =IFERROR(VLOOKUP(C17,[1]Sheet1!$A$1:$D$65536,3,0)/K17,"") | H17: 35 | J17: =H17*K17+I17 -> 175 | K17: 5 | L17: 계 | M17: 12870 | N17: =M17*J17 -> 2252250 | O17: 3/31신상
A18: 13 | B18: 대상(DS유통) | C18: 30002747 | D18: [냉동]간장돼지불고기A(파우치) PK(2kg)★(D-2) | E18: D+2 | F18: =IFERROR(VLOOKUP(C18,[1]Sheet1!$A$1:$D$65536,3,0)/K18,"") -> 6.1812 | G18: 대체 | H18: 17 | J18: =H18*K18+I18 -> 85 | K18: 5 | L18: 계 | M18: 12470 | N18: =M18*J18 -> 1059950
A19: 14 | B19: 대상(DS유통) | C19: 30002748 | D19: [냉동]고추장돼지불고기A(파우치)(냉동) PK(2kg) | E19: D+2 | F19: =IFERROR(VLOOKUP(C19,[1]Sheet1!$A$1:$D$65536,3,0)/K19,"") -> 24.7992 | H19: 11 | J19: =H19*K19+I19 -> 55 | K19: 5 | L19: 계 | M19: 12670 | N19: =M19*J19 -> 696850
A20: 15 | B20: 대상(DS유통) | C20: 30002522 | D20: [냉동] 고추장돼지불고기토핑 (2kg*5봉) | E20: D+2 | F20: =IFERROR(VLOOKUP(C20,[1]Sheet1!$A$1:$D$65536,3,0)/K20,"") -> 17.9158 | H20: 12 | J20: =H20*K20+I20 -> 60 | K20: 5 | L20: 튀 | M20: 12670 | N20: =M20*J20 -> 760200
A21: 16 | B21: 대상(DS유통) | C21: 30003415 | D21: [냉동] 매운마늘맛불고기(2kg*5ea) | E21: D+2 | F21: =IFERROR(VLOOKUP(C21,[1]Sheet1!$A$1:$D$65536,3,0)/K21,"") -> 0.3326 | H21: 9 | J21: =H21*K21+I21 -> 45 | K21: 5 | L21: 튀 | M21: 12870 | N21: =M21*J21 -> 579150
A22: 20 | B22: 대상(리테일) | C22: 30003287 | D22: [냉동] 세블락후랑크 CVS(1kg*10ea) | E22: D+2 | F22: =IFERROR(VLOOKUP(C22,[1]Sheet1!$A$1:$D$65536,3,0)/K22,"") -> 1.015 | H22: 3 | I22: 6 | J22: =H22*K22+I22 -> 36 | K22: 10 | L22: 튀 | M22: 7330 | N22: =M22*J22 -> 263880
A23: 21 | B23: 대상(리테일) | C23: 30002893 | D23: [냉동]청정원떡갈비(1kg*8ea) | E23: D+2 | F23: =IFERROR(VLOOKUP(C23,[1]Sheet1!$A$1:$D$65536,3,0)/K23,"") -> 2.5505 | H23: 5 | I23: 4 | J23: =H23*K23+I23 -> 44 | K23: 8 | L23: 튀 | M23: 6210 | N23: =M23*J23 -> 273240
A24: 21 | B24: 대상(리테일) | C24: 30002324 | D24: [냉동] 반숙계란후라이 (900g( 45g* 20개)*8봉)-변경 | E24: D+2 | H24: 17 | I24: 7 | J24: =H24*K24+I24 -> 143 | K24: 8 | L24: 튀 | N24: =M24*J24 -> 0
A25: 21 | B25: 대상(리테일) | C25: 30003743 | D25: [냉동]뚝배기용돼지불고기 (2kg*5봉) | E25: D+2 | H25: 7 | J25: =H25*K25+I25 -> 35 | K25: 5 | L25: 튀 | N25: =M25*J25 -> 0
A26: 22 | B26: 맘스터치 | C26: 30003637 | D26: [냉동]크리스피 순살치킨 1kg(저온)BOX(1kg*10ea) | E26: D+2 | F26: =IFERROR(VLOOKUP(C26,[1]Sheet1!$A$1:$D$65536,3,0)/K26,"") | J26: =H26*K26+I26 -> 0 | K26: 10 | L26: 커 | M26: 6850 | N26: =M26*J26 -> 0
A27: 23 | B27: 사옹원 | C27: 30003373 | D27: [냉동] 알찬해물부추전 (1kg(30g*33ea) * 5pk) | E27: D+2 | F27: =IFERROR(VLOOKUP(C27,[1]Sheet1!$A$1:$D$65536,3,0)/K27,"") | H27: 27 | J27: =H27*K27+I27 -> 135 | K27: 5 | L27: 튀 | M27: 6496 | N27: =M27*J27 -> 876960
A28: 23 | B28: 사옹원 | C28: 30003640 | D28: [냉동]계란옷입은고기완자(1kg*6) | E28: D+2 | F28: =IFERROR(VLOOKUP(C28,[1]Sheet1!$A$1:$D$65536,3,0)/K28,"") | G28: 대체 | H28: 14 | I28: 3 | J28: =H28*K28+I28 -> 87 | K28: 6 | L28: 튀 | M28: 6496 | N28: =M28*J28 -> 565152
A29: 24 | B29: 선진FS(리테일) | C29: 30003051 | D29: [냉동]갈비함박40 PK(40g*25ea) | E29: D+2 | F29: =IFERROR(VLOOKUP(C29,[1]Sheet1!$A$1:$D$65536,3,0)/K29,"") | H29: 31 | I29: 8 | J29: =H29*K29+I29 -> 318 | K29: 10 | L29: 튀 | M29: 11325 | N29: =M29*J29 -> 3601350
A30: 24 | B30: 선진FS(리테일) | C30: 20001437 | D30: [냉동] 냉동비프불고기토핑(1kg*10봉) | E30: D+2 | F30: =IFERROR(VLOOKUP(C30,[1]Sheet1!$A$1:$D$65536,3,0)/K30,"") -> 0.7843 | H30: 6 | I30: 6 | J30: =H30*K30+I30 -> 66 | K30: 10 | L30: 튀 | M30: 11325 | N30: =M30*J30 -> 747450
A31: 25 | B31: 선진FS(리테일) | C31: 30003527 | D31: [냉동] 대파불고기양념육(2kg*6ea) | E31: D+2 | F31: =IFERROR(VLOOKUP(C31,[1]Sheet1!$A$1:$D$65536,3,0)/K31,"") -> 5.8566667 | H31: 9 | J31: =H31*K31+I31 -> 54 | K31: 6 | L31: 계 | M31: =77030/6 -> 12838.333 | N31: =M31*J31 -> 693270
A32: 26 | B32: 선진FS(리테일) | C32: 30003652 | D32: [냉동] 선진)선진오징어제육 PK(2,000g*6PK) | E32: D+2 | F32: =IFERROR(VLOOKUP(C32,[1]Sheet1!$A$1:$D$65536,3,0)/K32,"") | H32: 18 | J32: =H32*K32+I32 -> 108 | K32: 6 | L32: 계 | N32: =M32*J32 -> 0
A33: 27 | B33: 선진FS(리테일) | C33: 30002988 | D33: [냉동] 미트볼골드(1kg*10ea) | E33: D+2 | F33: =IFERROR(VLOOKUP(C33,[1]Sheet1!$A$1:$D$65536,3,0)/K33,"") -> 0.9823 | H33: 5 | I33: 1 | J33: =H33*K33+I33 -> 51 | K33: 10 | L33: 튀 | M33: 7370 | N33: =M33*J33 -> 375870
A34: 30 | B34: 선진FS(리테일) | C34: 30003440 | D34: [냉동] 찌개용어슷후랑크(1kg*10ea) | E34: D+2 | F34: =IFERROR(VLOOKUP(C34,[1]Sheet1!$A$1:$D$65536,3,0)/K34,"") -> 2.9115 | J34: =H34*K34+I34 -> 0 | K34: 10 | L34: 커 | M34: 6400 | N34: =M34*J34 -> 0
A35: 31 | B35: 선진FS(리테일) | C35: 30002549 | D35: [냉동] 한돈프리미엄돈카츠 (160g*8ea*8ea) | E35: D+2 | F35: =IFERROR(VLOOKUP(C35,[1]Sheet1!$A$1:$D$65536,3,0)/K35,"") -> 11.50625 | H35: 8 | I35: 7 | J35: =H35*K35+I35 -> 71 | K35: 8 | L35: 튀 | M35: =72050/8 -> 9006.25 | N35: =M35*J35 -> 639443.75
A36: 32 | B36: 선진FS(리테일) | C36: 30003295 | D36: [냉동] 혜자토네이도소시지 [(55g*14ea) *12봉] | E36: D+2 | F36: =IFERROR(VLOOKUP(C36,[1]Sheet1!$A$1:$D$65536,3,0)/K36,"") -> 4.9783333 | H36: 46 | J36: =H36*K36+I36 -> 552 | K36: 12 | L36: 튀 | M36: =60700/12 -> 5058.3333 | N36: =M36*J36 -> 2792200
A37: 32 | B37: 선진FS(리테일) | C37: 30003674 | D37: [냉동]도톰한멘츠카츠S50 PK(50g*20ea) | E37: D+2 | F37: =IFERROR(VLOOKUP(C37,[1]Sheet1!$A$1:$D$65536,3,0)/K37,"") | H37: 10 | I37: 6 | J37: =H37*K37+I37 -> 106 | K37: 10 | L37: 튀 | M37: =60700/12 -> 5058.3333 | N37: =M37*J37 -> 536183.33
A38: 32 | B38: 선진FS(리테일) | C38: 30003063 | D38: [냉동]한입직화 떡갈비(20g*50ea)*10봉 | E38: D+2 | F38: =IFERROR(VLOOKUP(C38,[1]Sheet1!$A$1:$D$65536,3,0)/K38,"") | I38: 7 | J38: =H38*K38+I38 -> 7 | K38: 10 | L38: 튀 | M38: =60700/12 -> 5058.3333 | N38: =M38*J38 -> 35408.333
A39: 32 | B39: 선진FS(리테일) | C39: 30003754 | D39: [냉동]김밥용남도떡갈비140 PK(140g*10ea)★ | E39: D+2 | F39: =IFERROR(VLOOKUP(C39,[1]Sheet1!$A$1:$D$65536,3,0)/K39,"") | H39: 20 | J39: =H39*K39+I39 -> 200 | K39: 10 | L39: 튀 | M39: =60700/12 -> 5058.3333 | N39: =M39*J39 -> 1011666.7
A40: 34 | B40: 아워홈(리테일) | C40: 30001804 | D40: [냉동] 70미니등심돈까스(1.05kg*8봉)-리뉴얼 | E40: D+2 | F40: =IFERROR(VLOOKUP(C40,[1]Sheet1!$A$1:$D$65536,3,0)/K40,"") -> 21.220875 | H40: 32 | I40: 6 | J40: =H40*K40+I40 -> 262 | K40: 8 | L40: 튀 | M40: 5900 | N40: =M40*J40 -> 1545800
A41: 35 | B41: 아워홈(리테일) | C41: 30002098 | D41: [냉동] 나트륨줄인치킨가라야게(1kg*10봉) | E41: D+2 | F41: =IFERROR(VLOOKUP(C41,[1]Sheet1!$A$1:$D$65536,3,0)/K41,"") -> 8.3571 | H41: 6 | J41: =H41*K41+I41 -> 60 | K41: 10 | L41: 튀 | M41: 6050 | N41: =M41*J41 -> 363000
...

Sheet 상온
A1: 상온 | D1: =냉장1!D1 -> 46324 | J1: 작성 | K1: 검토 | L1: 승인
A3: 재고조사자 | F3: =냉장1!F3 -> 6/14 기준 | H3: 재고조사 시간
A4: 구분 | B4: 거래처 | C4: ID | D4: 제품명 | E4: 발주주기 | F4: 일 사용량 (박스) | G4: 유통기한 | H4: 박스 | I4: 낱개 | J4: 현재고(봉) | K4: 입수량 | L4: 발주일 | M4: 봉단가 | N4: 금액
A5: 1 | B5: 평화영농조합 | C5: 30003009 | D5: [상온] 평화햅쌀(500kg/포) | E5: D+1 | F5: =IFERROR(VLOOKUP(C5,[1]Sheet1!$A$1:$D$65536,3,0)/K5,"") -> 6.475732 | H5: 21 | J5: =H5*K5+I5 -> 10500 | K5: 500 | M5: 3000 | N5: =M5*J5 -> 31500000
A6: 2 | B6: 그래도푸드(리테일) | C6: 30002629 | D6: [상온] 그래도푸드)노란단무지13mm (2.5kg*4ea) | E6: D+1 | F6: =IFERROR(VLOOKUP(C6,[1]Sheet1!$A$1:$D$65536,3,0)/K6,"") -> 43.7975 | H6: 40 | J6: =H6*K6+I6 -> 160 | K6: 4 | L6: 샐 | M6: =15000/4 -> 3750 | N6: =M6*J6 -> 600000
A7: 4 | B7: 농심태경 | C7: 30003762 | D7: [상온]1/2김(100*190mm)(실온)PK(200EA)*50pk | E7: D+2 | G7: 46315 | H7: 26 | J7: =H7*K7+I7 -> 1300 | K7: 50 | L7: 계 | M7: 7250 | N7: =M7*J7 -> 9425000
A8: 4 | B8: 농심태경 | C8: 30002439 | D8: [상온] 비빔소스[30g*400ea(소포장)] | E8: D+2 | J8: =H8*K8+I8 -> 0 | K8: 400 | L8: 계 | M8: 7250 | N8: =M8*J8 -> 0
A9: 5 | B9: 대상(네트웍스) | C9: 30000093 | D9: [상온] 쇠고기 실속다시(2kg*6EA) | E9: D+2 | F9: =IFERROR(VLOOKUP(C9,[1]Sheet1!$A$1:$D$65536,3,0)/K9,"") -> 0.85483333 | H9: 5 | J9: =H9*K9+I9 -> 30 | K9: 6 | L9: 계 | M9: 6508.3333 | N9: =M9*J9 -> 195250
A10: 6 | B10: 더원씨푸드 (네트웍스) | C10: 30003148 | D10: [상온] 조미삼각김(100매*32팩)/ 외관변경 | E10: D+1 | F10: =IFERROR(VLOOKUP(C10,[1]Sheet1!$A$1:$D$65536,3,0)/K10,"") | G10: 6/2삭제 | J10: =H10*K10+I10 -> 0 | K10: 32 | M10: 10200 | N10: =M10*J10 -> 0
A11: 7 | B11: 대상(리테일) | C11: 30003368 | D11: [상온] 쉐프원 두번자른화영당면 (1kg*10ea) | E11: D+2 | F11: =IFERROR(VLOOKUP(C11,[1]Sheet1!$A$1:$D$65536,3,0)/K11,"") -> 1.2445 | H11: 3 | I11: 1 | J11: =H11*K11+I11 -> 31 | K11: 10 | L11: 조리실 | M11: 4460 | N11: =M11*J11 -> 138260
A12: 8 | B12: 대상(리테일) | C12: 30003340 | D12: [상온] 청정원_매운갈비양념(2kg*8ea) | E12: D+2 | F12: =IFERROR(VLOOKUP(C12,[1]Sheet1!$A$1:$D$65536,3,0)/K12,"") -> 0.968875 | H12: 1 | I12: 3 | J12: =H12*K12+I12 -> 11 | K12: 8 | L12: 계 | M12: 8510 | N12: =M12*J12 -> 93610
A13: 9 | B13: 대상(리테일) | C13: 30003735 | D13: [상온]혜자도시락김(소포장) | E13: D+2 | H13: 24 | J13: =H13*K13+I13 -> 7200 | K13: 300 | L13: 계 | M13: 6530 | N13: =M13*J13 -> 47016000 | O13: 3/31신상
A14: 10 | B14: 대상(리테일) | C14: 50000028 | D14: [상온] 청정원)진간장골드(13L) | E14: D+1 | F14: =IFERROR(VLOOKUP(C14,[1]Sheet1!$A$1:$D$65536,3,0)/K14,"") | H14: 6 | J14: =H14*K14+I14 -> 6 | K14: 1 | M14: 19800 | N14: =M14*J14 -> 118800
A15: 11 | B15: 더원씨푸드 (네트웍스) | C15: 30003605 | D15: [상온] 삼각김(투명_들기름) 100매*32개입 | E15: D+1 | F15: =IFERROR(VLOOKUP(C15,[1]Sheet1!$A$1:$D$65536,3,0)/K15,"") -> 1.658125 | H15: 6 | J15: =H15*K15+I15 -> 192 | K15: 32 | M15: 10200 | N15: =M15*J15 -> 1958400
A16: 12 | B16: 더원씨푸드 (네트웍스) | C16: 30003421 | D16: [상온] 더원씨푸드)1/2절김 200매*30개입 | E16: D+1 | F16: =IFERROR(VLOOKUP(C16,[1]Sheet1!$A$1:$D$65536,3,0)/K16,"") -> 1.1273 | J16: =H16*K16+I16 -> 0 | K16: 30 | M16: 11500 | N16: =M16*J16 -> 0
A17: 13 | B17: 더원씨푸드 (네트웍스) | C17: 30003155 | D17: [상온] 삼각김(무조미/100매*32ea) | E17: D+1 | F17: =IFERROR(VLOOKUP(C17,[1]Sheet1!$A$1:$D$65536,3,0)/K17,"") | G17: 6/2삭제 | J17: =H17*K17+I17 -> 0 | K17: 32 | M17: 10200 | N17: =M17*J17 -> 0
A18: 14 | B18: 더원씨푸드 (네트웍스) | C18: 30003115 | D18: [상온] 점보롤김 450매*8롤 | E18: D+1 | F18: =IFERROR(VLOOKUP(C18,[1]Sheet1!$A$1:$D$65536,3,0)/K18,"") -> 2.28975 | H18: 2 | J18: =H18*K18+I18 -> 16 | K18: 8 | M18: 63900 | N18: =M18*J18 -> 1022400
A19: 15 | B19: 롯데웰푸드(네트웍스) | C19: 30000363 | D19: [상온]데리야끼소스 2KG*6개입 | E19: D+1 | F19: =IFERROR(VLOOKUP(C19,[1]Sheet1!$A$1:$D$65536,3,0)/K19,"") | H19: 3 | J19: =H19*K19+I19 -> 18 | K19: 6 | M19: 12990 | N19: =M19*J19 -> 233820
A20: 15 | B20: 만전식품 (네트웍스) | C20: 30003168 | D20: [상온] 김밥김 3절 300매*50개입 | E20: D+1 | F20: =IFERROR(VLOOKUP(C20,[1]Sheet1!$A$1:$D$65536,3,0)/K20,"") -> 0.1033 | H20: 1 | I20: 7 | J20: =H20*K20+I20 -> 57 | K20: 50 | M20: 12990 | N20: =M20*J20 -> 740430
A21: 16 | B21: 만전식품 (네트웍스) | C21: 30003541 | D21: [상온] 점보삼각김(투명패턴) 100매*32개입 | E21: D+1 | F21: =IFERROR(VLOOKUP(C21,[1]Sheet1!$A$1:$D$65536,3,0)/K21,"") -> 6.538125 | H21: 19 | J21: =H21*K21+I21 -> 608 | K21: 32 | M21: =377600/32 -> 11800 | N21: =M21*J21 -> 7174400 | O21: 3/26리뉴얼
A22: 18 | B22: 사조대림 | C22: 30003419 | D22: [상온] 참치(2kg*5봉)-사조대림 | E22: D+2 | F22: =IFERROR(VLOOKUP(C22,[1]Sheet1!$A$1:$D$65536,3,0)/K22,"") -> 9.122 | J22: =H22*K22+I22 -> 0 | K22: 5 | L22: 샐 | M22: 13000 | N22: =M22*J22 -> 0
A23: 19 | B23: 삼성웰스토리 (네트웍스) | C23: 30001164 | D23: [상온] 고운고추분 1kg*20봉 | E23: D+2 | F23: =IFERROR(VLOOKUP(C23,[1]Sheet1!$A$1:$D$65536,3,0)/K23,"") -> 0.0968 | H23: 1 | I23: 6 | J23: =H23*K23+I23 -> 26 | K23: 20 | L23: 계 | M23: 8750 | N23: =M23*J23 -> 227500
A24: 20 | B24: 삼성웰스토리 (네트웍스) | C24: 30001581 | D24: [상온] 케찹파우치(3kg*4봉) | E24: D+2 | F24: =IFERROR(VLOOKUP(C24,[1]Sheet1!$A$1:$D$65536,3,0)/K24,"") -> 1.322 | H24: 3 | J24: =H24*K24+I24 -> 12 | K24: 4 | L24: 샐 | M24: 4300 | N24: =M24*J24 -> 51600
A25: 21 | B25: 성경(네트웍스) | C25: 30003061 | D25: 성경)돌자반(500g*6ea) | E25: D+1 | F25: =IFERROR(VLOOKUP(C25,[1]Sheet1!$A$1:$D$65536,3,0)/K25,"") -> 3.0656667 | H25: 5 | J25: =H25*K25+I25 -> 30 | K25: 6 | L25: 샐 | M25: 9680 | N25: =M25*J25 -> 290400
A26: 22 | B26: 성경(네트웍스) | C26: 30002759 | D26: [상온] 성경식품)재래도시락김 2G*10ea*24봉 | E26: D+1 | F26: =IFERROR(VLOOKUP(C26,[1]Sheet1!$A$1:$D$65536,3,0)/K26,"") -> 15.9625 | H26: 36 | J26: =H26*K26+I26 -> 864 | K26: 24 | L26: 샐 | M26: =27330/24 -> 1138.75 | N26: =M26*J26 -> 983880
A27: 23 | B27: 씨제이제일제당 (CJ) | C27: 30001140 | D27: [상온] 대두유(18L*통) | E27: D+1 | F27: =IFERROR(VLOOKUP(C27,[1]Sheet1!$A$1:$D$65536,3,0)/K27,"") -> 16.894 | H27: 90 | J27: =H27*K27+I27 -> 90 | K27: 1 | L27: 계/튀/취 | M27: 35000 | N27: =M27*J27 -> 3150000
A28: 24 | B28: 씨제이제일제당 (CJ) | C28: 30000389 | D28: [상온] 스팸(340g*20캔) | E28: D+1 | F28: =IFERROR(VLOOKUP(C28,[1]Sheet1!$A$1:$D$65536,3,0)/K28,"") -> 29.8447 | J28: =H28*K28+I28 -> 0 | K28: 20 | L28: 커 | M28: 3150 | N28: =M28*J28 -> 0
A29: 25 | B29: 씨제이제일제당 (CJ) | C29: 30001710 | D29: [상온] 하얀설탕(3kg*6봉) | E29: D+1 | F29: =IFERROR(VLOOKUP(C29,[1]Sheet1!$A$1:$D$65536,3,0)/K29,"") -> 1.4045 | J29: =H29*K29+I29 -> 0 | K29: 6 | L29: 계/샐 | M29: 4929 | N29: =M29*J29 -> 0
A30: 26 | B30: 씨제이제일제당 (CJ) | C30: 30003392 | D30: [상온] CJ백설 돼지갈비양념(10KG*1EA) | E30: D+1 | F30: =IFERROR(VLOOKUP(C30,[1]Sheet1!$A$1:$D$65536,3,0)/K30,"") -> 1.07 | H30: 7 | J30: =H30*K30+I30 -> 7 | K30: 1 | L30: 계/샐 | M30: 23000 | N30: =M30*J30 -> 161000
A31: 26 | B31: 씨제이제일제당 (CJ) | C31: 30002086 | D31: [상온]다담/강된장찌개양념(2kg*6ea) | E31: D+1 | H31: 1 | J31: =H31*K31+I31 -> 6 | K31: 6 | L31: 계/샐 | M31: 23000 | N31: =M31*J31 -> 138000
A32: 26 | B32: 씨제이제일제당 (CJ) | C32: 30000179 | D32: [상온]해찬들고추장14kg | E32: D+1 | J32: =H32*K32+I32 -> 0 | K32: 1 | L32: 계/샐 | M32: 23000 | N32: =M32*J32 -> 0
A33: 27 | B33: 오뚜기(리테일) | C33: 30003544 | D33: [상온] 오뚜기GS마요네즈 (10kg*1ea) | E33: D+1 | F33: =IFERROR(VLOOKUP(C33,[1]Sheet1!$A$1:$D$65536,3,0)/K33,"") -> 16.436 | H33: 60 | J33: =H33*K33+I33 -> 60 | K33: 1 | L33: 샐 | M33: 26880 | N33: =M33*J33 -> 1612800 | O33: 3/26리뉴얼
A34: 28 | B34: 오뚜기(리테일) | C34: 30003296 | D34: [상온] 오쉐프_허니마스타드 드레싱 (2kg*6ea) | E34: D+1 | F34: =IFERROR(VLOOKUP(C34,[1]Sheet1!$A$1:$D$65536,3,0)/K34,"") -> 0.393 | H34: 4 | J34: =H34*K34+I34 -> 24 | K34: 6 | L34: 야 | M34: 7150 | N34: =M34*J34 -> 171600
A35: 29 | B35: 오뚜기(리테일) | C35: 30003365 | D35: [상온]이금기_팬더굴소스(PE) 2.4KG | E35: D+1 | F35: =IFERROR(VLOOKUP(C35,[1]Sheet1!$A$1:$D$65536,3,0)/K35,"") -> 0.0545 | J35: =H35*K35+I35 -> 0 | K35: 6 | L35: 야 | M35: 9200 | N35: =M35*J35 -> 0 | O35: 3/26신상
A36: 30 | B36: 오뚜기(리테일) | C36: 30003276 | D36: [상온] 치킨파우더(1KG*12EA) | E36: D+1 | F36: =IFERROR(VLOOKUP(C36,[1]Sheet1!$A$1:$D$65536,3,0)/K36,"") -> 0.069166667 | J36: =H36*K36+I36 -> 0 | K36: 12 | L36: 계 | M36: 16750 | N36: =M36*J36 -> 0 | O36: 3/26신상
A37: 31 | B37: 오뚜기(리테일) | C37: 30002439 | D37: [상온] 고추맛기름(1.5L*9통)-NS유통 | E37: D+2 | F37: =IFERROR(VLOOKUP(C37,[1]Sheet1!$A$1:$D$65536,3,0)/K37,"") -> 0.25744444 | H37: 2 | I37: 4 | J37: =H37*K37+I37 -> 22 | K37: 9 | L37: 계 | M37: 7250 | N37: =M37*J37 -> 159500
A38: 32 | B38: 오뚜기(리테일) | C38: 30003772 | D38: [상온]빵가루(상온)PK(10kg) | E38: D+2 | H38: 3 | J38: =H38*K38+I38 -> 3 | K38: 1 | L38: 계 | M38: 22500 | N38: =M38*J38 -> 67500
A39: 33 | B39: 이너피스(네트웍스) | C39: 30003476 | D39: [상온] 화풍표고버섯채(종이BOX) 2.84KG*6캔 | E39: D+1 | F39: =IFERROR(VLOOKUP(C39,[1]Sheet1!$A$1:$D$65536,3,0)/K39,"") -> 1.3 | H39: 11 | I39: 2 | J39: =H39*K39+I39 -> 68 | K39: 6 | L39: 야 | M39: 4200 | N39: =M39*J39 -> 285600
A40: 34 | B40: 씨제이제일제당 (CJ) | C40: 30003296 | D40: 크레잇)허니머스타드드레싱(2kg*6ea) | E40: D+1 | F40: =IFERROR(VLOOKUP(C40,[1]Sheet1!$A$1:$D$65536,3,0)/K40,"") -> 0.393 | J40: =H40*K40+I40 -> 0 | K40: 6 | L40: 샐 | M40: 6773 | N40: =M40*J40 -> 0 | O40: 임시용도
A41: 35 | B41: NS유통 | C41: 30002793 | D41: [상온] 리챔 (340g*24ea) | E41: D+1 | F41: =IFERROR(VLOOKUP(C41,[1]Sheet1!$A$1:$D$65536,3,0)/K41,"") -> 5.9444583 | J41: =H41*K41+I41 -> 0 | K41: 24 | L41: 야 | M41: 2600 | N41: =M41*J41 -> 0
...

Sheet Sheet1
A1: 구분 | B1: 거래처 | C1: ID | D1: 제품명 | E1: 입고일 | F1: 일 사용량 (박스) | G1: 유통기한 | H1: 박스 | I1: 낱개 | J1: 현재고(봉) | K1: 입수량 | L1: 발주일 | M1: 봉단가 | N1: 금액
A2: 1 | B2: 농심태경(금행) | C2: 30002902 | D2: [냉장]토마토파스타소스(2kg*6ea) | E2: D+2 | F2: 2.0011667 | H2: 7 | I2: 5 | J2: 47 | K2: 6 | L2: 샐 | M2: 5150 | N2: 242050
A3: 2 | B3: 다미푸드텍(금행) | C3: 30002904 | D3: [냉장] 할라피뇨칠리소스(3kg*5ea) | E3: D+2 | F3: 0.6116 | H3: 3 | I3: 2 | J3: 17 | K3: 5 | L3: 샐 | M3: 11400 | N3: 193800 | O3: 3/17신상
A4: 3 | B4: 다미푸드텍(금행) | C4: 30003064 | D4: [냉장] 쌈장마요소스(3KG*5EA) | E4: D+2 | F4: 1.2412 | H4: 1 | I4: 2 | J4: 7 | K4: 5 | L4: 샐 | M4: 14700 | N4: 102900
A5: 4 | B5: 다미푸드텍(금행) | C5: 30003367 | D5: [냉장] 잡채용소스_JH (3kg*5ea) | E5: D+2 | H5: 1 | I5: 3 | J5: 8 | K5: 5 | L5: 샐 | M5: 11400 | N5: 91200 | O5: 3/17신상
A6: 5 | B6: 다미푸드텍(금행) | C6: 20194666 | D6: [냉장] 카츠도시락용소스 (3kg*5ea) | E6: D+2 | H6: 12 | J6: 60 | K6: 5 | L6: 샐 | M6: 14700 | N6: 882000
A7: 6 | B7: 대상(리테일) | C7: 30002846 | D7: [냉장] 비빔밥용고추장소스 (2kg*5ea) | E7: D+2 | F7: 0.4422 | H7: 1 | I7: 2 | J7: 7 | K7: 5 | L7: 커 | M7: 8910 | N7: 62370
A8: 7 | B8: 대상(리테일) | C8: 30003596 | D8: [냉장] 쉐프원 불맛베이스(캡파우치)(2kg*5ea) | E8: D+2 | F8: 1.1394 | H8: 1 | I8: 3 | J8: 8 | K8: 5 | L8: 샐 | M8: 16140 | N8: 129120
A9: 8 | B9: 동방푸드마스타(금행) | C9: 30002896 | D9: [냉장]통통쏘야소스(3kg*4ea) | E9: D+2 | F9: 0.893 | H9: 3 | I9: 2 | J9: 14 | K9: 4 | L9: 커 | M9: 10200 | N9: 142800
A10: 9 | B10: 동방푸드마스타(금행) | C10: 30003617 | D10: [냉장] 데리야끼마요소스-FS (3kg*4ea) | E10: D+2 | H10: 6 | J10: 24 | K10: 4 | L10: 샐 | M10: 14280 | N10: 342720
A11: 10 | B11: 매일유업(리테일) | C11: 20195150 | D11: [냉장] 마일드체다SOS치즈(960g*16ea) | E11: D+3 | F11: 1.990875 | H11: 9 | I11: 11 | J11: 155 | K11: 16 | L11: 커 | M11: 7440 | N11: 1153200
A12: 11 | B12: 반찬단지(리테일) | C12: 30003582 | D12: [냉장]8mm김밥단무지2.5kg(냉장)BOX(2.5KG*4EA) | E12: D+1 | F12: 10.21875 | H12: 14 | I12: 2 | J12: 58 | K12: 4 | L12: 커 | M12: 3950 | N12: 229100 | O12: 5/5신상
A13: 11 | B13: 반찬단지(리테일) | C13: 30003582 | D13: [냉장] 세천팜)김밥단무지 (2.5kg*4ea) | E13: D+1 | F13: 10.21875 | H13: 34 | J13: 136 | K13: 4 | L13: 커 | M13: 3950 | N13: 537200 | O13: 5/5신상
A14: 12 | B14: 부림 | C14: 20001846 | D14: [냉장] 당근채(4kg*3봉 - 1박스) | E14: D+1 | F14: 16.602 | H14: 15 | J14: 45 | K14: 3 | L14: 야 | M14: 7600 | N14: 342000
A15: 13 | B15: 선진FS(리테일) | C15: 30002903 | D15: [냉장] 치즈콕콕소시지(1.4kg*8ea) (1봉=100g*14ea) | E15: D+2 | F15: 9.45 | H15: 24 | J15: 192 | K15: 8 | L15: 커 | M15: 10226.25 | N15: 1963440 | O15: 3/17신상
A16: 14 | B16: 선진FS(리테일) | C16: 30003671 | D16: [냉장] 통통한칼집소시지 PK(990g) | E16: D+1 | H16: 20 | I16: 22 | J16: 222 | K16: 10 | L16: 커 | M16: 6300 | N16: 1398600
A17: 15 | B17: 아워홈(리테일) | C17: 30003656 | D17: [냉장] 마당놀이2(사각어묵)(1kg*10ea) | E17: D+2 | G17: 변경 | H17: 6 | I17: 26 | J17: 86 | K17: 10 | M17: 3200 | N17: 275200
A18: 16 | B18: 아워홈(리테일) | C18: 30001165 | D18: [냉장] 깍두기(10kg*box) | E18: D+2 | F18: 2.82 | H18: 4 | J18: 4 | K18: 1 | L18: 야 | M18: 19800 | N18: 79200
A19: 17 | B19: 아워홈(리테일) | C19: 30002355 | D19: [냉장] 알뜰어묵볼대림 (1kg*10봉) | E19: D+2 | F19: 2.626 | G19: 변경 | J19: 0 | K19: 10 | L19: 커 | M19: 2230 | N19: 0
A20: 18 | B20: 아워홈(리테일) | C20: 30003673 | D20: [냉장]숯불갈비맛소스_2kg 행복한맛남 | E20: D+2 | H20: 1 | J20: 1 | K20: 1 | L20: 커 | M20: 2230 | N20: 2230
A21: 19 | B21: 아워홈(리테일) | C21: 30002684 | D21: [냉장] 아워홈)채어묵Ⅲ (1kg*10ea) | E21: D+2 | G21: 영풍김밥용 | J21: 0 | K21: 10 | M21: 2810 | N21: 0
A22: 20 | B22: 엠디에스코리아 (CJ) | C22: 30002593 | D22: [냉장] 콘버터G (1kg*10봉) | E22: D+2 | F22: 2.6006 | H22: 12 | I22: 9 | J22: 129 | K22: 10 | L22: 커 | M22: 5200 | N22: 670800
A23: 21 | B23: 엠디에스코리아 (CJ) | C23: 30002318 | D23: [냉장] 만능마카로니샐러드(1kg*10봉) | E23: D+2 | F23: 3.8 | H23: 9 | J23: 90 | K23: 10 | L23: 커 | M23: 4300 | N23: 387000
A24: 22 | B24: 엠디에스코리아 (CJ) | C24: 30003566 | D24: [냉장]마카로니샐러드(1kg*10봉) | E24: D+2 | F24: 3.8 | H24: 2 | J24: 20 | K24: 10 | L24: 커 | M24: 4300 | N24: 86000
A25: 23 | B25: 이레팜(네트웍스) | C25: 30002007 | D25: [냉장] 계란구이(세절)(1020g*12봉) | E25: D+2 | F25: 1.2630833 | I25: 10 | J25: 10 | K25: 12 | L25: 커 | M25: 5900 | N25: 59000
A26: 24 | B26: 이레팜(네트웍스) | C26: 30000910 | D26: [냉장] 야채계란말이(900g*12봉) | E26: D+2 | F26: 2.4375833 | H26: 8 | I26: 9 | J26: 105 | K26: 12 | L26: 커 | M26: 6250 | N26: 656250
A27: 25 | B27: 이레팜(네트웍스) | C27: 30003510 | D27: [냉장] 더커진계란구이(1.02kg*12ea) | E27: D+2 | F27: 7.81175 | H27: 9 | I27: 6 | J27: 114 | K27: 12 | L27: 커 | M27: 5900 | N27: 672600 | O27: 3/10신상
A28: 26 | B28: 이우유통 | C28: 30003288 | D28: [냉장] 송송오이피클(1kg*6ea) | E28: D+1 | F28: 0.35616667 | H28: 1 | J28: 6 | K28: 6 | L28: 샐 | M28: 3900 | N28: 23400
A29: 27 | B29: 이우유통 | C29: 30003599 | D29: [냉장] 조리편한조각두부(부침용) (3kg(88ea)*3pk) | E29: D+1 | F29: 8.4546667 | H29: 58 | J29: 2 | K29: 3 | L29: 샐 | M29: 3900 | N29: 7800
A30: 27 | B30: 이우유통 | C30: 30003599 | D30: [냉장] 신슈단무지 찹핑 (1kg*10pk ) | E30: D+1 | F30: 2.5364 | H30: 7 | I30: 5 | J30: 2 | K30: 10 | L30: 샐 | M30: 3900 | N30: 7800
A31: 28 | B31: 진주햄(동원) | C31: 30000376 | D31: [냉장] 골드88세절K(1kg*10봉) | E31: D+1 | F31: 3.2648 | H31: 7 | I31: 2 | J31: 72 | K31: 10 | L31: 커 | M31: 5150 | N31: 370800
A32: 29 | B32: 진주햄(동원) | C32: 30002614 | D32: [냉장] 알뜰주부진주줄줄이(1kg*10봉) | E32: D+1 | F32: 5.9682 | G32: 대체품 | H32: 3 | I32: 10 | J32: 40 | K32: 10 | L32: 커 | M32: 5500 | N32: 220000
A33: 29 | B33: 진주햄(동원) | C33: 30003766 | D33: [냉장]숯불갈비맛스모크햄세절48(1KG*10) | E33: D+1 | H33: 3 | I33: 6 | J33: 36 | K33: 10 | L33: 커 | M33: 6900 | N33: 248400
A34: 30 | B34: 한성기업 (동원) | C34: 20001849 | D34: [냉장] 게맛살(1.2kg*10봉) | E34: D+2 | F34: 5.3747 | H34: 5 | I34: 4 | J34: 54 | K34: 10 | L34: 커 | M34: 4200 | N34: 226800
A35: 31 | B35: 풍림푸드(리테일) | C35: 30003695 | D35: [냉장]계란말이G900gBOX(900g*10pk) | E35: D+1 | H35: 25 | J35: 250 | K35: 10 | L35: 커 | M35: 24400 | N35: 6100000
A36: 32 | B36: 태원식품(금행) | C36: 30003556 | D36: [냉장] 마라상궈소스(2kg*5ea) | E36: D+2 | F36: 0.0074 | J36: 0 | K36: 5 | L36: 계 | M36: 19200 | N36: 0 | O36: 3/26신상
A37: 33 | B37: 태원식품(금행) | C37: 30003528 | D37: [냉장] 불맛향미유 (2kg*5ea) | E37: D+2 | F37: 0.0454 | I37: 1 | J37: 1 | K37: 5 | L37: 계 | M37: 26500 | N37: 26500 | O37: 4/07신상
A38: 34 | B38: 한성기업 (동원) | C38: 30003070 | D38: [냉장] 숯불구이맛김밥햄(200g*30ea) | E38: D+2 | F38: 0.4 | H38: 1 | I38: 20 | J38: 50 | K38: 30 | L38: 커 | M38: 1820 | N38: 91000
A39: 35 | B39: 일미농수산 | C39: 30003352 | D39: [냉장]새콤한채코울슬로우(1kg*12pk) | E39: D+2 | H39: 11 | I39: 4 | J39: 136 | K39: 12 | L39: 샐 | M39: 5330 | N39: 724880
A40: 36 | B40: 부림 | D40: 순성)당근채(국내산) (4kg*3pk/box) | E40: D+3 | G40: 순성김밥 | J40: 0 | K40: 3 | M40: 6255 | N40: 0
...
